{
  "version": 8,
  "blockIdVersion": 11,
  "anchorX": 0,
  "anchorY": 0,
  "anchorZ": 0,
  "blocks": [
    {
      "x": -7,
      "y": 18,
      "z": -15,
      "name": "Rock_Shale",
      "rotation": 2
    },
    {
      "x": -7,
      "y": 19,
      "z": -15,
      "name": "Rock_Shale",
      "rotation": 2
    },
    {
      "x": -7,
      "y": 18,
      "z": -14,
      "name": "Rock_Shale",
      "rotation": 2
    },
    {
      "x": -7,
      "y": 19,
      "z": -14,
      "name": "Rock_Shale",
      "rotation": 2
    },
    {
      "x": -7,
      "y": 20,
      "z": -14,
      "name": "Rock_Shale",
      "rotation": 2
    },
    {
      "x": -7,
      "y": 18,
      "z": -13,
      "name": "Rock_Shale",
      "rotation": 2
    },
    {
      "x": -7,
      "y": 19,
      "z": -13,
      "name": "Rock_Shale",
      "rotation": 2
    },
    {
      "x": -7,
      "y": 20,
      "z": -13,
      "name": "Rock_Shale",
      "rotation": 2
    },
    {
      "x": -7,
      "y": 18,
      "z": -12,
      "name": "Rock_Shale",
      "rotation": 2
    },
    {
      "x": -7,
      "y": 19,
      "z": -12,
      "name": "Rock_Shale",
      "rotation": 2
    },
    {
      "x": -7,
      "y": 20,
      "z": -12,
      "name": "Rock_Shale",
      "rotation": 2
    },
    {
      "x": -7,
      "y": 13,
      "z": -9,
      "name": "Rock_Shale",
      "rotation": 2
    },
    {
      "x": -7,
      "y": 14,
      "z": -9,
      "name": "Rock_Shale",
      "rotation": 2
    },
    {
      "x": -7,
      "y": 15,
      "z": -9,
      "name": "Rock_Shale",
      "rotation": 2
    },
    {
      "x": -7,
      "y": 16,
      "z": -9,
      "name": "Rock_Shale",
      "rotation": 2
    },
    {
      "x": -7,
      "y": 10,
      "z": -8,
      "name": "Rock_Shale",
      "rotation": 2
    },
    {
      "x": -7,
      "y": 11,
      "z": -8,
      "name": "Rock_Shale",
      "rotation": 2
    },
    {
      "x": -7,
      "y": 12,
      "z": -8,
      "name": "Rock_Shale",
      "rotation": 2
    },
    {
      "x": -7,
      "y": 13,
      "z": -8,
      "name": "Rock_Shale",
      "rotation": 2
    },
    {
      "x": -7,
      "y": 14,
      "z": -8,
      "name": "Rock_Shale",
      "rotation": 2
    },
    {
      "x": -7,
      "y": 15,
      "z": -8,
      "name": "Rock_Shale",
      "rotation": 2
    },
    {
      "x": -7,
      "y": 16,
      "z": -8,
      "name": "Rock_Shale",
      "rotation": 2
    },
    {
      "x": -7,
      "y": 17,
      "z": -8,
      "name": "Rock_Shale",
      "rotation": 2
    },
    {
      "x": -7,
      "y": 10,
      "z": -7,
      "name": "Rock_Shale",
      "rotation": 2
    },
    {
      "x": -7,
      "y": 11,
      "z": -7,
      "name": "Rock_Shale",
      "rotation": 2
    },
    {
      "x": -7,
      "y": 12,
      "z": -7,
      "name": "Rock_Shale",
      "rotation": 2
    },
    {
      "x": -7,
      "y": 13,
      "z": -7,
      "name": "Rock_Shale",
      "rotation": 2
    },
    {
      "x": -7,
      "y": 14,
      "z": -7,
      "name": "Rock_Shale",
      "rotation": 2
    },
    {
      "x": -7,
      "y": 15,
      "z": -7,
      "name": "Rock_Shale",
      "rotation": 2
    },
    {
      "x": -7,
      "y": 16,
      "z": -7,
      "name": "Rock_Shale",
      "rotation": 2
    },
    {
      "x": -7,
      "y": 17,
      "z": -7,
      "name": "Rock_Shale",
      "rotation": 2
    },
    {
      "x": -6,
      "y": 17,
      "z": -17,
      "name": "Rock_Shale_Brick",
      "rotation": 2
    },
    {
      "x": -6,
      "y": 16,
      "z": -16,
      "name": "Rock_Shale_Brick_Stairs",
      "rotation": 8
    },
    {
      "x": -6,
      "y": 17,
      "z": -16,
      "name": "Rock_Shale_Brick",
      "rotation": 2
    },
    {
      "x": -6,
      "y": 18,
      "z": -16,
      "name": "Rock_Shale",
      "rotation": 2
    },
    {
      "x": -6,
      "y": 19,
      "z": -16,
      "name": "Rock_Shale",
      "rotation": 2
    },
    {
      "x": -6,
      "y": 5,
      "z": -15,
      "name": "Rock_Shale_Brick",
      "rotation": 2
    },
    {
      "x": -6,
      "y": 6,
      "z": -15,
      "name": "Rock_Shale_Brick",
      "rotation": 2
    },
    {
      "x": -6,
      "y": 7,
      "z": -15,
      "name": "Rock_Shale_Brick",
      "rotation": 2
    },
    {
      "x": -6,
      "y": 8,
      "z": -15,
      "name": "Rock_Shale_Brick",
      "rotation": 2
    },
    {
      "x": -6,
      "y": 9,
      "z": -15,
      "name": "Rock_Shale_Brick",
      "rotation": 2
    },
    {
      "x": -6,
      "y": 10,
      "z": -15,
      "name": "Rock_Shale_Brick",
      "rotation": 2
    },
    {
      "x": -6,
      "y": 11,
      "z": -15,
      "name": "Rock_Shale_Brick_Pillar_Base",
      "rotation": 2
    },
    {
      "x": -6,
      "y": 12,
      "z": -15,
      "name": "Rock_Shale_Brick_Pillar_Middle",
      "rotation": 2
    },
    {
      "x": -6,
      "y": 13,
      "z": -15,
      "name": "Rock_Shale_Brick_Pillar_Middle",
      "rotation": 2
    },
    {
      "x": -6,
      "y": 14,
      "z": -15,
      "name": "Rock_Shale_Brick_Pillar_Middle",
      "rotation": 2
    },
    {
      "x": -6,
      "y": 15,
      "z": -15,
      "name": "Rock_Shale_Brick_Pillar_Base",
      "rotation": 10
    },
    {
      "x": -6,
      "y": 16,
      "z": -15,
      "name": "Rock_Shale_Brick",
      "rotation": 2
    },
    {
      "x": -6,
      "y": 17,
      "z": -15,
      "name": "Rock_Shale_Brick",
      "rotation": 2
    },
    {
      "x": -6,
      "y": 18,
      "z": -15,
      "name": "Rock_Shale",
      "rotation": 2
    },
    {
      "x": -6,
      "y": 19,
      "z": -15,
      "name": "Rock_Shale",
      "rotation": 2
    },
    {
      "x": -6,
      "y": 5,
      "z": -14,
      "name": "Rock_Shale_Brick",
      "rotation": 2
    },
    {
      "x": -6,
      "y": 6,
      "z": -14,
      "name": "Rock_Shale_Brick",
      "rotation": 2
    },
    {
      "x": -6,
      "y": 7,
      "z": -14,
      "name": "Rock_Shale_Brick",
      "rotation": 2
    },
    {
      "x": -6,
      "y": 8,
      "z": -14,
      "name": "Rock_Shale_Brick",
      "rotation": 2
    },
    {
      "x": -6,
      "y": 9,
      "z": -14,
      "name": "Rock_Shale_Brick",
      "rotation": 2
    },
    {
      "x": -6,
      "y": 10,
      "z": -14,
      "name": "Rock_Shale_Brick",
      "rotation": 2
    },
    {
      "x": -6,
      "y": 11,
      "z": -14,
      "name": "Rock_Shale_Brick_Pillar_Base",
      "rotation": 2
    },
    {
      "x": -6,
      "y": 12,
      "z": -14,
      "name": "Rock_Shale_Brick_Pillar_Middle",
      "rotation": 2
    },
    {
      "x": -6,
      "y": 13,
      "z": -14,
      "name": "Rock_Shale_Brick_Pillar_Middle",
      "rotation": 2
    },
    {
      "x": -6,
      "y": 14,
      "z": -14,
      "name": "Rock_Shale_Brick_Pillar_Middle",
      "rotation": 2
    },
    {
      "x": -6,
      "y": 15,
      "z": -14,
      "name": "Rock_Shale_Brick_Pillar_Base",
      "rotation": 10
    },
    {
      "x": -6,
      "y": 16,
      "z": -14,
      "name": "Rock_Shale_Brick",
      "rotation": 2
    },
    {
      "x": -6,
      "y": 17,
      "z": -14,
      "name": "Rock_Shale_Brick",
      "rotation": 2
    },
    {
      "x": -6,
      "y": 18,
      "z": -14,
      "name": "Rock_Shale",
      "rotation": 2
    },
    {
      "x": -6,
      "y": 19,
      "z": -14,
      "name": "Rock_Shale",
      "rotation": 2
    },
    {
      "x": -6,
      "y": 20,
      "z": -14,
      "name": "Rock_Shale",
      "rotation": 2
    },
    {
      "x": -6,
      "y": 5,
      "z": -13,
      "name": "Rock_Shale_Brick",
      "rotation": 2
    },
    {
      "x": -6,
      "y": 6,
      "z": -13,
      "name": "Rock_Shale_Brick",
      "rotation": 2
    },
    {
      "x": -6,
      "y": 7,
      "z": -13,
      "name": "Rock_Shale_Brick",
      "rotation": 2
    },
    {
      "x": -6,
      "y": 8,
      "z": -13,
      "name": "Rock_Shale_Brick",
      "rotation": 2
    },
    {
      "x": -6,
      "y": 9,
      "z": -13,
      "name": "Rock_Shale_Brick",
      "rotation": 2
    },
    {
      "x": -6,
      "y": 10,
      "z": -13,
      "name": "Rock_Shale_Brick",
      "rotation": 2
    },
    {
      "x": -6,
      "y": 11,
      "z": -13,
      "name": "Rock_Shale_Brick",
      "rotation": 2
    },
    {
      "x": -6,
      "y": 12,
      "z": -13,
      "name": "Deco_Bone_Pile",
      "rotation": 2
    },
    {
      "x": -6,
      "y": 13,
      "z": -13,
      "name": "Rock_Shale_Brick",
      "rotation": 2
    },
    {
      "x": -6,
      "y": 14,
      "z": -13,
      "name": "Deco_Bone_Pile",
      "rotation": 2
    },
    {
      "x": -6,
      "y": 16,
      "z": -13,
      "name": "Rock_Shale_Brick",
      "rotation": 2
    },
    {
      "x": -6,
      "y": 17,
      "z": -13,
      "name": "Rock_Shale_Brick",
      "rotation": 2
    },
    {
      "x": -6,
      "y": 18,
      "z": -13,
      "name": "Rock_Shale",
      "rotation": 2
    },
    {
      "x": -6,
      "y": 19,
      "z": -13,
      "name": "Rock_Shale",
      "rotation": 2
    },
    {
      "x": -6,
      "y": 20,
      "z": -13,
      "name": "Rock_Shale",
      "rotation": 2
    },
    {
      "x": -6,
      "y": 5,
      "z": -12,
      "name": "Rock_Shale_Brick",
      "rotation": 2
    },
    {
      "x": -6,
      "y": 6,
      "z": -12,
      "name": "Rock_Shale_Brick",
      "rotation": 2
    },
    {
      "x": -6,
      "y": 7,
      "z": -12,
      "name": "Rock_Shale_Brick",
      "rotation": 2
    },
    {
      "x": -6,
      "y": 8,
      "z": -12,
      "name": "Rock_Shale_Brick",
      "rotation": 2
    },
    {
      "x": -6,
      "y": 9,
      "z": -12,
      "name": "Rock_Shale_Brick",
      "rotation": 2
    },
    {
      "x": -6,
      "y": 10,
      "z": -12,
      "name": "Rock_Shale_Brick",
      "rotation": 2
    },
    {
      "x": -6,
      "y": 11,
      "z": -12,
      "name": "Rock_Shale_Brick",
      "rotation": 2
    },
    {
      "x": -6,
      "y": 12,
      "z": -12,
      "name": "Deco_Bone_Pile",
      "rotation": 2
    },
    {
      "x": -6,
      "y": 13,
      "z": -12,
      "name": "Rock_Shale_Brick",
      "rotation": 2
    },
    {
      "x": -6,
      "y": 16,
      "z": -12,
      "name": "Rock_Shale_Brick",
      "rotation": 2
    },
    {
      "x": -6,
      "y": 17,
      "z": -12,
      "name": "Rock_Shale_Brick",
      "rotation": 2
    },
    {
      "x": -6,
      "y": 18,
      "z": -12,
      "name": "Rock_Shale",
      "rotation": 2
    },
    {
      "x": -6,
      "y": 19,
      "z": -12,
      "name": "Rock_Shale",
      "rotation": 2
    },
    {
      "x": -6,
      "y": 20,
      "z": -12,
      "name": "Rock_Shale",
      "rotation": 2
    },
    {
      "x": -6,
      "y": 5,
      "z": -11,
      "name": "Rock_Shale_Brick",
      "rotation": 2
    },
    {
      "x": -6,
      "y": 6,
      "z": -11,
      "name": "Rock_Shale_Brick",
      "rotation": 2
    },
    {
      "x": -6,
      "y": 7,
      "z": -11,
      "name": "Rock_Shale_Brick",
      "rotation": 2
    },
    {
      "x": -6,
      "y": 8,
      "z": -11,
      "name": "Rock_Shale_Brick",
      "rotation": 2
    },
    {
      "x": -6,
      "y": 9,
      "z": -11,
      "name": "Rock_Shale_Brick",
      "rotation": 2
    },
    {
      "x": -6,
      "y": 10,
      "z": -11,
      "name": "Rock_Shale_Brick",
      "rotation": 2
    },
    {
      "x": -6,
      "y": 11,
      "z": -11,
      "name": "Rock_Shale_Brick",
      "rotation": 2
    },
    {
      "x": -6,
      "y": 12,
      "z": -11,
      "name": "Deco_Bone_Skulls",
      "rotation": 2
    },
    {
      "x": -6,
      "y": 13,
      "z": -11,
      "name": "Rock_Shale_Brick",
      "rotation": 2
    },
    {
      "x": -6,
      "y": 14,
      "z": -11,
      "name": "Deco_Bone_Skulls",
      "rotation": 2
    },
    {
      "x": -6,
      "y": 16,
      "z": -11,
      "name": "Rock_Shale_Brick",
      "rotation": 2
    },
    {
      "x": -6,
      "y": 17,
      "z": -11,
      "name": "Rock_Shale_Brick",
      "rotation": 2
    },
    {
      "x": -6,
      "y": 18,
      "z": -11,
      "name": "Rock_Shale_Brick_Half",
      "rotation": 7
    },
    {
      "x": -6,
      "y": 19,
      "z": -11,
      "name": "Rock_Shale_Brick_Half",
      "rotation": 7
    },
    {
      "x": -6,
      "y": 20,
      "z": -11,
      "name": "Rock_Shale_Brick_Half",
      "rotation": 7
    },
    {
      "x": -6,
      "y": 21,
      "z": -11,
      "name": "Rock_Shale_Brick_Half",
      "rotation": 7
    },
    {
      "x": -6,
      "y": 5,
      "z": -10,
      "name": "Rock_Shale_Brick",
      "rotation": 2
    },
    {
      "x": -6,
      "y": 6,
      "z": -10,
      "name": "Rock_Shale_Brick",
      "rotation": 2
    },
    {
      "x": -6,
      "y": 7,
      "z": -10,
      "name": "Rock_Shale_Brick",
      "rotation": 2
    },
    {
      "x": -6,
      "y": 8,
      "z": -10,
      "name": "Rock_Shale_Brick",
      "rotation": 2
    },
    {
      "x": -6,
      "y": 9,
      "z": -10,
      "name": "Rock_Shale_Brick",
      "rotation": 2
    },
    {
      "x": -6,
      "y": 10,
      "z": -10,
      "name": "Rock_Shale_Brick",
      "rotation": 2
    },
    {
      "x": -6,
      "y": 11,
      "z": -10,
      "name": "Rock_Shale_Brick",
      "rotation": 2
    },
    {
      "x": -6,
      "y": 13,
      "z": -10,
      "name": "Rock_Shale_Brick",
      "rotation": 2
    },
    {
      "x": -6,
      "y": 14,
      "z": -10,
      "name": "Deco_Bone_Pile",
      "rotation": 2
    },
    {
      "x": -6,
      "y": 16,
      "z": -10,
      "name": "Rock_Shale_Brick",
      "rotation": 2
    },
    {
      "x": -6,
      "y": 17,
      "z": -10,
      "name": "Rock_Shale_Brick",
      "rotation": 2
    },
    {
      "x": -6,
      "y": 18,
      "z": -10,
      "name": "Rock_Shale",
      "rotation": 2
    },
    {
      "x": -6,
      "y": 19,
      "z": -10,
      "name": "Rock_Shale",
      "rotation": 2
    },
    {
      "x": -6,
      "y": 5,
      "z": -9,
      "name": "Rock_Shale_Brick",
      "rotation": 2
    },
    {
      "x": -6,
      "y": 6,
      "z": -9,
      "name": "Rock_Shale_Brick",
      "rotation": 2
    },
    {
      "x": -6,
      "y": 7,
      "z": -9,
      "name": "Rock_Shale_Brick",
      "rotation": 2
    },
    {
      "x": -6,
      "y": 8,
      "z": -9,
      "name": "Rock_Shale_Brick",
      "rotation": 2
    },
    {
      "x": -6,
      "y": 9,
      "z": -9,
      "name": "Rock_Shale_Brick",
      "rotation": 2
    },
    {
      "x": -6,
      "y": 10,
      "z": -9,
      "name": "Rock_Shale_Brick",
      "rotation": 2
    },
    {
      "x": -6,
      "y": 11,
      "z": -9,
      "name": "Rock_Shale",
      "rotation": 2
    },
    {
      "x": -6,
      "y": 12,
      "z": -9,
      "name": "Rock_Shale",
      "rotation": 2
    },
    {
      "x": -6,
      "y": 13,
      "z": -9,
      "name": "Rock_Shale",
      "rotation": 2
    },
    {
      "x": -6,
      "y": 14,
      "z": -9,
      "name": "Rock_Shale",
      "rotation": 2
    },
    {
      "x": -6,
      "y": 15,
      "z": -9,
      "name": "Rock_Shale",
      "rotation": 2
    },
    {
      "x": -6,
      "y": 16,
      "z": -9,
      "name": "Rock_Shale_Brick",
      "rotation": 2
    },
    {
      "x": -6,
      "y": 17,
      "z": -9,
      "name": "Rock_Shale_Brick",
      "rotation": 2
    },
    {
      "x": -6,
      "y": 18,
      "z": -9,
      "name": "Rock_Shale",
      "rotation": 2
    },
    {
      "x": -6,
      "y": 19,
      "z": -9,
      "name": "Rock_Shale",
      "rotation": 2
    },
    {
      "x": -6,
      "y": 20,
      "z": -9,
      "name": "Rock_Shale",
      "rotation": 2
    },
    {
      "x": -6,
      "y": 5,
      "z": -8,
      "name": "Rock_Shale",
      "rotation": 2
    },
    {
      "x": -6,
      "y": 6,
      "z": -8,
      "name": "Rock_Shale",
      "rotation": 2
    },
    {
      "x": -6,
      "y": 7,
      "z": -8,
      "name": "Rock_Shale",
      "rotation": 2
    },
    {
      "x": -6,
      "y": 8,
      "z": -8,
      "name": "Rock_Shale",
      "rotation": 2
    },
    {
      "x": -6,
      "y": 9,
      "z": -8,
      "name": "Rock_Shale",
      "rotation": 2
    },
    {
      "x": -6,
      "y": 10,
      "z": -8,
      "name": "Rock_Shale",
      "rotation": 2
    },
    {
      "x": -6,
      "y": 11,
      "z": -8,
      "name": "Rock_Shale",
      "rotation": 2
    },
    {
      "x": -6,
      "y": 12,
      "z": -8,
      "name": "Rock_Shale",
      "rotation": 2
    },
    {
      "x": -6,
      "y": 13,
      "z": -8,
      "name": "Rock_Shale",
      "rotation": 2
    },
    {
      "x": -6,
      "y": 14,
      "z": -8,
      "name": "Rock_Shale",
      "rotation": 2
    },
    {
      "x": -6,
      "y": 15,
      "z": -8,
      "name": "Rock_Shale",
      "rotation": 2
    },
    {
      "x": -6,
      "y": 16,
      "z": -8,
      "name": "Rock_Shale",
      "rotation": 2
    },
    {
      "x": -6,
      "y": 17,
      "z": -8,
      "name": "Rock_Shale",
      "rotation": 2
    },
    {
      "x": -6,
      "y": 18,
      "z": -8,
      "name": "Rock_Shale",
      "rotation": 2
    },
    {
      "x": -6,
      "y": 19,
      "z": -8,
      "name": "Rock_Shale",
      "rotation": 2
    },
    {
      "x": -6,
      "y": 20,
      "z": -8,
      "name": "Rock_Shale",
      "rotation": 2
    },
    {
      "x": -6,
      "y": 5,
      "z": -7,
      "name": "Rock_Shale",
      "rotation": 2
    },
    {
      "x": -6,
      "y": 6,
      "z": -7,
      "name": "Rock_Shale",
      "rotation": 2
    },
    {
      "x": -6,
      "y": 7,
      "z": -7,
      "name": "Rock_Shale",
      "rotation": 2
    },
    {
      "x": -6,
      "y": 8,
      "z": -7,
      "name": "Rock_Shale",
      "rotation": 2
    },
    {
      "x": -6,
      "y": 9,
      "z": -7,
      "name": "Rock_Shale",
      "rotation": 2
    },
    {
      "x": -6,
      "y": 10,
      "z": -7,
      "name": "Rock_Shale",
      "rotation": 2
    },
    {
      "x": -6,
      "y": 11,
      "z": -7,
      "name": "Rock_Shale",
      "rotation": 2
    },
    {
      "x": -6,
      "y": 12,
      "z": -7,
      "name": "Rock_Shale",
      "rotation": 2
    },
    {
      "x": -6,
      "y": 13,
      "z": -7,
      "name": "Rock_Shale",
      "rotation": 2
    },
    {
      "x": -6,
      "y": 14,
      "z": -7,
      "name": "Rock_Shale",
      "rotation": 2
    },
    {
      "x": -6,
      "y": 15,
      "z": -7,
      "name": "Rock_Shale",
      "rotation": 2
    },
    {
      "x": -6,
      "y": 16,
      "z": -7,
      "name": "Rock_Shale",
      "rotation": 2
    },
    {
      "x": -6,
      "y": 17,
      "z": -7,
      "name": "Rock_Shale",
      "rotation": 2
    },
    {
      "x": -6,
      "y": 18,
      "z": -7,
      "name": "Rock_Shale",
      "rotation": 2
    },
    {
      "x": -6,
      "y": 19,
      "z": -7,
      "name": "Rock_Shale",
      "rotation": 2
    },
    {
      "x": -6,
      "y": 20,
      "z": -7,
      "name": "Rock_Shale",
      "rotation": 2
    },
    {
      "x": -6,
      "y": 5,
      "z": -6,
      "name": "Rock_Shale_Brick",
      "rotation": 2
    },
    {
      "x": -6,
      "y": 6,
      "z": -6,
      "name": "Rock_Shale_Brick",
      "rotation": 2
    },
    {
      "x": -6,
      "y": 7,
      "z": -6,
      "name": "Rock_Shale_Brick",
      "rotation": 2
    },
    {
      "x": -6,
      "y": 8,
      "z": -6,
      "name": "Rock_Shale_Brick",
      "rotation": 2
    },
    {
      "x": -6,
      "y": 9,
      "z": -6,
      "name": "Rock_Shale_Brick",
      "rotation": 2
    },
    {
      "x": -6,
      "y": 10,
      "z": -6,
      "name": "Rock_Shale_Brick",
      "rotation": 2
    },
    {
      "x": -6,
      "y": 16,
      "z": -6,
      "name": "Rock_Shale_Brick",
      "rotation": 2
    },
    {
      "x": -6,
      "y": 17,
      "z": -6,
      "name": "Rock_Shale_Brick",
      "rotation": 2
    },
    {
      "x": -6,
      "y": 18,
      "z": -6,
      "name": "Rock_Shale_Brick_Half",
      "rotation": 7
    },
    {
      "x": -6,
      "y": 19,
      "z": -6,
      "name": "Rock_Shale_Brick_Half",
      "rotation": 7
    },
    {
      "x": -6,
      "y": 20,
      "z": -6,
      "name": "Rock_Shale_Brick_Half",
      "rotation": 7
    },
    {
      "x": -6,
      "y": 21,
      "z": -6,
      "name": "Rock_Shale_Brick_Half",
      "rotation": 7
    },
    {
      "x": -6,
      "y": 5,
      "z": -5,
      "name": "Rock_Shale_Brick",
      "rotation": 2
    },
    {
      "x": -6,
      "y": 6,
      "z": -5,
      "name": "Rock_Shale_Brick",
      "rotation": 2
    },
    {
      "x": -6,
      "y": 7,
      "z": -5,
      "name": "Rock_Shale_Brick",
      "rotation": 2
    },
    {
      "x": -6,
      "y": 8,
      "z": -5,
      "name": "Rock_Shale_Brick",
      "rotation": 2
    },
    {
      "x": -6,
      "y": 9,
      "z": -5,
      "name": "Rock_Shale_Brick",
      "rotation": 2
    },
    {
      "x": -6,
      "y": 10,
      "z": -5,
      "name": "Rock_Shale_Brick",
      "rotation": 2
    },
    {
      "x": -6,
      "y": 11,
      "z": -5,
      "name": "Rock_Shale_Brick_Pillar_Base",
      "rotation": 2
    },
    {
      "x": -6,
      "y": 12,
      "z": -5,
      "name": "Rock_Shale_Brick_Pillar_Middle",
      "rotation": 2
    },
    {
      "x": -6,
      "y": 13,
      "z": -5,
      "name": "Rock_Shale_Brick_Pillar_Middle",
      "rotation": 2
    },
    {
      "x": -6,
      "y": 14,
      "z": -5,
      "name": "Rock_Shale_Brick_Pillar_Middle",
      "rotation": 2
    },
    {
      "x": -6,
      "y": 15,
      "z": -5,
      "name": "Rock_Shale_Brick_Pillar_Base",
      "rotation": 10
    },
    {
      "x": -6,
      "y": 16,
      "z": -5,
      "name": "Rock_Shale_Brick",
      "rotation": 2
    },
    {
      "x": -6,
      "y": 17,
      "z": -5,
      "name": "Rock_Shale_Brick",
      "rotation": 2
    },
    {
      "x": -6,
      "y": 18,
      "z": -5,
      "name": "Rock_Shale",
      "rotation": 2
    },
    {
      "x": -6,
      "y": 19,
      "z": -5,
      "name": "Rock_Shale",
      "rotation": 2
    },
    {
      "x": -6,
      "y": 20,
      "z": -5,
      "name": "Rock_Shale",
      "rotation": 2
    },
    {
      "x": -6,
      "y": 5,
      "z": -4,
      "name": "Rock_Shale_Brick",
      "rotation": 2
    },
    {
      "x": -6,
      "y": 6,
      "z": -4,
      "name": "Rock_Shale_Brick",
      "rotation": 2
    },
    {
      "x": -6,
      "y": 7,
      "z": -4,
      "name": "Rock_Shale_Brick",
      "rotation": 2
    },
    {
      "x": -6,
      "y": 8,
      "z": -4,
      "name": "Rock_Shale_Brick",
      "rotation": 2
    },
    {
      "x": -6,
      "y": 9,
      "z": -4,
      "name": "Rock_Shale_Brick",
      "rotation": 2
    },
    {
      "x": -6,
      "y": 10,
      "z": -4,
      "name": "Rock_Shale_Brick",
      "rotation": 2
    },
    {
      "x": -6,
      "y": 11,
      "z": -4,
      "name": "Rock_Shale_Brick_Pillar_Base",
      "rotation": 2
    },
    {
      "x": -6,
      "y": 12,
      "z": -4,
      "name": "Rock_Shale_Brick_Pillar_Middle",
      "rotation": 2
    },
    {
      "x": -6,
      "y": 13,
      "z": -4,
      "name": "Rock_Shale_Brick_Pillar_Middle",
      "rotation": 2
    },
    {
      "x": -6,
      "y": 14,
      "z": -4,
      "name": "Rock_Shale_Brick_Pillar_Middle",
      "rotation": 2
    },
    {
      "x": -6,
      "y": 15,
      "z": -4,
      "name": "Rock_Shale_Brick_Pillar_Base",
      "rotation": 10
    },
    {
      "x": -6,
      "y": 16,
      "z": -4,
      "name": "Rock_Shale_Brick",
      "rotation": 2
    },
    {
      "x": -6,
      "y": 17,
      "z": -4,
      "name": "Rock_Shale_Brick",
      "rotation": 2
    },
    {
      "x": -6,
      "y": 18,
      "z": -4,
      "name": "Rock_Shale",
      "rotation": 2
    },
    {
      "x": -6,
      "y": 19,
      "z": -4,
      "name": "Rock_Shale",
      "rotation": 2
    },
    {
      "x": -6,
      "y": 20,
      "z": -4,
      "name": "Rock_Shale",
      "rotation": 2
    },
    {
      "x": -6,
      "y": 16,
      "z": -3,
      "name": "Rock_Shale_Brick_Stairs",
      "rotation": 10
    },
    {
      "x": -6,
      "y": 17,
      "z": -3,
      "name": "Rock_Shale_Brick",
      "rotation": 2
    },
    {
      "x": -6,
      "y": 19,
      "z": -3,
      "name": "Rock_Shale",
      "rotation": 2
    },
    {
      "x": -6,
      "y": 20,
      "z": -3,
      "name": "Rock_Shale",
      "rotation": 2
    },
    {
      "x": -6,
      "y": 17,
      "z": -2,
      "name": "Rock_Shale_Brick",
      "rotation": 2
    },
    {
      "x": -5,
      "y": 17,
      "z": -17,
      "name": "Rock_Shale_Brick",
      "rotation": 2
    },
    {
      "x": -5,
      "y": 16,
      "z": -16,
      "name": "Rock_Shale_Brick_Stairs",
      "rotation": 8
    },
    {
      "x": -5,
      "y": 17,
      "z": -16,
      "name": "Rock_Shale_Brick",
      "rotation": 2
    },
    {
      "x": -5,
      "y": 18,
      "z": -16,
      "name": "Rock_Shale",
      "rotation": 2
    },
    {
      "x": -5,
      "y": 19,
      "z": -16,
      "name": "Rock_Shale",
      "rotation": 2
    },
    {
      "x": -5,
      "y": 21,
      "z": -16,
      "name": "Rock_Shale",
      "rotation": 2
    },
    {
      "x": -5,
      "y": 5,
      "z": -15,
      "name": "Rock_Shale_Brick",
      "rotation": 2
    },
    {
      "x": -5,
      "y": 6,
      "z": -15,
      "name": "Rock_Shale_Brick",
      "rotation": 2
    },
    {
      "x": -5,
      "y": 7,
      "z": -15,
      "name": "Rock_Shale_Brick",
      "rotation": 2
    },
    {
      "x": -5,
      "y": 8,
      "z": -15,
      "name": "Rock_Shale_Brick",
      "rotation": 2
    },
    {
      "x": -5,
      "y": 9,
      "z": -15,
      "name": "Rock_Shale_Brick",
      "rotation": 2
    },
    {
      "x": -5,
      "y": 10,
      "z": -15,
      "name": "Rock_Shale_Brick",
      "rotation": 2
    },
    {
      "x": -5,
      "y": 11,
      "z": -15,
      "name": "Rock_Shale_Brick_Pillar_Base",
      "rotation": 2
    },
    {
      "x": -5,
      "y": 12,
      "z": -15,
      "name": "Rock_Shale_Brick_Pillar_Middle",
      "rotation": 2
    },
    {
      "x": -5,
      "y": 13,
      "z": -15,
      "name": "Rock_Shale_Brick_Pillar_Middle",
      "rotation": 2
    },
    {
      "x": -5,
      "y": 14,
      "z": -15,
      "name": "Rock_Shale_Brick_Pillar_Middle",
      "rotation": 2
    },
    {
      "x": -5,
      "y": 15,
      "z": -15,
      "name": "Rock_Shale_Brick_Pillar_Base",
      "rotation": 10
    },
    {
      "x": -5,
      "y": 16,
      "z": -15,
      "name": "Rock_Shale_Brick",
      "rotation": 2
    },
    {
      "x": -5,
      "y": 17,
      "z": -15,
      "name": "Rock_Shale_Brick",
      "rotation": 2
    },
    {
      "x": -5,
      "y": 18,
      "z": -15,
      "name": "Rock_Shale",
      "rotation": 2
    },
    {
      "x": -5,
      "y": 19,
      "z": -15,
      "name": "Rock_Shale",
      "rotation": 2
    },
    {
      "x": -5,
      "y": 20,
      "z": -15,
      "name": "Rock_Shale",
      "rotation": 2
    },
    {
      "x": -5,
      "y": 21,
      "z": -15,
      "name": "Rock_Shale",
      "rotation": 2
    },
    {
      "x": -5,
      "y": 22,
      "z": -15,
      "name": "Rock_Shale",
      "rotation": 2
    },
    {
      "x": -5,
      "y": 5,
      "z": -14,
      "name": "Rock_Shale_Brick",
      "rotation": 2
    },
    {
      "x": -5,
      "y": 6,
      "z": -14,
      "name": "Rock_Shale_Brick",
      "rotation": 2
    },
    {
      "x": -5,
      "y": 7,
      "z": -14,
      "name": "Rock_Shale_Brick",
      "rotation": 2
    },
    {
      "x": -5,
      "y": 8,
      "z": -14,
      "name": "Rock_Shale_Brick",
      "rotation": 2
    },
    {
      "x": -5,
      "y": 9,
      "z": -14,
      "name": "Rock_Shale_Brick",
      "rotation": 2
    },
    {
      "x": -5,
      "y": 10,
      "z": -14,
      "name": "Rock_Shale_Brick",
      "rotation": 2
    },
    {
      "x": -5,
      "y": 11,
      "z": -14,
      "name": "Rock_Shale_Brick",
      "rotation": 2
    },
    {
      "x": -5,
      "y": 12,
      "z": -14,
      "name": "Rock_Shale_Brick",
      "rotation": 2
    },
    {
      "x": -5,
      "y": 13,
      "z": -14,
      "name": "Rock_Shale_Brick",
      "rotation": 2
    },
    {
      "x": -5,
      "y": 14,
      "z": -14,
      "name": "Rock_Shale_Brick",
      "rotation": 2
    },
    {
      "x": -5,
      "y": 15,
      "z": -14,
      "name": "Rock_Shale_Brick",
      "rotation": 2
    },
    {
      "x": -5,
      "y": 16,
      "z": -14,
      "name": "Rock_Shale_Brick",
      "rotation": 2
    },
    {
      "x": -5,
      "y": 17,
      "z": -14,
      "name": "Rock_Shale_Brick",
      "rotation": 2
    },
    {
      "x": -5,
      "y": 18,
      "z": -14,
      "name": "Rock_Shale",
      "rotation": 2
    },
    {
      "x": -5,
      "y": 19,
      "z": -14,
      "name": "Rock_Shale",
      "rotation": 2
    },
    {
      "x": -5,
      "y": 20,
      "z": -14,
      "name": "Rock_Shale",
      "rotation": 2
    },
    {
      "x": -5,
      "y": 21,
      "z": -14,
      "name": "Rock_Shale",
      "rotation": 2
    },
    {
      "x": -5,
      "y": 22,
      "z": -14,
      "name": "Rock_Shale",
      "rotation": 2
    },
    {
      "x": -5,
      "y": 5,
      "z": -13,
      "name": "Rock_Shale",
      "rotation": 2
    },
    {
      "x": -5,
      "y": 6,
      "z": -13,
      "name": "Rock_Shale",
      "rotation": 2
    },
    {
      "x": -5,
      "y": 7,
      "z": -13,
      "name": "Rock_Shale",
      "rotation": 2
    },
    {
      "x": -5,
      "y": 8,
      "z": -13,
      "name": "Rock_Shale",
      "rotation": 2
    },
    {
      "x": -5,
      "y": 9,
      "z": -13,
      "name": "Rock_Shale",
      "rotation": 2
    },
    {
      "x": -5,
      "y": 10,
      "z": -13,
      "name": "Rock_Shale",
      "rotation": 2
    },
    {
      "x": -5,
      "y": 11,
      "z": -13,
      "name": "Rock_Shale_Brick",
      "rotation": 2
    },
    {
      "x": -5,
      "y": 12,
      "z": -13,
      "name": "Rock_Shale_Cobble",
      "rotation": 2
    },
    {
      "x": -5,
      "y": 13,
      "z": -13,
      "name": "Rock_Shale_Cobble",
      "rotation": 2
    },
    {
      "x": -5,
      "y": 14,
      "z": -13,
      "name": "Rock_Shale_Cobble",
      "rotation": 2
    },
    {
      "x": -5,
      "y": 15,
      "z": -13,
      "name": "Rock_Shale_Brick",
      "rotation": 2
    },
    {
      "x": -5,
      "y": 16,
      "z": -13,
      "name": "Rock_Shale_Brick",
      "rotation": 2
    },
    {
      "x": -5,
      "y": 17,
      "z": -13,
      "name": "Rock_Shale_Brick",
      "rotation": 2
    },
    {
      "x": -5,
      "y": 18,
      "z": -13,
      "name": "Rock_Shale",
      "rotation": 2
    },
    {
      "x": -5,
      "y": 19,
      "z": -13,
      "name": "Rock_Shale",
      "rotation": 2
    },
    {
      "x": -5,
      "y": 20,
      "z": -13,
      "name": "Rock_Shale",
      "rotation": 2
    },
    {
      "x": -5,
      "y": 21,
      "z": -13,
      "name": "Rock_Shale",
      "rotation": 2
    },
    {
      "x": -5,
      "y": 5,
      "z": -12,
      "name": "Rock_Shale_Brick",
      "rotation": 2
    },
    {
      "x": -5,
      "y": 6,
      "z": -12,
      "name": "Rock_Shale_Brick",
      "rotation": 2
    },
    {
      "x": -5,
      "y": 7,
      "z": -12,
      "name": "Rock_Shale_Brick",
      "rotation": 2
    },
    {
      "x": -5,
      "y": 8,
      "z": -12,
      "name": "Rock_Shale_Brick",
      "rotation": 2
    },
    {
      "x": -5,
      "y": 9,
      "z": -12,
      "name": "Rock_Shale",
      "rotation": 2
    },
    {
      "x": -5,
      "y": 10,
      "z": -12,
      "name": "Rock_Shale",
      "rotation": 2
    },
    {
      "x": -5,
      "y": 11,
      "z": -12,
      "name": "Rock_Shale_Brick",
      "rotation": 2
    },
    {
      "x": -5,
      "y": 12,
      "z": -12,
      "name": "Rock_Shale_Cobble",
      "rotation": 2
    },
    {
      "x": -5,
      "y": 13,
      "z": -12,
      "name": "Rock_Shale_Cobble",
      "rotation": 2
    },
    {
      "x": -5,
      "y": 14,
      "z": -12,
      "name": "Rock_Shale_Cobble",
      "rotation": 2
    },
    {
      "x": -5,
      "y": 15,
      "z": -12,
      "name": "Rock_Shale_Brick",
      "rotation": 2
    },
    {
      "x": -5,
      "y": 16,
      "z": -12,
      "name": "Rock_Shale_Brick",
      "rotation": 2
    },
    {
      "x": -5,
      "y": 17,
      "z": -12,
      "name": "Rock_Shale_Brick",
      "rotation": 2
    },
    {
      "x": -5,
      "y": 18,
      "z": -12,
      "name": "Rock_Shale",
      "rotation": 2
    },
    {
      "x": -5,
      "y": 19,
      "z": -12,
      "name": "Rock_Shale",
      "rotation": 2
    },
    {
      "x": -5,
      "y": 20,
      "z": -12,
      "name": "Rock_Shale",
      "rotation": 2
    },
    {
      "x": -5,
      "y": 21,
      "z": -12,
      "name": "Rock_Shale",
      "rotation": 2
    },
    {
      "x": -5,
      "y": 5,
      "z": -11,
      "name": "Rock_Shale_Brick",
      "rotation": 2
    },
    {
      "x": -5,
      "y": 6,
      "z": -11,
      "name": "Rock_Shale_Brick",
      "rotation": 2
    },
    {
      "x": -5,
      "y": 7,
      "z": -11,
      "name": "Rock_Shale_Brick",
      "rotation": 2
    },
    {
      "x": -5,
      "y": 8,
      "z": -11,
      "name": "Rock_Shale",
      "rotation": 2
    },
    {
      "x": -5,
      "y": 9,
      "z": -11,
      "name": "Rock_Shale",
      "rotation": 2
    },
    {
      "x": -5,
      "y": 10,
      "z": -11,
      "name": "Rock_Shale",
      "rotation": 2
    },
    {
      "x": -5,
      "y": 11,
      "z": -11,
      "name": "Rock_Shale_Brick",
      "rotation": 2
    },
    {
      "x": -5,
      "y": 12,
      "z": -11,
      "name": "Rock_Shale_Cobble",
      "rotation": 2
    },
    {
      "x": -5,
      "y": 13,
      "z": -11,
      "name": "Rock_Shale_Cobble",
      "rotation": 2
    },
    {
      "x": -5,
      "y": 14,
      "z": -11,
      "name": "Rock_Shale_Cobble",
      "rotation": 2
    },
    {
      "x": -5,
      "y": 15,
      "z": -11,
      "name": "Rock_Shale_Brick",
      "rotation": 2
    },
    {
      "x": -5,
      "y": 16,
      "z": -11,
      "name": "Rock_Shale_Brick",
      "rotation": 2
    },
    {
      "x": -5,
      "y": 17,
      "z": -11,
      "name": "Rock_Shale_Brick",
      "rotation": 2
    },
    {
      "x": -5,
      "y": 18,
      "z": -11,
      "name": "Rock_Shale",
      "rotation": 2
    },
    {
      "x": -5,
      "y": 19,
      "z": -11,
      "name": "Rock_Shale",
      "rotation": 2
    },
    {
      "x": -5,
      "y": 20,
      "z": -11,
      "name": "Rock_Shale",
      "rotation": 2
    },
    {
      "x": -5,
      "y": 21,
      "z": -11,
      "name": "Rock_Shale",
      "rotation": 2
    },
    {
      "x": -5,
      "y": 22,
      "z": -11,
      "name": "Rock_Shale_Brick_Stairs",
      "rotation": 3
    },
    {
      "x": -5,
      "y": 5,
      "z": -10,
      "name": "Rock_Shale_Brick",
      "rotation": 2
    },
    {
      "x": -5,
      "y": 6,
      "z": -10,
      "name": "Rock_Shale_Brick",
      "rotation": 2
    },
    {
      "x": -5,
      "y": 7,
      "z": -10,
      "name": "Rock_Shale",
      "rotation": 2
    },
    {
      "x": -5,
      "y": 8,
      "z": -10,
      "name": "Rock_Shale",
      "rotation": 2
    },
    {
      "x": -5,
      "y": 9,
      "z": -10,
      "name": "Rock_Shale",
      "rotation": 2
    },
    {
      "x": -5,
      "y": 10,
      "z": -10,
      "name": "Rock_Shale",
      "rotation": 2
    },
    {
      "x": -5,
      "y": 11,
      "z": -10,
      "name": "Rock_Shale_Brick",
      "rotation": 2
    },
    {
      "x": -5,
      "y": 12,
      "z": -10,
      "name": "Rock_Shale_Cobble",
      "rotation": 2
    },
    {
      "x": -5,
      "y": 13,
      "z": -10,
      "name": "Rock_Shale_Cobble",
      "rotation": 2
    },
    {
      "x": -5,
      "y": 14,
      "z": -10,
      "name": "Rock_Shale_Cobble",
      "rotation": 2
    },
    {
      "x": -5,
      "y": 15,
      "z": -10,
      "name": "Rock_Shale_Brick",
      "rotation": 2
    },
    {
      "x": -5,
      "y": 16,
      "z": -10,
      "name": "Rock_Shale_Brick",
      "rotation": 2
    },
    {
      "x": -5,
      "y": 17,
      "z": -10,
      "name": "Rock_Shale_Brick",
      "rotation": 2
    },
    {
      "x": -5,
      "y": 18,
      "z": -10,
      "name": "Rock_Shale",
      "rotation": 2
    },
    {
      "x": -5,
      "y": 19,
      "z": -10,
      "name": "Rock_Shale",
      "rotation": 2
    },
    {
      "x": -5,
      "y": 20,
      "z": -10,
      "name": "Rock_Shale",
      "rotation": 2
    },
    {
      "x": -5,
      "y": 21,
      "z": -10,
      "name": "Rock_Shale",
      "rotation": 2
    },
    {
      "x": -5,
      "y": 5,
      "z": -9,
      "name": "Rock_Shale_Brick",
      "rotation": 2
    },
    {
      "x": -5,
      "y": 6,
      "z": -9,
      "name": "Rock_Shale",
      "rotation": 2
    },
    {
      "x": -5,
      "y": 7,
      "z": -9,
      "name": "Rock_Shale",
      "rotation": 2
    },
    {
      "x": -5,
      "y": 8,
      "z": -9,
      "name": "Rock_Shale",
      "rotation": 2
    },
    {
      "x": -5,
      "y": 9,
      "z": -9,
      "name": "Rock_Shale",
      "rotation": 2
    },
    {
      "x": -5,
      "y": 10,
      "z": -9,
      "name": "Rock_Shale",
      "rotation": 2
    },
    {
      "x": -5,
      "y": 11,
      "z": -9,
      "name": "Rock_Shale_Brick",
      "rotation": 2
    },
    {
      "x": -5,
      "y": 12,
      "z": -9,
      "name": "Rock_Shale_Brick",
      "rotation": 2
    },
    {
      "x": -5,
      "y": 13,
      "z": -9,
      "name": "Rock_Shale_Brick",
      "rotation": 2
    },
    {
      "x": -5,
      "y": 14,
      "z": -9,
      "name": "Rock_Shale_Brick",
      "rotation": 2
    },
    {
      "x": -5,
      "y": 15,
      "z": -9,
      "name": "Rock_Shale_Brick",
      "rotation": 2
    },
    {
      "x": -5,
      "y": 16,
      "z": -9,
      "name": "Rock_Shale_Brick",
      "rotation": 2
    },
    {
      "x": -5,
      "y": 17,
      "z": -9,
      "name": "Rock_Shale_Brick",
      "rotation": 2
    },
    {
      "x": -5,
      "y": 18,
      "z": -9,
      "name": "Rock_Shale",
      "rotation": 2
    },
    {
      "x": -5,
      "y": 19,
      "z": -9,
      "name": "Rock_Shale",
      "rotation": 2
    },
    {
      "x": -5,
      "y": 20,
      "z": -9,
      "name": "Rock_Shale",
      "rotation": 2
    },
    {
      "x": -5,
      "y": 21,
      "z": -9,
      "name": "Rock_Shale",
      "rotation": 2
    },
    {
      "x": -5,
      "y": 5,
      "z": -8,
      "name": "Rock_Shale",
      "rotation": 2
    },
    {
      "x": -5,
      "y": 6,
      "z": -8,
      "name": "Rock_Shale",
      "rotation": 2
    },
    {
      "x": -5,
      "y": 7,
      "z": -8,
      "name": "Rock_Shale",
      "rotation": 2
    },
    {
      "x": -5,
      "y": 8,
      "z": -8,
      "name": "Rock_Shale",
      "rotation": 2
    },
    {
      "x": -5,
      "y": 9,
      "z": -8,
      "name": "Rock_Shale",
      "rotation": 2
    },
    {
      "x": -5,
      "y": 10,
      "z": -8,
      "name": "Rock_Basalt",
      "rotation": 2
    },
    {
      "x": -5,
      "y": 11,
      "z": -8,
      "name": "Rock_Shale_Brick",
      "rotation": 2
    },
    {
      "x": -5,
      "y": 12,
      "z": -8,
      "name": "Rock_Shale_Brick",
      "rotation": 2
    },
    {
      "x": -5,
      "y": 13,
      "z": -8,
      "name": "Rock_Shale_Brick",
      "rotation": 2
    },
    {
      "x": -5,
      "y": 14,
      "z": -8,
      "name": "Rock_Shale_Brick",
      "rotation": 2
    },
    {
      "x": -5,
      "y": 15,
      "z": -8,
      "name": "Rock_Shale_Brick",
      "rotation": 2
    },
    {
      "x": -5,
      "y": 16,
      "z": -8,
      "name": "Rock_Shale_Brick",
      "rotation": 2
    },
    {
      "x": -5,
      "y": 17,
      "z": -8,
      "name": "Rock_Shale_Brick",
      "rotation": 2
    },
    {
      "x": -5,
      "y": 18,
      "z": -8,
      "name": "Rock_Shale",
      "rotation": 2
    },
    {
      "x": -5,
      "y": 19,
      "z": -8,
      "name": "Rock_Shale",
      "rotation": 2
    },
    {
      "x": -5,
      "y": 20,
      "z": -8,
      "name": "Rock_Shale",
      "rotation": 2
    },
    {
      "x": -5,
      "y": 21,
      "z": -8,
      "name": "Rock_Shale",
      "rotation": 2
    },
    {
      "x": -5,
      "y": 4,
      "z": -7,
      "name": "Rock_Shale",
      "rotation": 2
    },
    {
      "x": -5,
      "y": 5,
      "z": -7,
      "name": "Rock_Shale",
      "rotation": 2
    },
    {
      "x": -5,
      "y": 6,
      "z": -7,
      "name": "Rock_Shale",
      "rotation": 2
    },
    {
      "x": -5,
      "y": 7,
      "z": -7,
      "name": "Rock_Shale",
      "rotation": 2
    },
    {
      "x": -5,
      "y": 8,
      "z": -7,
      "name": "Rock_Shale",
      "rotation": 2
    },
    {
      "x": -5,
      "y": 9,
      "z": -7,
      "name": "Rock_Basalt",
      "rotation": 2
    },
    {
      "x": -5,
      "y": 10,
      "z": -7,
      "name": "Rock_Basalt",
      "rotation": 2
    },
    {
      "x": -5,
      "y": 11,
      "z": -7,
      "name": "Rock_Shale_Brick",
      "rotation": 2
    },
    {
      "x": -5,
      "y": 12,
      "z": -7,
      "name": "Rock_Shale_Brick",
      "rotation": 2
    },
    {
      "x": -5,
      "y": 13,
      "z": -7,
      "name": "Rock_Shale_Brick",
      "rotation": 2
    },
    {
      "x": -5,
      "y": 14,
      "z": -7,
      "name": "Rock_Shale_Brick",
      "rotation": 2
    },
    {
      "x": -5,
      "y": 15,
      "z": -7,
      "name": "Rock_Shale_Brick",
      "rotation": 2
    },
    {
      "x": -5,
      "y": 16,
      "z": -7,
      "name": "Rock_Shale_Brick",
      "rotation": 2
    },
    {
      "x": -5,
      "y": 17,
      "z": -7,
      "name": "Rock_Shale_Brick",
      "rotation": 2
    },
    {
      "x": -5,
      "y": 18,
      "z": -7,
      "name": "Rock_Shale",
      "rotation": 2
    },
    {
      "x": -5,
      "y": 19,
      "z": -7,
      "name": "Rock_Shale",
      "rotation": 2
    },
    {
      "x": -5,
      "y": 20,
      "z": -7,
      "name": "Rock_Shale",
      "rotation": 2
    },
    {
      "x": -5,
      "y": 21,
      "z": -7,
      "name": "Rock_Shale",
      "rotation": 2
    },
    {
      "x": -5,
      "y": 3,
      "z": -6,
      "name": "Rock_Shale",
      "rotation": 2
    },
    {
      "x": -5,
      "y": 4,
      "z": -6,
      "name": "Rock_Shale",
      "rotation": 2
    },
    {
      "x": -5,
      "y": 5,
      "z": -6,
      "name": "Rock_Shale",
      "rotation": 2
    },
    {
      "x": -5,
      "y": 6,
      "z": -6,
      "name": "Rock_Shale",
      "rotation": 2
    },
    {
      "x": -5,
      "y": 7,
      "z": -6,
      "name": "Rock_Shale",
      "rotation": 2
    },
    {
      "x": -5,
      "y": 8,
      "z": -6,
      "name": "Rock_Shale",
      "rotation": 2
    },
    {
      "x": -5,
      "y": 9,
      "z": -6,
      "name": "Rock_Shale",
      "rotation": 2
    },
    {
      "x": -5,
      "y": 10,
      "z": -6,
      "name": "Rock_Shale",
      "rotation": 2
    },
    {
      "x": -5,
      "y": 11,
      "z": -6,
      "name": "Rock_Shale_Brick",
      "rotation": 2
    },
    {
      "x": -5,
      "y": 12,
      "z": -6,
      "name": "Rock_Shale_Brick",
      "rotation": 2
    },
    {
      "x": -5,
      "y": 13,
      "z": -6,
      "name": "Rock_Shale_Brick",
      "rotation": 2
    },
    {
      "x": -5,
      "y": 14,
      "z": -6,
      "name": "Rock_Shale_Brick",
      "rotation": 2
    },
    {
      "x": -5,
      "y": 15,
      "z": -6,
      "name": "Rock_Shale_Brick",
      "rotation": 2
    },
    {
      "x": -5,
      "y": 16,
      "z": -6,
      "name": "Rock_Shale_Brick",
      "rotation": 2
    },
    {
      "x": -5,
      "y": 17,
      "z": -6,
      "name": "Rock_Shale_Brick",
      "rotation": 2
    },
    {
      "x": -5,
      "y": 18,
      "z": -6,
      "name": "Rock_Shale",
      "rotation": 2
    },
    {
      "x": -5,
      "y": 19,
      "z": -6,
      "name": "Rock_Shale",
      "rotation": 2
    },
    {
      "x": -5,
      "y": 20,
      "z": -6,
      "name": "Rock_Shale",
      "rotation": 2
    },
    {
      "x": -5,
      "y": 21,
      "z": -6,
      "name": "Rock_Shale",
      "rotation": 2
    },
    {
      "x": -5,
      "y": 22,
      "z": -6,
      "name": "Rock_Shale_Brick",
      "rotation": 2
    },
    {
      "x": -5,
      "y": 2,
      "z": -5,
      "name": "Rock_Shale",
      "rotation": 2
    },
    {
      "x": -5,
      "y": 3,
      "z": -5,
      "name": "Rock_Shale",
      "rotation": 2
    },
    {
      "x": -5,
      "y": 4,
      "z": -5,
      "name": "Rock_Shale",
      "rotation": 2
    },
    {
      "x": -5,
      "y": 5,
      "z": -5,
      "name": "Rock_Shale",
      "rotation": 2
    },
    {
      "x": -5,
      "y": 6,
      "z": -5,
      "name": "Rock_Shale",
      "rotation": 2
    },
    {
      "x": -5,
      "y": 7,
      "z": -5,
      "name": "Rock_Basalt",
      "rotation": 2
    },
    {
      "x": -5,
      "y": 8,
      "z": -5,
      "name": "Rock_Basalt",
      "rotation": 2
    },
    {
      "x": -5,
      "y": 9,
      "z": -5,
      "name": "Rock_Shale",
      "rotation": 2
    },
    {
      "x": -5,
      "y": 10,
      "z": -5,
      "name": "Rock_Shale_Brick",
      "rotation": 2
    },
    {
      "x": -5,
      "y": 11,
      "z": -5,
      "name": "Rock_Shale_Brick",
      "rotation": 2
    },
    {
      "x": -5,
      "y": 12,
      "z": -5,
      "name": "Rock_Shale_Brick",
      "rotation": 2
    },
    {
      "x": -5,
      "y": 13,
      "z": -5,
      "name": "Rock_Shale_Brick",
      "rotation": 2
    },
    {
      "x": -5,
      "y": 14,
      "z": -5,
      "name": "Rock_Shale_Brick",
      "rotation": 2
    },
    {
      "x": -5,
      "y": 15,
      "z": -5,
      "name": "Rock_Shale_Brick",
      "rotation": 2
    },
    {
      "x": -5,
      "y": 16,
      "z": -5,
      "name": "Rock_Shale_Brick",
      "rotation": 2
    },
    {
      "x": -5,
      "y": 17,
      "z": -5,
      "name": "Rock_Shale_Brick",
      "rotation": 2
    },
    {
      "x": -5,
      "y": 18,
      "z": -5,
      "name": "Rock_Shale",
      "rotation": 2
    },
    {
      "x": -5,
      "y": 19,
      "z": -5,
      "name": "Rock_Shale",
      "rotation": 2
    },
    {
      "x": -5,
      "y": 20,
      "z": -5,
      "name": "Rock_Shale",
      "rotation": 2
    },
    {
      "x": -5,
      "y": 21,
      "z": -5,
      "name": "Rock_Shale",
      "rotation": 2
    },
    {
      "x": -5,
      "y": 1,
      "z": -4,
      "name": "Rock_Shale",
      "rotation": 2
    },
    {
      "x": -5,
      "y": 2,
      "z": -4,
      "name": "Rock_Shale",
      "rotation": 2
    },
    {
      "x": -5,
      "y": 3,
      "z": -4,
      "name": "Rock_Shale",
      "rotation": 2
    },
    {
      "x": -5,
      "y": 4,
      "z": -4,
      "name": "Rock_Shale",
      "rotation": 2
    },
    {
      "x": -5,
      "y": 5,
      "z": -4,
      "name": "Rock_Shale",
      "rotation": 2
    },
    {
      "x": -5,
      "y": 6,
      "z": -4,
      "name": "Rock_Basalt",
      "rotation": 2
    },
    {
      "x": -5,
      "y": 7,
      "z": -4,
      "name": "Rock_Basalt",
      "rotation": 2
    },
    {
      "x": -5,
      "y": 8,
      "z": -4,
      "name": "Rock_Shale",
      "rotation": 2
    },
    {
      "x": -5,
      "y": 9,
      "z": -4,
      "name": "Rock_Shale",
      "rotation": 2
    },
    {
      "x": -5,
      "y": 10,
      "z": -4,
      "name": "Rock_Shale_Brick",
      "rotation": 2
    },
    {
      "x": -5,
      "y": 11,
      "z": -4,
      "name": "Rock_Shale_Brick_Pillar_Base",
      "rotation": 2
    },
    {
      "x": -5,
      "y": 12,
      "z": -4,
      "name": "Rock_Shale_Brick_Pillar_Middle",
      "rotation": 2
    },
    {
      "x": -5,
      "y": 13,
      "z": -4,
      "name": "Rock_Shale_Brick_Pillar_Middle",
      "rotation": 2
    },
    {
      "x": -5,
      "y": 14,
      "z": -4,
      "name": "Rock_Shale_Brick_Pillar_Middle",
      "rotation": 2
    },
    {
      "x": -5,
      "y": 15,
      "z": -4,
      "name": "Rock_Shale_Brick_Pillar_Base",
      "rotation": 10
    },
    {
      "x": -5,
      "y": 16,
      "z": -4,
      "name": "Rock_Shale_Brick",
      "rotation": 2
    },
    {
      "x": -5,
      "y": 17,
      "z": -4,
      "name": "Rock_Shale_Brick",
      "rotation": 2
    },
    {
      "x": -5,
      "y": 18,
      "z": -4,
      "name": "Rock_Shale",
      "rotation": 2
    },
    {
      "x": -5,
      "y": 19,
      "z": -4,
      "name": "Rock_Shale",
      "rotation": 2
    },
    {
      "x": -5,
      "y": 20,
      "z": -4,
      "name": "Rock_Shale",
      "rotation": 2
    },
    {
      "x": -5,
      "y": 21,
      "z": -4,
      "name": "Rock_Shale",
      "rotation": 2
    },
    {
      "x": -5,
      "y": 0,
      "z": -3,
      "name": "Rock_Shale_Brick_Smooth",
      "rotation": 2
    },
    {
      "x": -5,
      "y": 1,
      "z": -3,
      "name": "Rock_Shale",
      "rotation": 2
    },
    {
      "x": -5,
      "y": 2,
      "z": -3,
      "name": "Rock_Shale",
      "rotation": 2
    },
    {
      "x": -5,
      "y": 3,
      "z": -3,
      "name": "Rock_Shale",
      "rotation": 2
    },
    {
      "x": -5,
      "y": 4,
      "z": -3,
      "name": "Rock_Shale",
      "rotation": 2
    },
    {
      "x": -5,
      "y": 5,
      "z": -3,
      "name": "Rock_Basalt",
      "rotation": 2
    },
    {
      "x": -5,
      "y": 6,
      "z": -3,
      "name": "Rock_Basalt",
      "rotation": 2
    },
    {
      "x": -5,
      "y": 7,
      "z": -3,
      "name": "Rock_Shale",
      "rotation": 2
    },
    {
      "x": -5,
      "y": 8,
      "z": -3,
      "name": "Rock_Shale",
      "rotation": 2
    },
    {
      "x": -5,
      "y": 16,
      "z": -3,
      "name": "Rock_Shale_Brick_Stairs",
      "rotation": 10
    },
    {
      "x": -5,
      "y": 17,
      "z": -3,
      "name": "Rock_Shale_Brick",
      "rotation": 2
    },
    {
      "x": -5,
      "y": 18,
      "z": -3,
      "name": "Rock_Shale",
      "rotation": 2
    },
    {
      "x": -5,
      "y": 19,
      "z": -3,
      "name": "Rock_Shale",
      "rotation": 2
    },
    {
      "x": -5,
      "y": 20,
      "z": -3,
      "name": "Rock_Shale",
      "rotation": 2
    },
    {
      "x": -5,
      "y": 0,
      "z": -2,
      "name": "Rock_Shale_Brick_Smooth",
      "rotation": 2
    },
    {
      "x": -5,
      "y": 1,
      "z": -2,
      "name": "Rock_Shale",
      "rotation": 2
    },
    {
      "x": -5,
      "y": 2,
      "z": -2,
      "name": "Rock_Shale",
      "rotation": 2
    },
    {
      "x": -5,
      "y": 3,
      "z": -2,
      "name": "Rock_Shale",
      "rotation": 2
    },
    {
      "x": -5,
      "y": 4,
      "z": -2,
      "name": "Rock_Shale",
      "rotation": 2
    },
    {
      "x": -5,
      "y": 5,
      "z": -2,
      "name": "Rock_Shale",
      "rotation": 2
    },
    {
      "x": -5,
      "y": 6,
      "z": -2,
      "name": "Rock_Shale",
      "rotation": 2
    },
    {
      "x": -5,
      "y": 7,
      "z": -2,
      "name": "Rock_Shale",
      "rotation": 2
    },
    {
      "x": -5,
      "y": 17,
      "z": -2,
      "name": "Rock_Shale_Brick",
      "rotation": 2
    },
    {
      "x": -5,
      "y": 0,
      "z": -1,
      "name": "Rock_Shale_Brick_Smooth",
      "rotation": 2
    },
    {
      "x": -5,
      "y": 1,
      "z": -1,
      "name": "Rock_Shale",
      "rotation": 2
    },
    {
      "x": -5,
      "y": 2,
      "z": -1,
      "name": "Rock_Shale",
      "rotation": 2
    },
    {
      "x": -5,
      "y": 3,
      "z": -1,
      "name": "Rock_Shale",
      "rotation": 2
    },
    {
      "x": -5,
      "y": 4,
      "z": -1,
      "name": "Rock_Shale",
      "rotation": 2
    },
    {
      "x": -5,
      "y": 5,
      "z": -1,
      "name": "Rock_Shale",
      "rotation": 2
    },
    {
      "x": -5,
      "y": 6,
      "z": -1,
      "name": "Rock_Shale",
      "rotation": 2
    },
    {
      "x": -5,
      "y": 0,
      "z": 0,
      "name": "Rock_Shale_Brick_Smooth",
      "rotation": 2
    },
    {
      "x": -5,
      "y": 1,
      "z": 0,
      "name": "Rock_Shale",
      "rotation": 2
    },
    {
      "x": -5,
      "y": 2,
      "z": 0,
      "name": "Rock_Shale",
      "rotation": 2
    },
    {
      "x": -5,
      "y": 3,
      "z": 0,
      "name": "Rock_Shale",
      "rotation": 2
    },
    {
      "x": -5,
      "y": 4,
      "z": 0,
      "name": "Rock_Shale",
      "rotation": 2
    },
    {
      "x": -5,
      "y": 5,
      "z": 0,
      "name": "Rock_Shale",
      "rotation": 2
    },
    {
      "x": -5,
      "y": 6,
      "z": 0,
      "name": "Rock_Shale",
      "rotation": 2
    },
    {
      "x": -4,
      "y": 10,
      "z": -19,
      "name": "Rock_Shale",
      "rotation": 2
    },
    {
      "x": -4,
      "y": 11,
      "z": -19,
      "name": "Rock_Shale",
      "rotation": 2
    },
    {
      "x": -4,
      "y": 10,
      "z": -18,
      "name": "Rock_Shale",
      "rotation": 2
    },
    {
      "x": -4,
      "y": 11,
      "z": -18,
      "name": "Rock_Shale",
      "rotation": 2
    },
    {
      "x": -4,
      "y": 12,
      "z": -18,
      "name": "Rock_Shale",
      "rotation": 2
    },
    {
      "x": -4,
      "y": 10,
      "z": -17,
      "name": "Rock_Shale",
      "rotation": 2
    },
    {
      "x": -4,
      "y": 11,
      "z": -17,
      "name": "Rock_Shale",
      "rotation": 2
    },
    {
      "x": -4,
      "y": 12,
      "z": -17,
      "name": "Rock_Shale",
      "rotation": 2
    },
    {
      "x": -4,
      "y": 13,
      "z": -17,
      "name": "Rock_Shale",
      "rotation": 2
    },
    {
      "x": -4,
      "y": 14,
      "z": -17,
      "name": "Rock_Shale",
      "rotation": 2
    },
    {
      "x": -4,
      "y": 15,
      "z": -17,
      "name": "Rock_Shale",
      "rotation": 2
    },
    {
      "x": -4,
      "y": 16,
      "z": -17,
      "name": "Rock_Shale",
      "rotation": 2
    },
    {
      "x": -4,
      "y": 17,
      "z": -17,
      "name": "Rock_Shale",
      "rotation": 2
    },
    {
      "x": -4,
      "y": 5,
      "z": -16,
      "name": "Rock_Shale",
      "rotation": 2
    },
    {
      "x": -4,
      "y": 6,
      "z": -16,
      "name": "Rock_Shale",
      "rotation": 2
    },
    {
      "x": -4,
      "y": 7,
      "z": -16,
      "name": "Rock_Shale",
      "rotation": 2
    },
    {
      "x": -4,
      "y": 8,
      "z": -16,
      "name": "Rock_Shale",
      "rotation": 2
    },
    {
      "x": -4,
      "y": 9,
      "z": -16,
      "name": "Rock_Shale",
      "rotation": 2
    },
    {
      "x": -4,
      "y": 10,
      "z": -16,
      "name": "Rock_Shale",
      "rotation": 2
    },
    {
      "x": -4,
      "y": 11,
      "z": -16,
      "name": "Rock_Shale",
      "rotation": 2
    },
    {
      "x": -4,
      "y": 12,
      "z": -16,
      "name": "Rock_Shale",
      "rotation": 2
    },
    {
      "x": -4,
      "y": 13,
      "z": -16,
      "name": "Rock_Shale",
      "rotation": 2
    },
    {
      "x": -4,
      "y": 14,
      "z": -16,
      "name": "Rock_Shale",
      "rotation": 2
    },
    {
      "x": -4,
      "y": 15,
      "z": -16,
      "name": "Rock_Shale",
      "rotation": 2
    },
    {
      "x": -4,
      "y": 18,
      "z": -16,
      "name": "Rock_Shale",
      "rotation": 2
    },
    {
      "x": -4,
      "y": 19,
      "z": -16,
      "name": "Rock_Shale",
      "rotation": 2
    },
    {
      "x": -4,
      "y": 21,
      "z": -16,
      "name": "Rock_Shale",
      "rotation": 2
    },
    {
      "x": -4,
      "y": 22,
      "z": -16,
      "name": "Rock_Shale",
      "rotation": 2
    },
    {
      "x": -4,
      "y": 5,
      "z": -15,
      "name": "Rock_Shale",
      "rotation": 2
    },
    {
      "x": -4,
      "y": 6,
      "z": -15,
      "name": "Rock_Shale",
      "rotation": 2
    },
    {
      "x": -4,
      "y": 7,
      "z": -15,
      "name": "Rock_Shale",
      "rotation": 2
    },
    {
      "x": -4,
      "y": 8,
      "z": -15,
      "name": "Rock_Shale",
      "rotation": 2
    },
    {
      "x": -4,
      "y": 9,
      "z": -15,
      "name": "Rock_Shale",
      "rotation": 2
    },
    {
      "x": -4,
      "y": 10,
      "z": -15,
      "name": "Rock_Shale",
      "rotation": 2
    },
    {
      "x": -4,
      "y": 11,
      "z": -15,
      "name": "Rock_Shale",
      "rotation": 2
    },
    {
      "x": -4,
      "y": 12,
      "z": -15,
      "name": "Rock_Shale",
      "rotation": 2
    },
    {
      "x": -4,
      "y": 13,
      "z": -15,
      "name": "Rock_Shale",
      "rotation": 2
    },
    {
      "x": -4,
      "y": 14,
      "z": -15,
      "name": "Rock_Shale",
      "rotation": 2
    },
    {
      "x": -4,
      "y": 15,
      "z": -15,
      "name": "Rock_Shale",
      "rotation": 2
    },
    {
      "x": -4,
      "y": 16,
      "z": -15,
      "name": "Rock_Shale",
      "rotation": 2
    },
    {
      "x": -4,
      "y": 17,
      "z": -15,
      "name": "Rock_Shale",
      "rotation": 2
    },
    {
      "x": -4,
      "y": 18,
      "z": -15,
      "name": "Rock_Shale",
      "rotation": 2
    },
    {
      "x": -4,
      "y": 19,
      "z": -15,
      "name": "Rock_Shale",
      "rotation": 2
    },
    {
      "x": -4,
      "y": 20,
      "z": -15,
      "name": "Rock_Shale",
      "rotation": 2
    },
    {
      "x": -4,
      "y": 21,
      "z": -15,
      "name": "Rock_Shale",
      "rotation": 2
    },
    {
      "x": -4,
      "y": 22,
      "z": -15,
      "name": "Rock_Shale",
      "rotation": 2
    },
    {
      "x": -4,
      "y": 5,
      "z": -14,
      "name": "Rock_Shale",
      "rotation": 2
    },
    {
      "x": -4,
      "y": 6,
      "z": -14,
      "name": "Rock_Shale",
      "rotation": 2
    },
    {
      "x": -4,
      "y": 7,
      "z": -14,
      "name": "Rock_Shale",
      "rotation": 2
    },
    {
      "x": -4,
      "y": 8,
      "z": -14,
      "name": "Rock_Shale",
      "rotation": 2
    },
    {
      "x": -4,
      "y": 9,
      "z": -14,
      "name": "Rock_Shale",
      "rotation": 2
    },
    {
      "x": -4,
      "y": 10,
      "z": -14,
      "name": "Rock_Shale",
      "rotation": 2
    },
    {
      "x": -4,
      "y": 11,
      "z": -14,
      "name": "Rock_Shale",
      "rotation": 2
    },
    {
      "x": -4,
      "y": 12,
      "z": -14,
      "name": "Rock_Shale",
      "rotation": 2
    },
    {
      "x": -4,
      "y": 13,
      "z": -14,
      "name": "Rock_Shale",
      "rotation": 2
    },
    {
      "x": -4,
      "y": 14,
      "z": -14,
      "name": "Rock_Shale",
      "rotation": 2
    },
    {
      "x": -4,
      "y": 15,
      "z": -14,
      "name": "Rock_Shale",
      "rotation": 2
    },
    {
      "x": -4,
      "y": 16,
      "z": -14,
      "name": "Rock_Shale",
      "rotation": 2
    },
    {
      "x": -4,
      "y": 17,
      "z": -14,
      "name": "Rock_Shale_Brick",
      "rotation": 2
    },
    {
      "x": -4,
      "y": 18,
      "z": -14,
      "name": "Rock_Shale",
      "rotation": 2
    },
    {
      "x": -4,
      "y": 19,
      "z": -14,
      "name": "Rock_Shale",
      "rotation": 2
    },
    {
      "x": -4,
      "y": 20,
      "z": -14,
      "name": "Rock_Shale",
      "rotation": 2
    },
    {
      "x": -4,
      "y": 21,
      "z": -14,
      "name": "Rock_Shale",
      "rotation": 2
    },
    {
      "x": -4,
      "y": 22,
      "z": -14,
      "name": "Rock_Shale",
      "rotation": 2
    },
    {
      "x": -4,
      "y": 5,
      "z": -13,
      "name": "Rock_Shale_Brick",
      "rotation": 2
    },
    {
      "x": -4,
      "y": 6,
      "z": -13,
      "name": "Rock_Shale_Brick",
      "rotation": 2
    },
    {
      "x": -4,
      "y": 7,
      "z": -13,
      "name": "Rock_Shale_Brick",
      "rotation": 2
    },
    {
      "x": -4,
      "y": 8,
      "z": -13,
      "name": "Rock_Shale_Brick",
      "rotation": 2
    },
    {
      "x": -4,
      "y": 9,
      "z": -13,
      "name": "Rock_Shale_Brick",
      "rotation": 2
    },
    {
      "x": -4,
      "y": 10,
      "z": -13,
      "name": "Rock_Shale_Brick",
      "rotation": 2
    },
    {
      "x": -4,
      "y": 11,
      "z": -13,
      "name": "Rock_Shale_Brick",
      "rotation": 2
    },
    {
      "x": -4,
      "y": 16,
      "z": -13,
      "name": "Rock_Shale_Brick",
      "rotation": 2
    },
    {
      "x": -4,
      "y": 17,
      "z": -13,
      "name": "Rock_Shale",
      "rotation": 2
    },
    {
      "x": -4,
      "y": 18,
      "z": -13,
      "name": "Rock_Shale",
      "rotation": 2
    },
    {
      "x": -4,
      "y": 19,
      "z": -13,
      "name": "Rock_Shale",
      "rotation": 2
    },
    {
      "x": -4,
      "y": 20,
      "z": -13,
      "name": "Rock_Shale",
      "rotation": 2
    },
    {
      "x": -4,
      "y": 21,
      "z": -13,
      "name": "Rock_Shale",
      "rotation": 2
    },
    {
      "x": -4,
      "y": 22,
      "z": -13,
      "name": "Rock_Shale",
      "rotation": 2
    },
    {
      "x": -4,
      "y": 5,
      "z": -12,
      "name": "Rock_Shale_Brick",
      "rotation": 2
    },
    {
      "x": -4,
      "y": 6,
      "z": -12,
      "name": "Rock_Shale_Brick",
      "rotation": 2
    },
    {
      "x": -4,
      "y": 7,
      "z": -12,
      "name": "Rock_Shale_Brick",
      "rotation": 2
    },
    {
      "x": -4,
      "y": 8,
      "z": -12,
      "name": "Rock_Shale_Brick",
      "rotation": 2
    },
    {
      "x": -4,
      "y": 9,
      "z": -12,
      "name": "Rock_Shale_Brick",
      "rotation": 2
    },
    {
      "x": -4,
      "y": 10,
      "z": -12,
      "name": "Rock_Shale_Brick",
      "rotation": 2
    },
    {
      "x": -4,
      "y": 15,
      "z": -12,
      "name": "Rock_Shale_Brick_Stairs",
      "rotation": 8
    },
    {
      "x": -4,
      "y": 16,
      "z": -12,
      "name": "Rock_Shale_Brick",
      "rotation": 2
    },
    {
      "x": -4,
      "y": 17,
      "z": -12,
      "name": "Rock_Shale",
      "rotation": 2
    },
    {
      "x": -4,
      "y": 18,
      "z": -12,
      "name": "Rock_Shale",
      "rotation": 2
    },
    {
      "x": -4,
      "y": 19,
      "z": -12,
      "name": "Rock_Shale",
      "rotation": 2
    },
    {
      "x": -4,
      "y": 20,
      "z": -12,
      "name": "Rock_Shale",
      "rotation": 2
    },
    {
      "x": -4,
      "y": 21,
      "z": -12,
      "name": "Rock_Shale",
      "rotation": 2
    },
    {
      "x": -4,
      "y": 22,
      "z": -12,
      "name": "Rock_Shale",
      "rotation": 2
    },
    {
      "x": -4,
      "y": 5,
      "z": -11,
      "name": "Rock_Shale_Brick",
      "rotation": 2
    },
    {
      "x": -4,
      "y": 6,
      "z": -11,
      "name": "Rock_Shale_Brick",
      "rotation": 2
    },
    {
      "x": -4,
      "y": 7,
      "z": -11,
      "name": "Rock_Shale_Brick",
      "rotation": 2
    },
    {
      "x": -4,
      "y": 8,
      "z": -11,
      "name": "Rock_Shale_Brick",
      "rotation": 2
    },
    {
      "x": -4,
      "y": 9,
      "z": -11,
      "name": "Rock_Shale_Brick",
      "rotation": 2
    },
    {
      "x": -4,
      "y": 14,
      "z": -11,
      "name": "Rock_Shale_Brick_Stairs",
      "rotation": 8
    },
    {
      "x": -4,
      "y": 15,
      "z": -11,
      "name": "Rock_Shale_Brick",
      "rotation": 2
    },
    {
      "x": -4,
      "y": 16,
      "z": -11,
      "name": "Rock_Shale",
      "rotation": 2
    },
    {
      "x": -4,
      "y": 17,
      "z": -11,
      "name": "Rock_Shale_Brick",
      "rotation": 2
    },
    {
      "x": -4,
      "y": 18,
      "z": -11,
      "name": "Rock_Shale",
      "rotation": 2
    },
    {
      "x": -4,
      "y": 19,
      "z": -11,
      "name": "Rock_Shale",
      "rotation": 2
    },
    {
      "x": -4,
      "y": 20,
      "z": -11,
      "name": "Rock_Shale",
      "rotation": 2
    },
    {
      "x": -4,
      "y": 21,
      "z": -11,
      "name": "Rock_Shale",
      "rotation": 2
    },
    {
      "x": -4,
      "y": 22,
      "z": -11,
      "name": "Rock_Shale",
      "rotation": 2
    },
    {
      "x": -4,
      "y": 23,
      "z": -11,
      "name": "Rock_Shale_Brick_Stairs",
      "rotation": 3
    },
    {
      "x": -4,
      "y": 5,
      "z": -10,
      "name": "Rock_Shale_Brick",
      "rotation": 2
    },
    {
      "x": -4,
      "y": 6,
      "z": -10,
      "name": "Rock_Shale_Brick",
      "rotation": 2
    },
    {
      "x": -4,
      "y": 7,
      "z": -10,
      "name": "Rock_Shale_Brick",
      "rotation": 2
    },
    {
      "x": -4,
      "y": 8,
      "z": -10,
      "name": "Rock_Shale_Brick_Pillar_Base",
      "rotation": 2
    },
    {
      "x": -4,
      "y": 9,
      "z": -10,
      "name": "Rock_Shale_Brick_Pillar_Middle",
      "rotation": 2
    },
    {
      "x": -4,
      "y": 10,
      "z": -10,
      "name": "Rock_Shale_Brick_Pillar_Middle",
      "rotation": 2
    },
    {
      "x": -4,
      "y": 11,
      "z": -10,
      "name": "Rock_Shale_Brick_Pillar_Base",
      "rotation": 10
    },
    {
      "x": -4,
      "y": 12,
      "z": -10,
      "name": "Rock_Shale_Brick",
      "rotation": 2
    },
    {
      "x": -4,
      "y": 13,
      "z": -10,
      "name": "Rock_Shale_Brick",
      "rotation": 2
    },
    {
      "x": -4,
      "y": 14,
      "z": -10,
      "name": "Rock_Shale_Brick",
      "rotation": 2
    },
    {
      "x": -4,
      "y": 15,
      "z": -10,
      "name": "Rock_Shale",
      "rotation": 2
    },
    {
      "x": -4,
      "y": 16,
      "z": -10,
      "name": "Rock_Shale_Brick",
      "rotation": 2
    },
    {
      "x": -4,
      "y": 17,
      "z": -10,
      "name": "Rock_Shale_Brick",
      "rotation": 2
    },
    {
      "x": -4,
      "y": 18,
      "z": -10,
      "name": "Rock_Shale",
      "rotation": 2
    },
    {
      "x": -4,
      "y": 19,
      "z": -10,
      "name": "Rock_Shale",
      "rotation": 2
    },
    {
      "x": -4,
      "y": 20,
      "z": -10,
      "name": "Rock_Shale",
      "rotation": 2
    },
    {
      "x": -4,
      "y": 21,
      "z": -10,
      "name": "Rock_Shale",
      "rotation": 2
    },
    {
      "x": -4,
      "y": 22,
      "z": -10,
      "name": "Rock_Shale",
      "rotation": 2
    },
    {
      "x": -4,
      "y": 5,
      "z": -9,
      "name": "Rock_Shale_Brick",
      "rotation": 2
    },
    {
      "x": -4,
      "y": 6,
      "z": -9,
      "name": "Rock_Basalt",
      "rotation": 2
    },
    {
      "x": -4,
      "y": 7,
      "z": -9,
      "name": "Rock_Basalt",
      "rotation": 2
    },
    {
      "x": -4,
      "y": 8,
      "z": -9,
      "name": "Rock_Basalt",
      "rotation": 2
    },
    {
      "x": -4,
      "y": 12,
      "z": -9,
      "name": "Rock_Shale_Brick_Stairs",
      "rotation": 8
    },
    {
      "x": -4,
      "y": 13,
      "z": -9,
      "name": "Rock_Shale_Brick",
      "rotation": 2
    },
    {
      "x": -4,
      "y": 14,
      "z": -9,
      "name": "Rock_Shale",
      "rotation": 2
    },
    {
      "x": -4,
      "y": 15,
      "z": -9,
      "name": "Rock_Shale_Brick",
      "rotation": 2
    },
    {
      "x": -4,
      "y": 16,
      "z": -9,
      "name": "Rock_Shale_Brick",
      "rotation": 2
    },
    {
      "x": -4,
      "y": 17,
      "z": -9,
      "name": "Rock_Shale_Brick",
      "rotation": 2
    },
    {
      "x": -4,
      "y": 18,
      "z": -9,
      "name": "Rock_Shale",
      "rotation": 2
    },
    {
      "x": -4,
      "y": 19,
      "z": -9,
      "name": "Rock_Shale",
      "rotation": 2
    },
    {
      "x": -4,
      "y": 20,
      "z": -9,
      "name": "Rock_Shale",
      "rotation": 2
    },
    {
      "x": -4,
      "y": 21,
      "z": -9,
      "name": "Rock_Shale",
      "rotation": 2
    },
    {
      "x": -4,
      "y": 22,
      "z": -9,
      "name": "Rock_Shale",
      "rotation": 2
    },
    {
      "x": -4,
      "y": 5,
      "z": -8,
      "name": "Rock_Basalt",
      "rotation": 2
    },
    {
      "x": -4,
      "y": 6,
      "z": -8,
      "name": "Rock_Basalt",
      "rotation": 2
    },
    {
      "x": -4,
      "y": 7,
      "z": -8,
      "name": "Rubble_Basalt_Medium",
      "rotation": 2
    },
    {
      "x": -4,
      "y": 11,
      "z": -8,
      "name": "Rock_Shale_Brick_Stairs",
      "rotation": 8
    },
    {
      "x": -4,
      "y": 12,
      "z": -8,
      "name": "Rock_Shale_Brick",
      "rotation": 2
    },
    {
      "x": -4,
      "y": 13,
      "z": -8,
      "name": "Rock_Shale",
      "rotation": 2
    },
    {
      "x": -4,
      "y": 14,
      "z": -8,
      "name": "Rock_Shale_Brick",
      "rotation": 2
    },
    {
      "x": -4,
      "y": 15,
      "z": -8,
      "name": "Rock_Shale_Brick",
      "rotation": 2
    },
    {
      "x": -4,
      "y": 16,
      "z": -8,
      "name": "Rock_Shale_Brick",
      "rotation": 2
    },
    {
      "x": -4,
      "y": 17,
      "z": -8,
      "name": "Rock_Shale_Brick",
      "rotation": 2
    },
    {
      "x": -4,
      "y": 18,
      "z": -8,
      "name": "Rock_Shale",
      "rotation": 2
    },
    {
      "x": -4,
      "y": 19,
      "z": -8,
      "name": "Rock_Shale",
      "rotation": 2
    },
    {
      "x": -4,
      "y": 20,
      "z": -8,
      "name": "Rock_Shale",
      "rotation": 2
    },
    {
      "x": -4,
      "y": 21,
      "z": -8,
      "name": "Rock_Shale",
      "rotation": 2
    },
    {
      "x": -4,
      "y": 22,
      "z": -8,
      "name": "Rock_Shale",
      "rotation": 2
    },
    {
      "x": -4,
      "y": 4,
      "z": -7,
      "name": "Rock_Shale_Brick",
      "rotation": 2
    },
    {
      "x": -4,
      "y": 5,
      "z": -7,
      "name": "Rock_Shale_Brick",
      "rotation": 2
    },
    {
      "x": -4,
      "y": 10,
      "z": -7,
      "name": "Rock_Shale_Brick_Stairs",
      "rotation": 8
    },
    {
      "x": -4,
      "y": 11,
      "z": -7,
      "name": "Rock_Shale_Brick",
      "rotation": 2
    },
    {
      "x": -4,
      "y": 12,
      "z": -7,
      "name": "Rock_Shale",
      "rotation": 2
    },
    {
      "x": -4,
      "y": 13,
      "z": -7,
      "name": "Rock_Shale_Brick",
      "rotation": 2
    },
    {
      "x": -4,
      "y": 14,
      "z": -7,
      "name": "Rock_Shale_Brick",
      "rotation": 2
    },
    {
      "x": -4,
      "y": 15,
      "z": -7,
      "name": "Rock_Shale_Brick",
      "rotation": 2
    },
    {
      "x": -4,
      "y": 16,
      "z": -7,
      "name": "Rock_Shale_Brick",
      "rotation": 2
    },
    {
      "x": -4,
      "y": 17,
      "z": -7,
      "name": "Rock_Shale_Brick",
      "rotation": 2
    },
    {
      "x": -4,
      "y": 18,
      "z": -7,
      "name": "Rock_Shale",
      "rotation": 2
    },
    {
      "x": -4,
      "y": 19,
      "z": -7,
      "name": "Rock_Shale",
      "rotation": 2
    },
    {
      "x": -4,
      "y": 20,
      "z": -7,
      "name": "Rock_Shale",
      "rotation": 2
    },
    {
      "x": -4,
      "y": 21,
      "z": -7,
      "name": "Rock_Shale",
      "rotation": 2
    },
    {
      "x": -4,
      "y": 22,
      "z": -7,
      "name": "Rock_Shale",
      "rotation": 2
    },
    {
      "x": -4,
      "y": 3,
      "z": -6,
      "name": "Rock_Shale_Brick",
      "rotation": 2
    },
    {
      "x": -4,
      "y": 4,
      "z": -6,
      "name": "Rock_Shale_Brick_Pillar_Base",
      "rotation": 2
    },
    {
      "x": -4,
      "y": 5,
      "z": -6,
      "name": "Rock_Shale_Brick_Pillar_Middle",
      "rotation": 2
    },
    {
      "x": -4,
      "y": 6,
      "z": -6,
      "name": "Rock_Shale_Brick_Pillar_Middle",
      "rotation": 2
    },
    {
      "x": -4,
      "y": 7,
      "z": -6,
      "name": "Rock_Shale_Brick_Pillar_Base",
      "rotation": 10
    },
    {
      "x": -4,
      "y": 8,
      "z": -6,
      "name": "Rock_Shale_Brick",
      "rotation": 2
    },
    {
      "x": -4,
      "y": 9,
      "z": -6,
      "name": "Rock_Shale_Brick",
      "rotation": 2
    },
    {
      "x": -4,
      "y": 10,
      "z": -6,
      "name": "Rock_Shale_Brick",
      "rotation": 2
    },
    {
      "x": -4,
      "y": 11,
      "z": -6,
      "name": "Rock_Shale",
      "rotation": 2
    },
    {
      "x": -4,
      "y": 12,
      "z": -6,
      "name": "Rock_Shale_Brick",
      "rotation": 2
    },
    {
      "x": -4,
      "y": 13,
      "z": -6,
      "name": "Rock_Shale_Brick",
      "rotation": 2
    },
    {
      "x": -4,
      "y": 14,
      "z": -6,
      "name": "Rock_Shale_Brick",
      "rotation": 2
    },
    {
      "x": -4,
      "y": 15,
      "z": -6,
      "name": "Rock_Shale_Brick",
      "rotation": 2
    },
    {
      "x": -4,
      "y": 16,
      "z": -6,
      "name": "Rock_Shale_Brick",
      "rotation": 2
    },
    {
      "x": -4,
      "y": 17,
      "z": -6,
      "name": "Rock_Shale_Brick",
      "rotation": 2
    },
    {
      "x": -4,
      "y": 18,
      "z": -6,
      "name": "Rock_Shale",
      "rotation": 2
    },
    {
      "x": -4,
      "y": 19,
      "z": -6,
      "name": "Rock_Shale",
      "rotation": 2
    },
    {
      "x": -4,
      "y": 20,
      "z": -6,
      "name": "Rock_Shale",
      "rotation": 2
    },
    {
      "x": -4,
      "y": 21,
      "z": -6,
      "name": "Rock_Shale",
      "rotation": 2
    },
    {
      "x": -4,
      "y": 22,
      "z": -6,
      "name": "Rock_Shale",
      "rotation": 2
    },
    {
      "x": -4,
      "y": 23,
      "z": -6,
      "name": "Rock_Shale_Brick",
      "rotation": 2
    },
    {
      "x": -4,
      "y": 2,
      "z": -5,
      "name": "Rock_Shale_Brick",
      "rotation": 2
    },
    {
      "x": -4,
      "y": 3,
      "z": -5,
      "name": "Rock_Shale_Brick",
      "rotation": 2
    },
    {
      "x": -4,
      "y": 8,
      "z": -5,
      "name": "Rock_Shale_Brick_Stairs",
      "rotation": 8
    },
    {
      "x": -4,
      "y": 9,
      "z": -5,
      "name": "Rock_Shale_Brick",
      "rotation": 2
    },
    {
      "x": -4,
      "y": 10,
      "z": -5,
      "name": "Rock_Shale",
      "rotation": 2
    },
    {
      "x": -4,
      "y": 11,
      "z": -5,
      "name": "Rock_Shale_Brick",
      "rotation": 2
    },
    {
      "x": -4,
      "y": 12,
      "z": -5,
      "name": "Rock_Shale_Brick",
      "rotation": 2
    },
    {
      "x": -4,
      "y": 13,
      "z": -5,
      "name": "Rock_Shale_Brick",
      "rotation": 2
    },
    {
      "x": -4,
      "y": 14,
      "z": -5,
      "name": "Rock_Shale_Brick",
      "rotation": 2
    },
    {
      "x": -4,
      "y": 15,
      "z": -5,
      "name": "Rock_Shale_Brick",
      "rotation": 2
    },
    {
      "x": -4,
      "y": 16,
      "z": -5,
      "name": "Rock_Shale_Brick",
      "rotation": 2
    },
    {
      "x": -4,
      "y": 17,
      "z": -5,
      "name": "Rock_Shale_Brick",
      "rotation": 2
    },
    {
      "x": -4,
      "y": 18,
      "z": -5,
      "name": "Rock_Shale",
      "rotation": 2
    },
    {
      "x": -4,
      "y": 19,
      "z": -5,
      "name": "Rock_Shale",
      "rotation": 2
    },
    {
      "x": -4,
      "y": 20,
      "z": -5,
      "name": "Rock_Shale",
      "rotation": 2
    },
    {
      "x": -4,
      "y": 21,
      "z": -5,
      "name": "Rock_Shale",
      "rotation": 2
    },
    {
      "x": -4,
      "y": 22,
      "z": -5,
      "name": "Rock_Shale",
      "rotation": 2
    },
    {
      "x": -4,
      "y": 1,
      "z": -4,
      "name": "Rock_Shale_Brick",
      "rotation": 2
    },
    {
      "x": -4,
      "y": 2,
      "z": -4,
      "name": "Rock_Shale_Brick",
      "rotation": 2
    },
    {
      "x": -4,
      "y": 7,
      "z": -4,
      "name": "Rock_Shale_Brick_Stairs",
      "rotation": 8
    },
    {
      "x": -4,
      "y": 8,
      "z": -4,
      "name": "Rock_Shale_Brick",
      "rotation": 2
    },
    {
      "x": -4,
      "y": 9,
      "z": -4,
      "name": "Rock_Shale",
      "rotation": 2
    },
    {
      "x": -4,
      "y": 10,
      "z": -4,
      "name": "Rock_Shale_Brick",
      "rotation": 2
    },
    {
      "x": -4,
      "y": 18,
      "z": -4,
      "name": "Rock_Shale",
      "rotation": 2
    },
    {
      "x": -4,
      "y": 19,
      "z": -4,
      "name": "Rock_Shale",
      "rotation": 2
    },
    {
      "x": -4,
      "y": 20,
      "z": -4,
      "name": "Rock_Shale",
      "rotation": 2
    },
    {
      "x": -4,
      "y": 21,
      "z": -4,
      "name": "Rock_Shale",
      "rotation": 2
    },
    {
      "x": -4,
      "y": 22,
      "z": -4,
      "name": "Rock_Shale",
      "rotation": 2
    },
    {
      "x": -4,
      "y": 0,
      "z": -3,
      "name": "Rock_Shale_Brick_Smooth",
      "rotation": 2
    },
    {
      "x": -4,
      "y": 1,
      "z": -3,
      "name": "Rock_Shale_Brick",
      "rotation": 2
    },
    {
      "x": -4,
      "y": 6,
      "z": -3,
      "name": "Rock_Shale_Brick_Stairs",
      "rotation": 8
    },
    {
      "x": -4,
      "y": 7,
      "z": -3,
      "name": "Rock_Shale_Brick",
      "rotation": 2
    },
    {
      "x": -4,
      "y": 8,
      "z": -3,
      "name": "Rock_Shale",
      "rotation": 2
    },
    {
      "x": -4,
      "y": 18,
      "z": -3,
      "name": "Rock_Shale",
      "rotation": 2
    },
    {
      "x": -4,
      "y": 19,
      "z": -3,
      "name": "Rock_Shale",
      "rotation": 2
    },
    {
      "x": -4,
      "y": 20,
      "z": -3,
      "name": "Rock_Shale",
      "rotation": 2
    },
    {
      "x": -4,
      "y": 0,
      "z": -2,
      "name": "Rock_Shale_Brick_Smooth",
      "rotation": 2
    },
    {
      "x": -4,
      "y": 1,
      "z": -2,
      "name": "Rock_Basalt",
      "rotation": 2
    },
    {
      "x": -4,
      "y": 2,
      "z": -2,
      "name": "Rock_Basalt",
      "rotation": 2
    },
    {
      "x": -4,
      "y": 3,
      "z": -2,
      "name": "Rock_Shale_Brick_Pillar_Base",
      "rotation": 10
    },
    {
      "x": -4,
      "y": 4,
      "z": -2,
      "name": "Rock_Shale_Brick",
      "rotation": 2
    },
    {
      "x": -4,
      "y": 5,
      "z": -2,
      "name": "Rock_Shale_Brick",
      "rotation": 2
    },
    {
      "x": -4,
      "y": 6,
      "z": -2,
      "name": "Rock_Shale_Brick",
      "rotation": 2
    },
    {
      "x": -4,
      "y": 7,
      "z": -2,
      "name": "Rock_Shale",
      "rotation": 2
    },
    {
      "x": -4,
      "y": 0,
      "z": -1,
      "name": "Rock_Shale_Brick_Smooth",
      "rotation": 2
    },
    {
      "x": -4,
      "y": 1,
      "z": -1,
      "name": "Rock_Basalt",
      "rotation": 2
    },
    {
      "x": -4,
      "y": 2,
      "z": -1,
      "name": "Rock_Basalt",
      "rotation": 2
    },
    {
      "x": -4,
      "y": 3,
      "z": -1,
      "name": "Rubble_Basalt",
      "rotation": 2
    },
    {
      "x": -4,
      "y": 4,
      "z": -1,
      "name": "Rock_Shale_Brick_Stairs",
      "rotation": 10
    },
    {
      "x": -4,
      "y": 5,
      "z": -1,
      "name": "Rock_Shale_Brick",
      "rotation": 2
    },
    {
      "x": -4,
      "y": 6,
      "z": -1,
      "name": "Rock_Shale",
      "rotation": 2
    },
    {
      "x": -4,
      "y": 0,
      "z": 0,
      "name": "Rock_Shale_Brick_Smooth",
      "rotation": 2
    },
    {
      "x": -4,
      "y": 5,
      "z": 0,
      "name": "Rock_Shale_Brick",
      "rotation": 2
    },
    {
      "x": -4,
      "y": 6,
      "z": 0,
      "name": "Rock_Shale",
      "rotation": 2
    },
    {
      "x": -3,
      "y": 10,
      "z": -19,
      "name": "Rock_Shale",
      "rotation": 2
    },
    {
      "x": -3,
      "y": 11,
      "z": -19,
      "name": "Rock_Shale",
      "rotation": 2
    },
    {
      "x": -3,
      "y": 12,
      "z": -19,
      "name": "Rock_Shale",
      "rotation": 2
    },
    {
      "x": -3,
      "y": 10,
      "z": -18,
      "name": "Rock_Shale",
      "rotation": 2
    },
    {
      "x": -3,
      "y": 11,
      "z": -18,
      "name": "Rock_Shale",
      "rotation": 2
    },
    {
      "x": -3,
      "y": 12,
      "z": -18,
      "name": "Rock_Shale",
      "rotation": 2
    },
    {
      "x": -3,
      "y": 13,
      "z": -18,
      "name": "Rock_Shale",
      "rotation": 2
    },
    {
      "x": -3,
      "y": 14,
      "z": -18,
      "name": "Rock_Shale",
      "rotation": 2
    },
    {
      "x": -3,
      "y": 15,
      "z": -18,
      "name": "Rock_Shale",
      "rotation": 2
    },
    {
      "x": -3,
      "y": 10,
      "z": -17,
      "name": "Rock_Shale",
      "rotation": 2
    },
    {
      "x": -3,
      "y": 16,
      "z": -17,
      "name": "Rock_Shale",
      "rotation": 2
    },
    {
      "x": -3,
      "y": 17,
      "z": -17,
      "name": "Rock_Shale",
      "rotation": 2
    },
    {
      "x": -3,
      "y": 5,
      "z": -16,
      "name": "Rock_Shale",
      "rotation": 2
    },
    {
      "x": -3,
      "y": 6,
      "z": -16,
      "name": "Rock_Shale",
      "rotation": 2
    },
    {
      "x": -3,
      "y": 7,
      "z": -16,
      "name": "Rock_Shale",
      "rotation": 2
    },
    {
      "x": -3,
      "y": 8,
      "z": -16,
      "name": "Rock_Shale",
      "rotation": 2
    },
    {
      "x": -3,
      "y": 9,
      "z": -16,
      "name": "Rock_Shale",
      "rotation": 2
    },
    {
      "x": -3,
      "y": 10,
      "z": -16,
      "name": "Rock_Shale",
      "rotation": 2
    },
    {
      "x": -3,
      "y": 11,
      "z": -16,
      "name": "Rock_Shale",
      "rotation": 2
    },
    {
      "x": -3,
      "y": 12,
      "z": -16,
      "name": "Rock_Shale",
      "rotation": 2
    },
    {
      "x": -3,
      "y": 13,
      "z": -16,
      "name": "Rock_Shale",
      "rotation": 2
    },
    {
      "x": -3,
      "y": 14,
      "z": -16,
      "name": "Rock_Shale",
      "rotation": 2
    },
    {
      "x": -3,
      "y": 15,
      "z": -16,
      "name": "Rock_Shale",
      "rotation": 2
    },
    {
      "x": -3,
      "y": 16,
      "z": -16,
      "name": "Rock_Shale",
      "rotation": 2
    },
    {
      "x": -3,
      "y": 18,
      "z": -16,
      "name": "Rock_Shale",
      "rotation": 2
    },
    {
      "x": -3,
      "y": 19,
      "z": -16,
      "name": "Rock_Shale",
      "rotation": 2
    },
    {
      "x": -3,
      "y": 23,
      "z": -16,
      "name": "Rock_Shale",
      "rotation": 2
    },
    {
      "x": -3,
      "y": 24,
      "z": -16,
      "name": "Rock_Shale",
      "rotation": 2
    },
    {
      "x": -3,
      "y": 5,
      "z": -15,
      "name": "Rock_Shale",
      "rotation": 2
    },
    {
      "x": -3,
      "y": 6,
      "z": -15,
      "name": "Rock_Shale",
      "rotation": 2
    },
    {
      "x": -3,
      "y": 7,
      "z": -15,
      "name": "Rock_Shale",
      "rotation": 2
    },
    {
      "x": -3,
      "y": 8,
      "z": -15,
      "name": "Rock_Shale",
      "rotation": 2
    },
    {
      "x": -3,
      "y": 9,
      "z": -15,
      "name": "Rock_Shale",
      "rotation": 2
    },
    {
      "x": -3,
      "y": 10,
      "z": -15,
      "name": "Rock_Shale",
      "rotation": 2
    },
    {
      "x": -3,
      "y": 11,
      "z": -15,
      "name": "Rock_Shale",
      "rotation": 2
    },
    {
      "x": -3,
      "y": 12,
      "z": -15,
      "name": "Rock_Shale",
      "rotation": 2
    },
    {
      "x": -3,
      "y": 13,
      "z": -15,
      "name": "Rock_Shale",
      "rotation": 2
    },
    {
      "x": -3,
      "y": 14,
      "z": -15,
      "name": "Rock_Shale",
      "rotation": 2
    },
    {
      "x": -3,
      "y": 15,
      "z": -15,
      "name": "Rock_Shale",
      "rotation": 2
    },
    {
      "x": -3,
      "y": 16,
      "z": -15,
      "name": "Rock_Shale",
      "rotation": 2
    },
    {
      "x": -3,
      "y": 17,
      "z": -15,
      "name": "Rock_Shale",
      "rotation": 2
    },
    {
      "x": -3,
      "y": 18,
      "z": -15,
      "name": "Rock_Shale",
      "rotation": 2
    },
    {
      "x": -3,
      "y": 19,
      "z": -15,
      "name": "Rock_Shale",
      "rotation": 2
    },
    {
      "x": -3,
      "y": 20,
      "z": -15,
      "name": "Rock_Shale",
      "rotation": 2
    },
    {
      "x": -3,
      "y": 21,
      "z": -15,
      "name": "Rock_Shale",
      "rotation": 2
    },
    {
      "x": -3,
      "y": 22,
      "z": -15,
      "name": "Rock_Shale",
      "rotation": 2
    },
    {
      "x": -3,
      "y": 23,
      "z": -15,
      "name": "Rock_Shale",
      "rotation": 2
    },
    {
      "x": -3,
      "y": 24,
      "z": -15,
      "name": "Rock_Shale",
      "rotation": 2
    },
    {
      "x": -3,
      "y": 5,
      "z": -14,
      "name": "Rock_Shale",
      "rotation": 2
    },
    {
      "x": -3,
      "y": 6,
      "z": -14,
      "name": "Rock_Shale",
      "rotation": 2
    },
    {
      "x": -3,
      "y": 7,
      "z": -14,
      "name": "Rock_Shale",
      "rotation": 2
    },
    {
      "x": -3,
      "y": 8,
      "z": -14,
      "name": "Rock_Shale",
      "rotation": 2
    },
    {
      "x": -3,
      "y": 9,
      "z": -14,
      "name": "Rock_Shale",
      "rotation": 2
    },
    {
      "x": -3,
      "y": 10,
      "z": -14,
      "name": "Rock_Shale",
      "rotation": 2
    },
    {
      "x": -3,
      "y": 11,
      "z": -14,
      "name": "Rock_Shale",
      "rotation": 2
    },
    {
      "x": -3,
      "y": 12,
      "z": -14,
      "name": "Rock_Shale",
      "rotation": 2
    },
    {
      "x": -3,
      "y": 13,
      "z": -14,
      "name": "Rock_Shale",
      "rotation": 2
    },
    {
      "x": -3,
      "y": 14,
      "z": -14,
      "name": "Rock_Shale",
      "rotation": 2
    },
    {
      "x": -3,
      "y": 15,
      "z": -14,
      "name": "Rock_Shale",
      "rotation": 2
    },
    {
      "x": -3,
      "y": 16,
      "z": -14,
      "name": "Rock_Shale",
      "rotation": 2
    },
    {
      "x": -3,
      "y": 17,
      "z": -14,
      "name": "Rock_Shale_Brick",
      "rotation": 2
    },
    {
      "x": -3,
      "y": 18,
      "z": -14,
      "name": "Rock_Shale",
      "rotation": 2
    },
    {
      "x": -3,
      "y": 19,
      "z": -14,
      "name": "Rock_Shale",
      "rotation": 2
    },
    {
      "x": -3,
      "y": 20,
      "z": -14,
      "name": "Rock_Shale",
      "rotation": 2
    },
    {
      "x": -3,
      "y": 21,
      "z": -14,
      "name": "Rock_Shale",
      "rotation": 2
    },
    {
      "x": -3,
      "y": 22,
      "z": -14,
      "name": "Rock_Shale",
      "rotation": 2
    },
    {
      "x": -3,
      "y": 23,
      "z": -14,
      "name": "Rock_Shale",
      "rotation": 2
    },
    {
      "x": -3,
      "y": 5,
      "z": -13,
      "name": "Rock_Shale_Cobble",
      "rotation": 2
    },
    {
      "x": -3,
      "y": 6,
      "z": -13,
      "name": "Rock_Shale_Cobble",
      "rotation": 2
    },
    {
      "x": -3,
      "y": 7,
      "z": -13,
      "name": "Rock_Shale_Cobble",
      "rotation": 2
    },
    {
      "x": -3,
      "y": 8,
      "z": -13,
      "name": "Rock_Shale_Cobble",
      "rotation": 2
    },
    {
      "x": -3,
      "y": 9,
      "z": -13,
      "name": "Rock_Shale_Cobble",
      "rotation": 2
    },
    {
      "x": -3,
      "y": 10,
      "z": -13,
      "name": "Rock_Shale_Brick_Stairs"
    },
    {
      "x": -3,
      "y": 17,
      "z": -13,
      "name": "Rock_Shale",
      "rotation": 2
    },
    {
      "x": -3,
      "y": 18,
      "z": -13,
      "name": "Rock_Shale",
      "rotation": 2
    },
    {
      "x": -3,
      "y": 19,
      "z": -13,
      "name": "Rock_Shale",
      "rotation": 2
    },
    {
      "x": -3,
      "y": 20,
      "z": -13,
      "name": "Rock_Shale",
      "rotation": 2
    },
    {
      "x": -3,
      "y": 21,
      "z": -13,
      "name": "Rock_Shale",
      "rotation": 2
    },
    {
      "x": -3,
      "y": 22,
      "z": -13,
      "name": "Rock_Shale",
      "rotation": 2
    },
    {
      "x": -3,
      "y": 23,
      "z": -13,
      "name": "Rock_Shale",
      "rotation": 2
    },
    {
      "x": -3,
      "y": 5,
      "z": -12,
      "name": "Rock_Shale_Brick",
      "rotation": 2
    },
    {
      "x": -3,
      "y": 6,
      "z": -12,
      "name": "Rock_Shale_Brick",
      "rotation": 2
    },
    {
      "x": -3,
      "y": 7,
      "z": -12,
      "name": "Rock_Shale_Brick",
      "rotation": 2
    },
    {
      "x": -3,
      "y": 8,
      "z": -12,
      "name": "Rock_Shale_Brick",
      "rotation": 2
    },
    {
      "x": -3,
      "y": 9,
      "z": -12,
      "name": "Rock_Shale_Brick_Stairs"
    },
    {
      "x": -3,
      "y": 16,
      "z": -12,
      "name": "Plant_Bush_Dead_Hanging",
      "rotation": 2
    },
    {
      "x": -3,
      "y": 17,
      "z": -12,
      "name": "Rock_Shale",
      "rotation": 2
    },
    {
      "x": -3,
      "y": 18,
      "z": -12,
      "name": "Rock_Shale",
      "rotation": 2
    },
    {
      "x": -3,
      "y": 19,
      "z": -12,
      "name": "Rock_Shale",
      "rotation": 2
    },
    {
      "x": -3,
      "y": 20,
      "z": -12,
      "name": "Rock_Shale",
      "rotation": 2
    },
    {
      "x": -3,
      "y": 21,
      "z": -12,
      "name": "Rock_Shale",
      "rotation": 2
    },
    {
      "x": -3,
      "y": 22,
      "z": -12,
      "name": "Rock_Shale",
      "rotation": 2
    },
    {
      "x": -3,
      "y": 23,
      "z": -12,
      "name": "Rock_Shale",
      "rotation": 2
    },
    {
      "x": -3,
      "y": 5,
      "z": -11,
      "name": "Rock_Shale_Brick",
      "rotation": 2
    },
    {
      "x": -3,
      "y": 6,
      "z": -11,
      "name": "Rock_Shale_Brick",
      "rotation": 2
    },
    {
      "x": -3,
      "y": 7,
      "z": -11,
      "name": "Rock_Shale_Brick",
      "rotation": 2
    },
    {
      "x": -3,
      "y": 8,
      "z": -11,
      "name": "Rock_Shale_Brick_Stairs"
    },
    {
      "x": -3,
      "y": 16,
      "z": -11,
      "name": "Rock_Shale",
      "rotation": 2
    },
    {
      "x": -3,
      "y": 17,
      "z": -11,
      "name": "Rock_Shale_Brick",
      "rotation": 2
    },
    {
      "x": -3,
      "y": 18,
      "z": -11,
      "name": "Rock_Shale",
      "rotation": 2
    },
    {
      "x": -3,
      "y": 19,
      "z": -11,
      "name": "Rock_Shale",
      "rotation": 2
    },
    {
      "x": -3,
      "y": 20,
      "z": -11,
      "name": "Rock_Shale",
      "rotation": 2
    },
    {
      "x": -3,
      "y": 21,
      "z": -11,
      "name": "Rock_Shale",
      "rotation": 2
    },
    {
      "x": -3,
      "y": 22,
      "z": -11,
      "name": "Rock_Shale",
      "rotation": 2
    },
    {
      "x": -3,
      "y": 23,
      "z": -11,
      "name": "Rock_Shale",
      "rotation": 2
    },
    {
      "x": -3,
      "y": 24,
      "z": -11,
      "name": "Rock_Shale_Brick",
      "rotation": 2
    },
    {
      "x": -3,
      "y": 5,
      "z": -10,
      "name": "Rock_Shale_Brick",
      "rotation": 2
    },
    {
      "x": -3,
      "y": 6,
      "z": -10,
      "name": "Rock_Shale_Brick",
      "rotation": 2
    },
    {
      "x": -3,
      "y": 7,
      "z": -10,
      "name": "Rock_Basalt",
      "rotation": 2
    },
    {
      "x": -3,
      "y": 8,
      "z": -10,
      "name": "Rock_Basalt",
      "rotation": 2
    },
    {
      "x": -3,
      "y": 9,
      "z": -10,
      "name": "Rubble_Basalt",
      "rotation": 2
    },
    {
      "x": -3,
      "y": 14,
      "z": -10,
      "name": "Rock_Shale_Brick_Stairs",
      "rotation": 11
    },
    {
      "x": -3,
      "y": 15,
      "z": -10,
      "name": "Rock_Shale",
      "rotation": 2
    },
    {
      "x": -3,
      "y": 16,
      "z": -10,
      "name": "Rock_Shale_Brick",
      "rotation": 2
    },
    {
      "x": -3,
      "y": 17,
      "z": -10,
      "name": "Rock_Shale_Brick",
      "rotation": 2
    },
    {
      "x": -3,
      "y": 18,
      "z": -10,
      "name": "Rock_Shale",
      "rotation": 2
    },
    {
      "x": -3,
      "y": 19,
      "z": -10,
      "name": "Rock_Shale",
      "rotation": 2
    },
    {
      "x": -3,
      "y": 20,
      "z": -10,
      "name": "Rock_Shale",
      "rotation": 2
    },
    {
      "x": -3,
      "y": 21,
      "z": -10,
      "name": "Rock_Shale",
      "rotation": 2
    },
    {
      "x": -3,
      "y": 22,
      "z": -10,
      "name": "Rock_Shale",
      "rotation": 2
    },
    {
      "x": -3,
      "y": 23,
      "z": -10,
      "name": "Rock_Shale",
      "rotation": 2
    },
    {
      "x": -3,
      "y": 5,
      "z": -9,
      "name": "Rock_Shale_Brick",
      "rotation": 2
    },
    {
      "x": -3,
      "y": 6,
      "z": -9,
      "name": "Rock_Basalt",
      "rotation": 2
    },
    {
      "x": -3,
      "y": 7,
      "z": -9,
      "name": "Rock_Basalt",
      "rotation": 2
    },
    {
      "x": -3,
      "y": 14,
      "z": -9,
      "name": "Rock_Shale",
      "rotation": 2
    },
    {
      "x": -3,
      "y": 15,
      "z": -9,
      "name": "Rock_Shale_Brick",
      "rotation": 2
    },
    {
      "x": -3,
      "y": 16,
      "z": -9,
      "name": "Rock_Shale_Brick",
      "rotation": 2
    },
    {
      "x": -3,
      "y": 17,
      "z": -9,
      "name": "Rock_Shale_Brick",
      "rotation": 2
    },
    {
      "x": -3,
      "y": 18,
      "z": -9,
      "name": "Rock_Shale",
      "rotation": 2
    },
    {
      "x": -3,
      "y": 19,
      "z": -9,
      "name": "Rock_Shale",
      "rotation": 2
    },
    {
      "x": -3,
      "y": 20,
      "z": -9,
      "name": "Rock_Shale",
      "rotation": 2
    },
    {
      "x": -3,
      "y": 21,
      "z": -9,
      "name": "Rock_Shale",
      "rotation": 2
    },
    {
      "x": -3,
      "y": 22,
      "z": -9,
      "name": "Rock_Shale",
      "rotation": 2
    },
    {
      "x": -3,
      "y": 23,
      "z": -9,
      "name": "Rock_Shale",
      "rotation": 2
    },
    {
      "x": -3,
      "y": 5,
      "z": -8,
      "name": "Soil_Dirt_Cold",
      "rotation": 2
    },
    {
      "x": -3,
      "y": 6,
      "z": -8,
      "name": "Plant_Bush_Dead_Twisted",
      "rotation": 2
    },
    {
      "x": -3,
      "y": 13,
      "z": -8,
      "name": "Rock_Shale",
      "rotation": 2
    },
    {
      "x": -3,
      "y": 14,
      "z": -8,
      "name": "Rock_Shale_Brick",
      "rotation": 2
    },
    {
      "x": -3,
      "y": 15,
      "z": -8,
      "name": "Rock_Shale_Brick",
      "rotation": 2
    },
    {
      "x": -3,
      "y": 16,
      "z": -8,
      "name": "Rock_Shale_Brick",
      "rotation": 2
    },
    {
      "x": -3,
      "y": 17,
      "z": -8,
      "name": "Rock_Shale_Brick",
      "rotation": 2
    },
    {
      "x": -3,
      "y": 18,
      "z": -8,
      "name": "Rock_Shale",
      "rotation": 2
    },
    {
      "x": -3,
      "y": 19,
      "z": -8,
      "name": "Rock_Shale",
      "rotation": 2
    },
    {
      "x": -3,
      "y": 20,
      "z": -8,
      "name": "Rock_Shale",
      "rotation": 2
    },
    {
      "x": -3,
      "y": 21,
      "z": -8,
      "name": "Rock_Shale",
      "rotation": 2
    },
    {
      "x": -3,
      "y": 22,
      "z": -8,
      "name": "Rock_Shale",
      "rotation": 2
    },
    {
      "x": -3,
      "y": 23,
      "z": -8,
      "name": "Rock_Shale",
      "rotation": 2
    },
    {
      "x": -3,
      "y": 4,
      "z": -7,
      "name": "Soil_Dirt_Cold",
      "rotation": 2
    },
    {
      "x": -3,
      "y": 5,
      "z": -7,
      "name": "*Plant_Crop_Berry_Winter_Block_State_Definitions_StageFinal",
      "rotation": 2
    },
    {
      "x": -3,
      "y": 12,
      "z": -7,
      "name": "Rock_Shale",
      "rotation": 2
    },
    {
      "x": -3,
      "y": 13,
      "z": -7,
      "name": "Rock_Shale_Brick",
      "rotation": 2
    },
    {
      "x": -3,
      "y": 14,
      "z": -7,
      "name": "Rock_Shale_Brick",
      "rotation": 2
    },
    {
      "x": -3,
      "y": 15,
      "z": -7,
      "name": "Rock_Shale_Brick",
      "rotation": 2
    },
    {
      "x": -3,
      "y": 16,
      "z": -7,
      "name": "Rock_Shale_Brick",
      "rotation": 2
    },
    {
      "x": -3,
      "y": 17,
      "z": -7,
      "name": "Rock_Shale_Brick",
      "rotation": 2
    },
    {
      "x": -3,
      "y": 18,
      "z": -7,
      "name": "Rock_Shale",
      "rotation": 2
    },
    {
      "x": -3,
      "y": 19,
      "z": -7,
      "name": "Rock_Shale",
      "rotation": 2
    },
    {
      "x": -3,
      "y": 20,
      "z": -7,
      "name": "Rock_Shale",
      "rotation": 2
    },
    {
      "x": -3,
      "y": 21,
      "z": -7,
      "name": "Rock_Shale",
      "rotation": 2
    },
    {
      "x": -3,
      "y": 22,
      "z": -7,
      "name": "Rock_Shale",
      "rotation": 2
    },
    {
      "x": -3,
      "y": 23,
      "z": -7,
      "name": "Rock_Shale",
      "rotation": 2
    },
    {
      "x": -3,
      "y": 3,
      "z": -6,
      "name": "Rock_Shale_Brick_Stairs"
    },
    {
      "x": -3,
      "y": 10,
      "z": -6,
      "name": "Rock_Shale_Brick_Stairs",
      "rotation": 11
    },
    {
      "x": -3,
      "y": 11,
      "z": -6,
      "name": "Rock_Shale",
      "rotation": 2
    },
    {
      "x": -3,
      "y": 12,
      "z": -6,
      "name": "Rock_Shale_Brick",
      "rotation": 2
    },
    {
      "x": -3,
      "y": 13,
      "z": -6,
      "name": "Rock_Shale_Brick",
      "rotation": 2
    },
    {
      "x": -3,
      "y": 14,
      "z": -6,
      "name": "Rock_Shale_Brick",
      "rotation": 2
    },
    {
      "x": -3,
      "y": 15,
      "z": -6,
      "name": "Rock_Shale_Brick",
      "rotation": 2
    },
    {
      "x": -3,
      "y": 16,
      "z": -6,
      "name": "Rock_Shale_Brick",
      "rotation": 2
    },
    {
      "x": -3,
      "y": 17,
      "z": -6,
      "name": "Rock_Shale_Brick",
      "rotation": 2
    },
    {
      "x": -3,
      "y": 18,
      "z": -6,
      "name": "Rock_Shale",
      "rotation": 2
    },
    {
      "x": -3,
      "y": 19,
      "z": -6,
      "name": "Rock_Shale",
      "rotation": 2
    },
    {
      "x": -3,
      "y": 20,
      "z": -6,
      "name": "Rock_Shale",
      "rotation": 2
    },
    {
      "x": -3,
      "y": 21,
      "z": -6,
      "name": "Rock_Shale",
      "rotation": 2
    },
    {
      "x": -3,
      "y": 22,
      "z": -6,
      "name": "Rock_Shale",
      "rotation": 2
    },
    {
      "x": -3,
      "y": 23,
      "z": -6,
      "name": "Rock_Shale",
      "rotation": 2
    },
    {
      "x": -3,
      "y": 24,
      "z": -6,
      "name": "Rock_Shale_Brick_Stairs",
      "rotation": 3
    },
    {
      "x": -3,
      "y": 2,
      "z": -5,
      "name": "Rock_Shale_Brick_Stairs"
    },
    {
      "x": -3,
      "y": 10,
      "z": -5,
      "name": "Rock_Shale",
      "rotation": 2
    },
    {
      "x": -3,
      "y": 11,
      "z": -5,
      "name": "Rock_Shale_Brick",
      "rotation": 2
    },
    {
      "x": -3,
      "y": 12,
      "z": -5,
      "name": "Rock_Shale_Brick",
      "rotation": 2
    },
    {
      "x": -3,
      "y": 13,
      "z": -5,
      "name": "Rock_Shale_Brick",
      "rotation": 2
    },
    {
      "x": -3,
      "y": 14,
      "z": -5,
