{
  "version": 8,
  "blockIdVersion": 11,
  "anchorX": 0,
  "anchorY": 0,
  "anchorZ": 0,
  "blocks": [
    {
      "x": -11,
      "y": 0,
      "z": -10,
      "name": "Prefab_Spawner_Block",
      "components": {
        "Components": {
          "PrefabSpawner": {
            "FitHeightmap": false,
            "InheritSeed": true,
            "InheritHeightCondition": true
          },
          "PlacedByInteraction": {
            "WhoPlacedUuid": {
              "$binary": "QBnQLM5NQMa81/Qj3+UrJQ==",
              "$type": "04"
            }
          }
        }
      },
      "rotation": 3
    },
    {
      "x": -10,
      "y": 0,
      "z": -15,
      "name": "Rock_Shale_Brick_Smooth"
    },
    {
      "x": -10,
      "y": 1,
      "z": -15,
      "name": "Rock_Shale_Brick"
    },
    {
      "x": -10,
      "y": 2,
      "z": -15,
      "name": "Rock_Shale_Brick"
    },
    {
      "x": -10,
      "y": 3,
      "z": -15,
      "name": "Rock_Shale_Brick"
    },
    {
      "x": -10,
      "y": 4,
      "z": -15,
      "name": "Rock_Shale"
    },
    {
      "x": -10,
      "y": 5,
      "z": -15,
      "name": "Rock_Basalt"
    },
    {
      "x": -10,
      "y": 0,
      "z": -14,
      "name": "Rock_Shale_Brick_Smooth"
    },
    {
      "x": -10,
      "y": 1,
      "z": -14,
      "name": "Rock_Shale_Brick_Pillar_Base"
    },
    {
      "x": -10,
      "y": 2,
      "z": -14,
      "name": "Rock_Shale_Brick_Pillar_Middle"
    },
    {
      "x": -10,
      "y": 3,
      "z": -14,
      "name": "Rock_Shale_Brick_Pillar_Base",
      "rotation": 8
    },
    {
      "x": -10,
      "y": 4,
      "z": -14,
      "name": "Rock_Shale_Brick"
    },
    {
      "x": -10,
      "y": 5,
      "z": -14,
      "name": "Rock_Basalt"
    },
    {
      "x": -10,
      "y": 0,
      "z": -13,
      "name": "Rock_Shale_Brick_Smooth"
    },
    {
      "x": -10,
      "y": 1,
      "z": -13,
      "name": "Empty"
    },
    {
      "x": -10,
      "y": 2,
      "z": -13,
      "name": "Empty"
    },
    {
      "x": -10,
      "y": 3,
      "z": -13,
      "name": "Empty"
    },
    {
      "x": -10,
      "y": 4,
      "z": -13,
      "name": "Rock_Shale_Brick_Stairs",
      "rotation": 10
    },
    {
      "x": -10,
      "y": 5,
      "z": -13,
      "name": "Rock_Basalt"
    },
    {
      "x": -10,
      "y": 0,
      "z": -12,
      "name": "Rock_Shale_Brick_Smooth"
    },
    {
      "x": -10,
      "y": 1,
      "z": -12,
      "name": "Empty"
    },
    {
      "x": -10,
      "y": 2,
      "z": -12,
      "name": "Empty"
    },
    {
      "x": -10,
      "y": 3,
      "z": -12,
      "name": "Empty"
    },
    {
      "x": -10,
      "y": 4,
      "z": -12,
      "name": "Plant_Bush_Dead_Hanging"
    },
    {
      "x": -10,
      "y": 5,
      "z": -12,
      "name": "Rock_Basalt"
    },
    {
      "x": -10,
      "y": 0,
      "z": -11,
      "name": "Rock_Shale_Brick_Smooth"
    },
    {
      "x": -10,
      "y": 1,
      "z": -11,
      "name": "Empty"
    },
    {
      "x": -10,
      "y": 2,
      "z": -11,
      "name": "Empty"
    },
    {
      "x": -10,
      "y": 3,
      "z": -11,
      "name": "Empty"
    },
    {
      "x": -10,
      "y": 4,
      "z": -11,
      "name": "Empty"
    },
    {
      "x": -10,
      "y": 5,
      "z": -11,
      "name": "Rock_Basalt"
    },
    {
      "x": -10,
      "y": 0,
      "z": -10,
      "name": "Rock_Shale_Brick_Smooth"
    },
    {
      "x": -10,
      "y": 1,
      "z": -10,
      "name": "Empty"
    },
    {
      "x": -10,
      "y": 2,
      "z": -10,
      "name": "Empty"
    },
    {
      "x": -10,
      "y": 3,
      "z": -10,
      "name": "Empty"
    },
    {
      "x": -10,
      "y": 4,
      "z": -10,
      "name": "Empty"
    },
    {
      "x": -10,
      "y": 5,
      "z": -10,
      "name": "Rock_Basalt"
    },
    {
      "x": -10,
      "y": 0,
      "z": -9,
      "name": "Rock_Shale_Brick_Smooth"
    },
    {
      "x": -10,
      "y": 1,
      "z": -9,
      "name": "Empty"
    },
    {
      "x": -10,
      "y": 2,
      "z": -9,
      "name": "Empty"
    },
    {
      "x": -10,
      "y": 3,
      "z": -9,
      "name": "Empty"
    },
    {
      "x": -10,
      "y": 4,
      "z": -9,
      "name": "Empty"
    },
    {
      "x": -10,
      "y": 5,
      "z": -9,
      "name": "Rock_Basalt"
    },
    {
      "x": -10,
      "y": 0,
      "z": -8,
      "name": "Rock_Shale_Brick_Smooth"
    },
    {
      "x": -10,
      "y": 1,
      "z": -8,
      "name": "Empty"
    },
    {
      "x": -10,
      "y": 2,
      "z": -8,
      "name": "Empty"
    },
    {
      "x": -10,
      "y": 3,
      "z": -8,
      "name": "Empty"
    },
    {
      "x": -10,
      "y": 4,
      "z": -8,
      "name": "Empty"
    },
    {
      "x": -10,
      "y": 5,
      "z": -8,
      "name": "Rock_Basalt"
    },
    {
      "x": -10,
      "y": 0,
      "z": -7,
      "name": "Rock_Shale_Brick_Smooth"
    },
    {
      "x": -10,
      "y": 1,
      "z": -7,
      "name": "Empty"
    },
    {
      "x": -10,
      "y": 2,
      "z": -7,
      "name": "Empty"
    },
    {
      "x": -10,
      "y": 3,
      "z": -7,
      "name": "Empty"
    },
    {
      "x": -10,
      "y": 4,
      "z": -7,
      "name": "Rock_Shale_Brick_Stairs",
      "rotation": 8
    },
    {
      "x": -10,
      "y": 5,
      "z": -7,
      "name": "Rock_Basalt"
    },
    {
      "x": -10,
      "y": 0,
      "z": -6,
      "name": "Rock_Shale_Brick_Smooth"
    },
    {
      "x": -10,
      "y": 1,
      "z": -6,
      "name": "Rock_Shale_Brick_Pillar_Base"
    },
    {
      "x": -10,
      "y": 2,
      "z": -6,
      "name": "Rock_Shale_Brick_Pillar_Middle"
    },
    {
      "x": -10,
      "y": 3,
      "z": -6,
      "name": "Rock_Shale_Brick_Pillar_Base",
      "rotation": 8
    },
    {
      "x": -10,
      "y": 4,
      "z": -6,
      "name": "Rock_Shale_Brick"
    },
    {
      "x": -10,
      "y": 5,
      "z": -6,
      "name": "Rock_Basalt"
    },
    {
      "x": -10,
      "y": 0,
      "z": -5,
      "name": "Rock_Shale_Brick_Smooth"
    },
    {
      "x": -10,
      "y": 1,
      "z": -5,
      "name": "Rock_Shale_Brick"
    },
    {
      "x": -10,
      "y": 2,
      "z": -5,
      "name": "Rock_Shale_Brick"
    },
    {
      "x": -10,
      "y": 3,
      "z": -5,
      "name": "Rock_Shale_Brick"
    },
    {
      "x": -10,
      "y": 4,
      "z": -5,
      "name": "Rock_Shale"
    },
    {
      "x": -10,
      "y": 5,
      "z": -5,
      "name": "Rock_Basalt"
    },
    {
      "x": -9,
      "y": 0,
      "z": -15,
      "name": "Rock_Shale_Brick_Smooth"
    },
    {
      "x": -9,
      "y": 1,
      "z": -15,
      "name": "Rock_Shale_Brick"
    },
    {
      "x": -9,
      "y": 2,
      "z": -15,
      "name": "Rock_Shale_Brick"
    },
    {
      "x": -9,
      "y": 3,
      "z": -15,
      "name": "Rock_Shale_Brick"
    },
    {
      "x": -9,
      "y": 4,
      "z": -15,
      "name": "Rock_Shale"
    },
    {
      "x": -9,
      "y": 5,
      "z": -15,
      "name": "Rock_Basalt"
    },
    {
      "x": -9,
      "y": 0,
      "z": -14,
      "name": "Rock_Shale_Brick_Smooth"
    },
    {
      "x": -9,
      "y": 1,
      "z": -14,
      "name": "Rock_Shale_Brick_Stairs",
      "rotation": 10
    },
    {
      "x": -9,
      "y": 2,
      "z": -14,
      "name": "Deco_Bone_Skulls"
    },
    {
      "x": -9,
      "y": 3,
      "z": -14,
      "name": "Empty"
    },
    {
      "x": -9,
      "y": 4,
      "z": -14,
      "name": "Rock_Shale_Brick"
    },
    {
      "x": -9,
      "y": 5,
      "z": -14,
      "name": "Rock_Basalt"
    },
    {
      "x": -9,
      "y": 0,
      "z": -13,
      "name": "Rock_Basalt"
    },
    {
      "x": -9,
      "y": 1,
      "z": -13,
      "name": "Empty"
    },
    {
      "x": -9,
      "y": 2,
      "z": -13,
      "name": "Empty"
    },
    {
      "x": -9,
      "y": 3,
      "z": -13,
      "name": "Empty"
    },
    {
      "x": -9,
      "y": 4,
      "z": -13,
      "name": "Empty"
    },
    {
      "x": -9,
      "y": 5,
      "z": -13,
      "name": "Rock_Basalt"
    },
    {
      "x": -9,
      "y": 0,
      "z": -12,
      "name": "Rock_Basalt"
    },
    {
      "x": -9,
      "y": 1,
      "z": -12,
      "name": "Empty"
    },
    {
      "x": -9,
      "y": 2,
      "z": -12,
      "name": "Empty"
    },
    {
      "x": -9,
      "y": 3,
      "z": -12,
      "name": "Empty"
    },
    {
      "x": -9,
      "y": 4,
      "z": -12,
      "name": "Empty"
    },
    {
      "x": -9,
      "y": 5,
      "z": -12,
      "name": "Rock_Basalt"
    },
    {
      "x": -9,
      "y": 0,
      "z": -11,
      "name": "Rock_Shale"
    },
    {
      "x": -9,
      "y": 1,
      "z": -11,
      "name": "Empty"
    },
    {
      "x": -9,
      "y": 2,
      "z": -11,
      "name": "Empty"
    },
    {
      "x": -9,
      "y": 3,
      "z": -11,
      "name": "Empty"
    },
    {
      "x": -9,
      "y": 4,
      "z": -11,
      "name": "Empty"
    },
    {
      "x": -9,
      "y": 5,
      "z": -11,
      "name": "Rock_Basalt"
    },
    {
      "x": -9,
      "y": 0,
      "z": -10,
      "name": "Rock_Shale"
    },
    {
      "x": -9,
      "y": 1,
      "z": -10,
      "name": "Empty"
    },
    {
      "x": -9,
      "y": 2,
      "z": -10,
      "name": "Empty"
    },
    {
      "x": -9,
      "y": 3,
      "z": -10,
      "name": "Empty"
    },
    {
      "x": -9,
      "y": 4,
      "z": -10,
      "name": "Empty"
    },
    {
      "x": -9,
      "y": 5,
      "z": -10,
      "name": "Rock_Basalt"
    },
    {
      "x": -9,
      "y": 0,
      "z": -9,
      "name": "Rock_Shale"
    },
    {
      "x": -9,
      "y": 1,
      "z": -9,
      "name": "Empty"
    },
    {
      "x": -9,
      "y": 2,
      "z": -9,
      "name": "Empty"
    },
    {
      "x": -9,
      "y": 3,
      "z": -9,
      "name": "Empty"
    },
    {
      "x": -9,
      "y": 4,
      "z": -9,
      "name": "Empty"
    },
    {
      "x": -9,
      "y": 5,
      "z": -9,
      "name": "Rock_Basalt"
    },
    {
      "x": -9,
      "y": 0,
      "z": -8,
      "name": "Rock_Shale"
    },
    {
      "x": -9,
      "y": 1,
      "z": -8,
      "name": "Empty"
    },
    {
      "x": -9,
      "y": 2,
      "z": -8,
      "name": "Empty"
    },
    {
      "x": -9,
      "y": 3,
      "z": -8,
      "name": "Empty"
    },
    {
      "x": -9,
      "y": 4,
      "z": -8,
      "name": "Empty"
    },
    {
      "x": -9,
      "y": 5,
      "z": -8,
      "name": "Rock_Basalt"
    },
    {
      "x": -9,
      "y": 0,
      "z": -7,
      "name": "Rock_Basalt"
    },
    {
      "x": -9,
      "y": 1,
      "z": -7,
      "name": "Empty"
    },
    {
      "x": -9,
      "y": 2,
      "z": -7,
      "name": "Empty"
    },
    {
      "x": -9,
      "y": 3,
      "z": -7,
      "name": "Empty"
    },
    {
      "x": -9,
      "y": 4,
      "z": -7,
      "name": "Empty"
    },
    {
      "x": -9,
      "y": 5,
      "z": -7,
      "name": "Rock_Basalt"
    },
    {
      "x": -9,
      "y": 0,
      "z": -6,
      "name": "Rock_Shale_Brick_Smooth"
    },
    {
      "x": -9,
      "y": 1,
      "z": -6,
      "name": "Rock_Shale_Brick_Stairs",
      "rotation": 8
    },
    {
      "x": -9,
      "y": 2,
      "z": -6,
      "name": "Deco_Bone_Skulls"
    },
    {
      "x": -9,
      "y": 3,
      "z": -6,
      "name": "Empty"
    },
    {
      "x": -9,
      "y": 4,
      "z": -6,
      "name": "Rock_Shale_Brick"
    },
    {
      "x": -9,
      "y": 5,
      "z": -6,
      "name": "Rock_Basalt"
    },
    {
      "x": -9,
      "y": 0,
      "z": -5,
      "name": "Rock_Shale_Brick_Smooth"
    },
    {
      "x": -9,
      "y": 1,
      "z": -5,
      "name": "Rock_Shale_Brick"
    },
    {
      "x": -9,
      "y": 2,
      "z": -5,
      "name": "Rock_Shale_Brick"
    },
    {
      "x": -9,
      "y": 3,
      "z": -5,
      "name": "Rock_Shale_Brick"
    },
    {
      "x": -9,
      "y": 4,
      "z": -5,
      "name": "Rock_Shale"
    },
    {
      "x": -9,
      "y": 5,
      "z": -5,
      "name": "Rock_Basalt"
    },
    {
      "x": -8,
      "y": 0,
      "z": -15,
      "name": "Rock_Shale_Brick_Smooth"
    },
    {
      "x": -8,
      "y": 1,
      "z": -15,
      "name": "Rock_Basalt"
    },
    {
      "x": -8,
      "y": 2,
      "z": -15,
      "name": "Rock_Basalt"
    },
    {
      "x": -8,
      "y": 3,
      "z": -15,
      "name": "Rock_Basalt"
    },
    {
      "x": -8,
      "y": 4,
      "z": -15,
      "name": "Rock_Shale"
    },
    {
      "x": -8,
      "y": 5,
      "z": -15,
      "name": "Rock_Basalt"
    },
    {
      "x": -8,
      "y": 0,
      "z": -14,
      "name": "Rock_Shale_Brick_Smooth"
    },
    {
      "x": -8,
      "y": 1,
      "z": -14,
      "name": "Rock_Shale_Brick_Stairs",
      "rotation": 10
    },
    {
      "x": -8,
      "y": 2,
      "z": -14,
      "name": "Deco_Bone_Pile"
    },
    {
      "x": -8,
      "y": 3,
      "z": -14,
      "name": "Empty"
    },
    {
      "x": -8,
      "y": 4,
      "z": -14,
      "name": "Rock_Shale_Brick"
    },
    {
      "x": -8,
      "y": 5,
      "z": -14,
      "name": "Rock_Basalt"
    },
    {
      "x": -8,
      "y": 0,
      "z": -13,
      "name": "Rock_Basalt"
    },
    {
      "x": -8,
      "y": 1,
      "z": -13,
      "name": "Empty"
    },
    {
      "x": -8,
      "y": 2,
      "z": -13,
      "name": "Empty"
    },
    {
      "x": -8,
      "y": 3,
      "z": -13,
      "name": "Empty"
    },
    {
      "x": -8,
      "y": 4,
      "z": -13,
      "name": "Empty"
    },
    {
      "x": -8,
      "y": 5,
      "z": -13,
      "name": "Rock_Basalt"
    },
    {
      "x": -8,
      "y": 0,
      "z": -12,
      "name": "Rock_Shale"
    },
    {
      "x": -8,
      "y": 1,
      "z": -12,
      "name": "Empty"
    },
    {
      "x": -8,
      "y": 2,
      "z": -12,
      "name": "Empty"
    },
    {
      "x": -8,
      "y": 3,
      "z": -12,
      "name": "Empty"
    },
    {
      "x": -8,
      "y": 4,
      "z": -12,
      "name": "Empty"
    },
    {
      "x": -8,
      "y": 5,
      "z": -12,
      "name": "Rock_Basalt"
    },
    {
      "x": -8,
      "y": 0,
      "z": -11,
      "name": "Rock_Shale"
    },
    {
      "x": -8,
      "y": 1,
      "z": -11,
      "name": "Empty"
    },
    {
      "x": -8,
      "y": 2,
      "z": -11,
      "name": "Empty"
    },
    {
      "x": -8,
      "y": 3,
      "z": -11,
      "name": "Empty"
    },
    {
      "x": -8,
      "y": 4,
      "z": -11,
      "name": "Empty"
    },
    {
      "x": -8,
      "y": 5,
      "z": -11,
      "name": "Rock_Basalt"
    },
    {
      "x": -8,
      "y": 0,
      "z": -10,
      "name": "Rock_Shale"
    },
    {
      "x": -8,
      "y": 1,
      "z": -10,
      "name": "Empty"
    },
    {
      "x": -8,
      "y": 2,
      "z": -10,
      "name": "Empty"
    },
    {
      "x": -8,
      "y": 3,
      "z": -10,
      "name": "Empty"
    },
    {
      "x": -8,
      "y": 4,
      "z": -10,
      "name": "Empty"
    },
    {
      "x": -8,
      "y": 5,
      "z": -10,
      "name": "Rock_Basalt"
    },
    {
      "x": -8,
      "y": 0,
      "z": -9,
      "name": "Rock_Shale"
    },
    {
      "x": -8,
      "y": 1,
      "z": -9,
      "name": "Empty"
    },
    {
      "x": -8,
      "y": 2,
      "z": -9,
      "name": "Empty"
    },
    {
      "x": -8,
      "y": 3,
      "z": -9,
      "name": "Empty"
    },
    {
      "x": -8,
      "y": 4,
      "z": -9,
      "name": "Empty"
    },
    {
      "x": -8,
      "y": 5,
      "z": -9,
      "name": "Rock_Basalt"
    },
    {
      "x": -8,
      "y": 0,
      "z": -8,
      "name": "Rock_Shale"
    },
    {
      "x": -8,
      "y": 1,
      "z": -8,
      "name": "Empty"
    },
    {
      "x": -8,
      "y": 2,
      "z": -8,
      "name": "Empty"
    },
    {
      "x": -8,
      "y": 3,
      "z": -8,
      "name": "Empty"
    },
    {
      "x": -8,
      "y": 4,
      "z": -8,
      "name": "Empty"
    },
    {
      "x": -8,
      "y": 5,
      "z": -8,
      "name": "Rock_Basalt"
    },
    {
      "x": -8,
      "y": 0,
      "z": -7,
      "name": "Rock_Basalt"
    },
    {
      "x": -8,
      "y": 1,
      "z": -7,
      "name": "Empty"
    },
    {
      "x": -8,
      "y": 2,
      "z": -7,
      "name": "Empty"
    },
    {
      "x": -8,
      "y": 3,
      "z": -7,
      "name": "Empty"
    },
    {
      "x": -8,
      "y": 4,
      "z": -7,
      "name": "Empty"
    },
    {
      "x": -8,
      "y": 5,
      "z": -7,
      "name": "Rock_Basalt"
    },
    {
      "x": -8,
      "y": 0,
      "z": -6,
      "name": "Rock_Shale_Brick_Smooth"
    },
    {
      "x": -8,
      "y": 1,
      "z": -6,
      "name": "Rock_Shale_Brick_Stairs",
      "rotation": 8
    },
    {
      "x": -8,
      "y": 2,
      "z": -6,
      "name": "Deco_Bone_Pile"
    },
    {
      "x": -8,
      "y": 3,
      "z": -6,
      "name": "Empty"
    },
    {
      "x": -8,
      "y": 4,
      "z": -6,
      "name": "Rock_Shale_Brick"
    },
    {
      "x": -8,
      "y": 5,
      "z": -6,
      "name": "Rock_Basalt"
    },
    {
      "x": -8,
      "y": 0,
      "z": -5,
      "name": "Rock_Shale_Brick_Smooth"
    },
    {
      "x": -8,
      "y": 1,
      "z": -5,
      "name": "Rock_Basalt"
    },
    {
      "x": -8,
      "y": 2,
      "z": -5,
      "name": "Rock_Basalt"
    },
    {
      "x": -8,
      "y": 3,
      "z": -5,
      "name": "Rock_Basalt"
    },
    {
      "x": -8,
      "y": 4,
      "z": -5,
      "name": "Rock_Shale"
    },
    {
      "x": -8,
      "y": 5,
      "z": -5,
      "name": "Rock_Basalt"
    },
    {
      "x": -7,
      "y": 0,
      "z": -15,
      "name": "Rock_Shale_Brick_Smooth"
    },
    {
      "x": -7,
      "y": 1,
      "z": -15,
      "name": "Rock_Shale_Brick"
    },
    {
      "x": -7,
      "y": 2,
      "z": -15,
      "name": "Rock_Shale_Brick"
    },
    {
      "x": -7,
      "y": 3,
      "z": -15,
      "name": "Rock_Shale_Brick"
    },
    {
      "x": -7,
      "y": 4,
      "z": -15,
      "name": "Rock_Shale"
    },
    {
      "x": -7,
      "y": 5,
      "z": -15,
      "name": "Rock_Basalt"
    },
    {
      "x": -7,
      "y": 0,
      "z": -14,
      "name": "Rock_Shale_Brick_Smooth"
    },
    {
      "x": -7,
      "y": 1,
      "z": -14,
      "name": "Rock_Shale_Brick_Stairs",
      "rotation": 10
    },
    {
      "x": -7,
      "y": 2,
      "z": -14,
      "name": "Empty"
    },
    {
      "x": -7,
      "y": 3,
      "z": -14,
      "name": "Empty"
    },
    {
      "x": -7,
      "y": 4,
      "z": -14,
      "name": "Rock_Shale_Brick"
    },
    {
      "x": -7,
      "y": 5,
      "z": -14,
      "name": "Rock_Basalt"
    },
    {
      "x": -7,
      "y": 0,
      "z": -13,
      "name": "Soil_Dirt_Cold"
    },
    {
      "x": -7,
      "y": 1,
      "z": -13,
      "name": "Furniture_Ancient_Barrel"
    },
    {
      "x": -7,
      "y": 2,
      "z": -13,
      "name": "Empty"
    },
    {
      "x": -7,
      "y": 3,
      "z": -13,
      "name": "Empty"
    },
    {
      "x": -7,
      "y": 4,
      "z": -13,
      "name": "Empty"
    },
    {
      "x": -7,
      "y": 5,
      "z": -13,
      "name": "Rock_Basalt"
    },
    {
      "x": -7,
      "y": 0,
      "z": -12,
      "name": "Rock_Shale"
    },
    {
      "x": -7,
      "y": 1,
      "z": -12,
      "name": "Empty"
    },
    {
      "x": -7,
      "y": 2,
      "z": -12,
      "name": "Empty"
    },
    {
      "x": -7,
      "y": 3,
      "z": -12,
      "name": "Empty"
    },
    {
      "x": -7,
      "y": 4,
      "z": -12,
      "name": "Empty"
    },
    {
      "x": -7,
      "y": 5,
      "z": -12,
      "name": "Rock_Basalt"
    },
    {
      "x": -7,
      "y": 0,
      "z": -11,
      "name": "Rock_Shale"
    },
    {
      "x": -7,
      "y": 1,
      "z": -11,
      "name": "Empty"
    },
    {
      "x": -7,
      "y": 2,
      "z": -11,
      "name": "Empty"
    },
    {
      "x": -7,
      "y": 3,
      "z": -11,
      "name": "Empty"
    },
    {
      "x": -7,
      "y": 4,
      "z": -11,
      "name": "Empty"
    },
    {
      "x": -7,
      "y": 5,
      "z": -11,
      "name": "Rock_Basalt"
    },
    {
      "x": -7,
      "y": 0,
      "z": -10,
      "name": "Rock_Shale"
    },
    {
      "x": -7,
      "y": 1,
      "z": -10,
      "name": "Empty"
    },
    {
      "x": -7,
      "y": 2,
      "z": -10,
      "name": "Empty"
    },
    {
      "x": -7,
      "y": 3,
      "z": -10,
      "name": "Empty"
    },
    {
      "x": -7,
      "y": 4,
      "z": -10,
      "name": "Empty"
    },
    {
      "x": -7,
      "y": 5,
      "z": -10,
      "name": "Rock_Basalt"
    },
    {
      "x": -7,
      "y": 0,
      "z": -9,
      "name": "Rock_Shale"
    },
    {
      "x": -7,
      "y": 1,
      "z": -9,
      "name": "Empty"
    },
    {
      "x": -7,
      "y": 2,
      "z": -9,
      "name": "Empty"
    },
    {
      "x": -7,
      "y": 3,
      "z": -9,
      "name": "Empty"
    },
    {
      "x": -7,
      "y": 4,
      "z": -9,
      "name": "Empty"
    },
    {
      "x": -7,
      "y": 5,
      "z": -9,
      "name": "Rock_Basalt"
    },
    {
      "x": -7,
      "y": 0,
      "z": -8,
      "name": "Rock_Basalt"
    },
    {
      "x": -7,
      "y": 1,
      "z": -8,
      "name": "Empty"
    },
    {
      "x": -7,
      "y": 2,
      "z": -8,
      "name": "Empty"
    },
    {
      "x": -7,
      "y": 3,
      "z": -8,
      "name": "Empty"
    },
    {
      "x": -7,
      "y": 4,
      "z": -8,
      "name": "Plant_Bush_Dead_Hanging"
    },
    {
      "x": -7,
      "y": 5,
      "z": -8,
      "name": "Rock_Basalt"
    },
    {
      "x": -7,
      "y": 0,
      "z": -7,
      "name": "Rock_Basalt"
    },
    {
      "x": -7,
      "y": 1,
      "z": -7,
      "name": "Empty"
    },
    {
      "x": -7,
      "y": 2,
      "z": -7,
      "name": "Empty"
    },
    {
      "x": -7,
      "y": 3,
      "z": -7,
      "name": "Empty"
    },
    {
      "x": -7,
      "y": 4,
      "z": -7,
      "name": "Empty"
    },
    {
      "x": -7,
      "y": 5,
      "z": -7,
      "name": "Rock_Basalt"
    },
    {
      "x": -7,
      "y": 0,
      "z": -6,
      "name": "Rock_Shale_Brick_Smooth"
    },
    {
      "x": -7,
      "y": 1,
      "z": -6,
      "name": "Rock_Shale_Brick_Stairs",
      "rotation": 8
    },
    {
      "x": -7,
      "y": 2,
      "z": -6,
      "name": "Deco_Bone_Skulls"
    },
    {
      "x": -7,
      "y": 3,
      "z": -6,
      "name": "Empty"
    },
    {
      "x": -7,
      "y": 4,
      "z": -6,
      "name": "Rock_Shale_Brick"
    },
    {
      "x": -7,
      "y": 5,
      "z": -6,
      "name": "Rock_Basalt"
    },
    {
      "x": -7,
      "y": 0,
      "z": -5,
      "name": "Rock_Shale_Brick_Smooth"
    },
    {
      "x": -7,
      "y": 1,
      "z": -5,
      "name": "Rock_Shale_Brick"
    },
    {
      "x": -7,
      "y": 2,
      "z": -5,
      "name": "Rock_Shale_Brick"
    },
    {
      "x": -7,
      "y": 3,
      "z": -5,
      "name": "Rock_Shale_Brick"
    },
    {
      "x": -7,
      "y": 4,
      "z": -5,
      "name": "Rock_Shale"
    },
    {
      "x": -7,
      "y": 5,
      "z": -5,
      "name": "Rock_Basalt"
    },
    {
      "x": -6,
      "y": 0,
      "z": -15,
      "name": "Rock_Shale_Brick_Smooth"
    },
    {
      "x": -6,
      "y": 1,
      "z": -15,
      "name": "Rock_Shale_Brick"
    },
    {
      "x": -6,
      "y": 2,
      "z": -15,
      "name": "Rock_Shale_Brick"
    },
    {
      "x": -6,
      "y": 3,
      "z": -15,
      "name": "Rock_Shale_Brick"
    },
    {
      "x": -6,
      "y": 4,
      "z": -15,
      "name": "Rock_Shale"
    },
    {
      "x": -6,
      "y": 5,
      "z": -15,
      "name": "Rock_Basalt"
    },
    {
      "x": -6,
      "y": 0,
      "z": -14,
      "name": "Rock_Shale_Brick_Smooth"
    },
    {
      "x": -6,
      "y": 1,
      "z": -14,
      "name": "Rock_Shale_Brick_Pillar_Base"
    },
    {
      "x": -6,
      "y": 2,
      "z": -14,
      "name": "Rock_Shale_Brick_Pillar_Middle"
    },
    {
      "x": -6,
      "y": 3,
      "z": -14,
      "name": "Rock_Shale_Brick_Pillar_Base",
      "rotation": 8
    },
    {
      "x": -6,
      "y": 4,
      "z": -14,
      "name": "Rock_Shale_Brick"
    },
    {
      "x": -6,
      "y": 5,
      "z": -14,
      "name": "Rock_Basalt"
    },
    {
      "x": -6,
      "y": 0,
      "z": -13,
      "name": "Soil_Dirt_Cold"
    },
    {
      "x": -6,
      "y": 1,
      "z": -13,
      "name": "Furniture_Ancient_Crate"
    },
    {
      "x": -6,
      "y": 2,
      "z": -13,
      "name": "Empty"
    },
    {
      "x": -6,
      "y": 3,
      "z": -13,
      "name": "Empty"
    },
    {
      "x": -6,
      "y": 4,
      "z": -13,
      "name": "Rock_Shale_Brick_Stairs",
      "rotation": 10
    },
    {
      "x": -6,
      "y": 5,
      "z": -13,
      "name": "Rock_Basalt"
    },
    {
      "x": -6,
      "y": 0,
      "z": -12,
      "name": "Rock_Shale"
    },
    {
      "x": -6,
      "y": 1,
      "z": -12,
      "name": "Empty"
    },
    {
      "x": -6,
      "y": 2,
      "z": -12,
      "name": "Empty"
    },
    {
      "x": -6,
      "y": 3,
      "z": -12,
      "name": "Empty"
    },
    {
      "x": -6,
      "y": 4,
      "z": -12,
      "name": "Empty"
    },
    {
      "x": -6,
      "y": 5,
      "z": -12,
      "name": "Rock_Basalt"
    },
    {
      "x": -6,
      "y": 0,
      "z": -11,
      "name": "Rock_Shale"
    },
    {
      "x": -6,
      "y": 1,
      "z": -11,
      "name": "Empty"
    },
    {
      "x": -6,
      "y": 2,
      "z": -11,
      "name": "Empty"
    },
    {
      "x": -6,
      "y": 3,
      "z": -11,
      "name": "Empty"
    },
    {
      "x": -6,
      "y": 4,
      "z": -11,
      "name": "Empty"
    },
    {
      "x": -6,
      "y": 5,
      "z": -11,
      "name": "Rock_Basalt"
    },
    {
      "x": -6,
      "y": 0,
      "z": -10,
      "name": "Rock_Shale"
    },
    {
      "x": -6,
      "y": 1,
      "z": -10,
      "name": "Empty"
    },
    {
      "x": -6,
      "y": 2,
      "z": -10,
      "name": "Empty"
    },
    {
      "x": -6,
      "y": 3,
      "z": -10,
      "name": "Empty"
    },
    {
      "x": -6,
      "y": 4,
      "z": -10,
      "name": "Empty"
    },
    {
      "x": -6,
      "y": 5,
      "z": -10,
      "name": "Rock_Basalt"
    },
    {
      "x": -6,
      "y": 0,
      "z": -9,
      "name": "Rock_Shale"
    },
    {
      "x": -6,
      "y": 1,
      "z": -9,
      "name": "Empty"
    },
    {
      "x": -6,
      "y": 2,
      "z": -9,
      "name": "Empty"
    },
    {
      "x": -6,
      "y": 3,
      "z": -9,
      "name": "Empty"
    },
    {
      "x": -6,
      "y": 4,
      "z": -9,
      "name": "Empty"
    },
    {
      "x": -6,
      "y": 5,
      "z": -9,
      "name": "Rock_Basalt"
    },
    {
      "x": -6,
      "y": 0,
      "z": -8,
      "name": "Rock_Basalt"
    },
    {
      "x": -6,
      "y": 1,
      "z": -8,
      "name": "Empty"
    },
    {
      "x": -6,
      "y": 2,
      "z": -8,
      "name": "Empty"
    },
    {
      "x": -6,
      "y": 3,
      "z": -8,
      "name": "Empty"
    },
    {
      "x": -6,
      "y": 4,
      "z": -8,
      "name": "Empty"
    },
    {
      "x": -6,
      "y": 5,
      "z": -8,
      "name": "Rock_Basalt"
    },
    {
      "x": -6,
      "y": 0,
      "z": -7,
      "name": "Soil_Dirt_Cold"
    },
    {
      "x": -6,
      "y": 1,
      "z": -7,
      "name": "Furniture_Ancient_Crate",
      "rotation": 2
    },
    {
      "x": -6,
      "y": 2,
      "z": -7,
      "name": "Empty"
    },
    {
      "x": -6,
      "y": 3,
      "z": -7,
      "name": "Empty"
    },
    {
      "x": -6,
      "y": 4,
      "z": -7,
      "name": "Rock_Shale_Brick_Stairs",
      "rotation": 8
    },
    {
      "x": -6,
      "y": 5,
      "z": -7,
      "name": "Rock_Basalt"
    },
    {
      "x": -6,
      "y": 0,
      "z": -6,
      "name": "Rock_Shale_Brick_Smooth"
    },
    {
      "x": -6,
      "y": 1,
      "z": -6,
      "name": "Rock_Shale_Brick_Pillar_Base"
    },
    {
      "x": -6,
      "y": 2,
      "z": -6,
      "name": "Rock_Shale_Brick_Pillar_Middle"
    },
    {
      "x": -6,
      "y": 3,
      "z": -6,
      "name": "Rock_Shale_Brick_Pillar_Base",
      "rotation": 8
    },
    {
      "x": -6,
      "y": 4,
      "z": -6,
      "name": "Rock_Shale_Brick"
    },
    {
      "x": -6,
      "y": 5,
      "z": -6,
      "name": "Rock_Basalt"
    },
    {
      "x": -6,
      "y": 0,
      "z": -5,
      "name": "Rock_Shale_Brick_Smooth"
    },
    {
      "x": -6,
      "y": 1,
      "z": -5,
      "name": "Rock_Shale_Brick"
    },
    {
      "x": -6,
      "y": 2,
      "z": -5,
      "name": "Rock_Shale_Brick"
    },
    {
      "x": -6,
      "y": 3,
      "z": -5,
      "name": "Rock_Shale_Brick"
    },
    {
      "x": -6,
      "y": 4,
      "z": -5,
      "name": "Rock_Shale"
    },
    {
      "x": -6,
      "y": 5,
      "z": -5,
      "name": "Rock_Basalt"
    },
    {
      "x": -5,
      "y": 0,
      "z": -15,
      "name": "Rock_Shale_Brick_Smooth"
    },
    {
      "x": -5,
      "y": 1,
      "z": -15,
      "name": "Rock_Shale"
    },
    {
      "x": -5,
      "y": 2,
      "z": -15,
      "name": "Rock_Shale"
    },
    {
      "x": -5,
      "y": 3,
      "z": -15,
      "name": "Rock_Shale"
    },
    {
      "x": -5,
      "y": 4,
      "z": -15,
      "name": "Rock_Shale"
    },
    {
      "x": -5,
      "y": 5,
      "z": -15,
      "name": "Rock_Basalt"
    },
    {
      "x": -5,
      "y": 0,
      "z": -14,
      "name": "Rock_Shale_Brick_Smooth"
    },
    {
      "x": -5,
      "y": 1,
      "z": -14,
      "name": "Rock_Basalt_Brick"
    },
    {
      "x": -5,
      "y": 2,
      "z": -14,
      "name": "Rock_Basalt_Brick"
    },
    {
      "x": -5,
      "y": 3,
      "z": -14,
      "name": "Rock_Basalt_Brick"
    },
    {
      "x": -5,
      "y": 4,
      "z": -14,
      "name": "Rock_Basalt_Brick"
    },
    {
      "x": -5,
      "y": 5,
      "z": -14,
      "name": "Rock_Basalt"
    },
    {
      "x": -5,
      "y": 0,
      "z": -13,
      "name": "Soil_Dirt_Cold"
    },
    {
      "x": -5,
      "y": 1,
      "z": -13,
      "name": "Empty"
    },
    {
      "x": -5,
      "y": 2,
      "z": -13,
      "name": "Empty"
    },
    {
      "x": -5,
      "y": 3,
      "z": -13,
      "name": "Rock_Basalt_Brick"
    },
    {
      "x": -5,
      "y": 4,
      "z": -13,
      "name": "Rock_Basalt_Brick"
    },
    {
      "x": -5,
      "y": 5,
      "z": -13,
      "name": "Rock_Basalt"
    },
    {
      "x": -5,
      "y": 0,
      "z": -12,
      "name": "Soil_Dirt_Cold"
    },
    {
      "x": -5,
      "y": 1,
      "z": -12,
      "name": "Deco_Bone_Pile"
    },
    {
      "x": -5,
      "y": 2,
      "z": -12,
      "name": "Empty"
    },
    {
      "x": -5,
      "y": 3,
      "z": -12,
      "name": "Rock_Basalt_Brick_Half",
      "rotation": 8
    },
    {
      "x": -5,
      "y": 4,
      "z": -12,
      "name": "Rock_Basalt_Brick"
    },
    {
      "x": -5,
      "y": 5,
      "z": -12,
      "name": "Rock_Basalt"
    },
    {
      "x": -5,
      "y": 0,
      "z": -11,
      "name": "Rock_Shale"
    },
    {
      "x": -5,
      "y": 1,
      "z": -11,
      "name": "Empty"
    },
    {
      "x": -5,
      "y": 2,
      "z": -11,
      "name": "Empty"
    },
    {
      "x": -5,
      "y": 3,
      "z": -11,
      "name": "Empty"
    },
    {
      "x": -5,
      "y": 4,
      "z": -11,
      "name": "Rock_Basalt_Brick"
    },
    {
      "x": -5,
      "y": 5,
      "z": -11,
      "name": "Rock_Basalt"
    },
    {
      "x": -5,
      "y": 0,
      "z": -10,
      "name": "Rock_Shale"
    },
    {
      "x": -5,
      "y": 1,
      "z": -10,
      "name": "Empty"
    },
    {
      "x": -5,
      "y": 2,
      "z": -10,
      "name": "Empty"
    },
    {
      "x": -5,
      "y": 3,
      "z": -10,
      "name": "Empty"
    },
    {
      "x": -5,
      "y": 4,
      "z": -10,
      "name": "Rock_Basalt_Brick"
    },
    {
      "x": -5,
      "y": 5,
      "z": -10,
      "name": "Rock_Basalt"
    },
    {
      "x": -5,
      "y": 0,
      "z": -9,
      "name": "Rock_Shale"
    },
    {
      "x": -5,
      "y": 1,
      "z": -9,
      "name": "Empty"
    },
    {
      "x": -5,
      "y": 2,
      "z": -9,
      "name": "Empty"
    },
    {
      "x": -5,
      "y": 3,
      "z": -9,
      "name": "Empty"
    },
    {
      "x": -5,
      "y": 4,
      "z": -9,
      "name": "Rock_Basalt_Brick"
    },
    {
      "x": -5,
      "y": 5,
      "z": -9,
      "name": "Rock_Basalt"
    },
    {
      "x": -5,
      "y": 0,
      "z": -8,
      "name": "Soil_Dirt_Cold"
    },
    {
      "x": -5,
      "y": 1,
      "z": -8,
      "name": "Empty"
    },
    {
      "x": -5,
      "y": 2,
      "z": -8,
      "name": "Empty"
    },
    {
      "x": -5,
      "y": 3,
      "z": -8,
      "name": "Rock_Basalt_Brick_Half",
      "rotation": 8
    },
    {
      "x": -5,
      "y": 4,
      "z": -8,
      "name": "Rock_Basalt_Brick"
    },
    {
      "x": -5,
      "y": 5,
      "z": -8,
      "name": "Rock_Basalt"
    },
    {
      "x": -5,
      "y": 0,
      "z": -7,
      "name": "Soil_Dirt_Cold"
    },
    {
      "x": -5,
      "y": 1,
      "z": -7,
      "name": "Empty"
    },
    {
      "x": -5,
      "y": 2,
      "z": -7,
      "name": "Empty"
    },
    {
      "x": -5,
      "y": 3,
      "z": -7,
      "name": "Rock_Basalt_Brick"
    },
    {
      "x": -5,
      "y": 4,
      "z": -7,
      "name": "Rock_Basalt_Brick"
    },
    {
      "x": -5,
      "y": 5,
      "z": -7,
      "name": "Rock_Basalt"
    },
    {
      "x": -5,
      "y": 0,
      "z": -6,
      "name": "Rock_Shale_Brick_Smooth"
    },
    {
      "x": -5,
      "y": 1,
      "z": -6,
      "name": "Rock_Basalt_Brick"
    },
    {
      "x": -5,
      "y": 2,
      "z": -6,
      "name": "Rock_Basalt_Brick"
    },
    {
      "x": -5,
      "y": 3,
      "z": -6,
      "name": "Rock_Basalt_Brick"
    },
    {
      "x": -5,
      "y": 4,
      "z": -6,
      "name": "Rock_Basalt_Brick"
    },
    {
      "x": -5,
      "y": 5,
      "z": -6,
      "name": "Rock_Basalt"
    },
    {
      "x": -5,
      "y": 0,
      "z": -5,
      "name": "Rock_Shale_Brick_Smooth"
    },
    {
      "x": -5,
      "y": 1,
      "z": -5,
      "name": "Rock_Shale"
    },
    {
      "x": -5,
      "y": 2,
      "z": -5,
      "name": "Rock_Shale"
    },
    {
      "x": -5,
      "y": 3,
      "z": -5,
      "name": "Rock_Shale"
    },
    {
      "x": -5,
      "y": 4,
      "z": -5,
      "name": "Rock_Shale"
    },
    {
      "x": -5,
      "y": 5,
      "z": -5,
      "name": "Rock_Basalt"
    },
    {
      "x": -5,
      "y": 0,
      "z": -4,
      "name": "Rock_Shale_Brick_Smooth"
    },
    {
      "x": -5,
      "y": 1,
      "z": -4,
      "name": "Rock_Shale_Brick"
    },
    {
      "x": -5,
      "y": 2,
      "z": -4,
      "name": "Rock_Shale_Brick"
    },
    {
      "x": -5,
      "y": 3,
      "z": -4,
      "name": "Rock_Shale_Brick"
    },
    {
      "x": -5,
      "y": 4,
      "z": -4,
      "name": "Rock_Shale"
    },
    {
      "x": -5,
      "y": 5,
      "z": -4,
      "name": "Rock_Basalt"
    },
    {
      "x": -5,
      "y": 0,
      "z": -3,
      "name": "Rock_Shale_Brick_Smooth"
    },
    {
      "x": -5,
      "y": 1,
      "z": -3,
      "name": "Rock_Shale_Brick"
    },
    {
      "x": -5,
      "y": 2,
      "z": -3,
      "name": "Rock_Shale_Brick"
    },
    {
      "x": -5,
      "y": 3,
      "z": -3,
      "name": "Rock_Shale_Brick"
    },
    {
      "x": -5,
      "y": 4,
      "z": -3,
      "name": "Rock_Shale"
    },
    {
      "x": -5,
      "y": 5,
      "z": -3,
      "name": "Rock_Basalt"
    },
    {
      "x": -5,
      "y": 0,
      "z": -2,
      "name": "Rock_Shale_Brick_Smooth"
    },
    {
      "x": -5,
      "y": 1,
      "z": -2,
      "name": "Rock_Basalt"
    },
    {
      "x": -5,
      "y": 2,
      "z": -2,
      "name": "Rock_Basalt"
    },
    {
      "x": -5,
      "y": 3,
      "z": -2,
      "name": "Rock_Basalt"
    },
    {
      "x": -5,
      "y": 4,
      "z": -2,
      "name": "Rock_Shale"
    },
    {
      "x": -5,
      "y": 5,
      "z": -2,
      "name": "Rock_Basalt"
    },
    {
      "x": -5,
      "y": 0,
      "z": -1,
      "name": "Rock_Shale_Brick_Smooth"
    },
    {
      "x": -5,
      "y": 1,
      "z": -1,
      "name": "Rock_Shale_Brick"
    },
    {
      "x": -5,
      "y": 2,
      "z": -1,
      "name": "Rock_Shale_Brick"
    },
    {
      "x": -5,
      "y": 3,
      "z": -1,
      "name": "Rock_Shale_Brick"
    },
    {
      "x": -5,
      "y": 4,
      "z": -1,
      "name": "Rock_Shale"
    },
    {
      "x": -5,
      "y": 5,
      "z": -1,
      "name": "Rock_Basalt"
    },
    {
      "x": -5,
      "y": 0,
      "z": 0,
      "name": "Rock_Shale_Brick_Smooth"
    },
    {
      "x": -5,
      "y": 1,
      "z": 0,
      "name": "Rock_Shale_Brick"
    },
    {
      "x": -5,
      "y": 2,
      "z": 0,
      "name": "Rock_Shale_Brick"
    },
    {
      "x": -5,
      "y": 3,
      "z": 0,
      "name": "Rock_Shale_Brick"
    },
    {
      "x": -5,
      "y": 4,
      "z": 0,
      "name": "Rock_Shale"
    },
    {
      "x": -5,
      "y": 5,
      "z": 0,
      "name": "Rock_Basalt"
    },
    {
      "x": -4,
      "y": 0,
      "z": -15,
      "name": "Rock_Shale_Brick_Smooth"
    },
    {
      "x": -4,
      "y": 1,
      "z": -15,
      "name": "Rock_Basalt_Brick"
    },
    {
      "x": -4,
      "y": 2,
      "z": -15,
      "name": "Rock_Basalt_Brick"
    },
    {
      "x": -4,
      "y": 3,
      "z": -15,
      "name": "Rock_Basalt_Brick"
    },
    {
      "x": -4,
      "y": 4,
      "z": -15,
      "name": "Rock_Basalt_Brick"
    },
    {
      "x": -4,
      "y": 5,
      "z": -15,
      "name": "Rock_Basalt"
    },
    {
      "x": -4,
      "y": 0,
      "z": -14,
      "name": "Rock_Shale_Brick_Smooth"
    },
    {
      "x": -4,
      "y": 1,
      "z": -14,
      "name": "Rock_Basalt_Brick"
    },
    {
      "x": -4,
      "y": 2,
      "z": -14,
      "name": "Rock_Basalt_Brick"
    },
    {
      "x": -4,
      "y": 3,
      "z": -14,
      "name": "Rock_Basalt_Brick"
    },
    {
      "x": -4,
      "y": 4,
      "z": -14,
      "name": "Rock_Basalt_Brick"
    },
    {
      "x": -4,
      "y": 5,
      "z": -14,
      "name": "Rock_Basalt"
    },
    {
      "x": -4,
      "y": 0,
      "z": -13,
      "name": "Soil_Dirt_Cold"
    },
    {
      "x": -4,
      "y": 1,
      "z": -13,
      "name": "Plant_Bush_Dead_Twisted"
    },
    {
      "x": -4,
      "y": 2,
      "z": -13,
      "name": "Empty"
    },
    {
      "x": -4,
      "y": 3,
      "z": -13,
      "name": "Rock_Basalt_Brick"
    },
    {
      "x": -4,
      "y": 4,
      "z": -13,
      "name": "Rock_Basalt_Brick"
    },
    {
      "x": -4,
      "y": 5,
      "z": -13,
      "name": "Rock_Basalt"
    },
    {
      "x": -4,
      "y": 0,
      "z": -12,
      "name": "Soil_Dirt_Cold"
    },
    {
      "x": -4,
      "y": 1,
      "z": -12,
      "name": "Empty"
    },
    {
      "x": -4,
      "y": 2,
      "z": -12,
      "name": "Empty"
    },
    {
      "x": -4,
      "y": 3,
      "z": -12,
      "name": "Rock_Basalt_Brick_Half",
      "rotation": 8
    },
    {
      "x": -4,
      "y": 4,
      "z": -12,
      "name": "Rock_Basalt_Brick"
    },
    {
      "x": -4,
      "y": 5,
      "z": -12,
      "name": "Rock_Basalt"
    },
    {
      "x": -4,
      "y": 0,
      "z": -11,
      "name": "Soil_Dirt_Cold"
    },
    {
      "x": -4,
      "y": 1,
      "z": -11,
      "name": "Empty"
    },
    {
      "x": -4,
      "y": 2,
      "z": -11,
      "name": "Empty"
    },
    {
      "x": -4,
      "y": 3,
      "z": -11,
      "name": "Empty"
    },
    {
      "x": -4,
      "y": 4,
      "z": -11,
      "name": "Rock_Basalt_Brick"
    },
    {
      "x": -4,
      "y": 5,
      "z": -11,
      "name": "Rock_Basalt"
    },
    {
      "x": -4,
      "y": 0,
      "z": -10,
      "name": "Rock_Shale_Brick_Smooth"
    },
    {
      "x": -4,
      "y": 1,
      "z": -10,
      "name": "Empty"
    },
    {
      "x": -4,
      "y": 2,
      "z": -10,
      "name": "Empty"
    },
    {
      "x": -4,
      "y": 3,
      "z": -10,
      "name": "Empty"
    },
    {
      "x": -4,
      "y": 4,
      "z": -10,
      "name": "Rock_Basalt_Brick"
    },
    {
      "x": -4,
      "y": 5,
      "z": -10,
      "name": "Rock_Basalt"
    },
    {
      "x": -4,
      "y": 0,
      "z": -9,
      "name": "Rock_Shale_Brick_Smooth"
    },
    {
      "x": -4,
      "y": 1,
      "z": -9,
      "name": "Empty"
    },
    {
      "x": -4,
      "y": 2,
      "z": -9,
      "name": "Empty"
    },
    {
      "x": -4,
      "y": 3,
      "z": -9,
      "name": "Empty"
    },
    {
      "x": -4,
      "y": 4,
      "z": -9,
      "name": "Rock_Basalt_Brick"
    },
    {
      "x": -4,
      "y": 5,
      "z": -9,
      "name": "Rock_Basalt"
    },
    {
      "x": -4,
      "y": 0,
      "z": -8,
      "name": "Rock_Shale_Brick_Smooth"
    },
    {
      "x": -4,
      "y": 1,
      "z": -8,
      "name": "Empty"
    },
    {
      "x": -4,
      "y": 2,
      "z": -8,
      "name": "Empty"
    },
    {
      "x": -4,
      "y": 3,
      "z": -8,
      "name": "Rock_Basalt_Brick_Half",
      "rotation": 8
    },
    {
      "x": -4,
      "y": 4,
      "z": -8,
      "name": "Rock_Basalt_Brick"
    },
    {
      "x": -4,
      "y": 5,
      "z": -8,
      "name": "Rock_Basalt"
    },
    {
      "x": -4,
      "y": 0,
      "z": -7,
      "name": "Rock_Shale_Brick_Smooth"
    },
    {
      "x": -4,
      "y": 1,
      "z": -7,
      "name": "Empty"
    },
    {
      "x": -4,
      "y": 2,
      "z": -7,
      "name": "Empty"
    },
    {
      "x": -4,
      "y": 3,
      "z": -7,
      "name": "Rock_Basalt_Brick"
    },
    {
      "x": -4,
      "y": 4,
      "z": -7,
      "name": "Rock_Basalt_Brick"
    },
    {
      "x": -4,
      "y": 5,
      "z": -7,
      "name": "Rock_Basalt"
    },
    {
      "x": -4,
      "y": 0,
      "z": -6,
      "name": "Rock_Shale_Brick_Smooth"
    },
    {
      "x": -4,
      "y": 1,
      "z": -6,
      "name": "Rock_Basalt_Brick"
    },
    {
      "x": -4,
      "y": 2,
      "z": -6,
      "name": "Rock_Basalt_Brick"
    },
    {
      "x": -4,
      "y": 3,
      "z": -6,
      "name": "Rock_Basalt_Brick"
    },
    {
      "x": -4,
      "y": 4,
      "z": -6,
      "name": "Rock_Basalt_Brick"
    },
    {
      "x": -4,
      "y": 5,
      "z": -6,
      "name": "Rock_Basalt"
    },
    {
      "x": -4,
      "y": 0,
      "z": -5,
      "name": "Rock_Shale_Brick_Smooth"
    },
    {
      "x": -4,
      "y": 1,
      "z": -5,
      "name": "Rock_Basalt_Brick"
    },
    {
      "x": -4,
      "y": 2,
      "z": -5,
      "name": "Rock_Basalt_Brick"
    },
    {
      "x": -4,
      "y": 3,
      "z": -5,
      "name": "Rock_Basalt_Brick"
    },
    {
      "x": -4,
      "y": 4,
      "z": -5,
      "name": "Rock_Basalt_Brick"
    },
    {
      "x": -4,
      "y": 5,
      "z": -5,
      "name": "Rock_Basalt"
    },
    {
      "x": -4,
      "y": 0,
      "z": -4,
      "name": "Rock_Shale_Brick_Smooth"
    },
    {
      "x": -4,
      "y": 1,
      "z": -4,
      "name": "Rock_Shale_Brick_Pillar_Base"
    },
    {
      "x": -4,
      "y": 2,
      "z": -4,
      "name": "Rock_Shale_Brick_Pillar_Middle"
    },
    {
      "x": -4,
      "y": 3,
      "z": -4,
      "name": "Rock_Shale_Brick_Pillar_Base",
      "rotation": 8
    },
    {
      "x": -4,
      "y": 4,
      "z": -4,
      "name": "Rock_Shale_Brick"
    },
    {
      "x": -4,
      "y": 5,
      "z": -4,
      "name": "Rock_Basalt"
    },
    {
      "x": -4,
      "y": 0,
      "z": -3,
      "name": "Rock_Shale_Brick_Smooth"
    },
    {
      "x": -4,
      "y": 1,
      "z": -3,
      "name": "Rock_Shale_Brick_Stairs",
      "rotation": 11
    },
    {
      "x": -4,
      "y": 2,
      "z": -3,
      "name": "Deco_Bone_Pile"
    },
    {
      "x": -4,
      "y": 3,
      "z": -3,
      "name": "Empty"
    },
    {
      "x": -4,
      "y": 4,
      "z": -3,
      "name": "Rock_Shale_Brick"
    },
    {
      "x": -4,
      "y": 5,
      "z": -3,
      "name": "Rock_Basalt"
    },
    {
      "x": -4,
      "y": 0,
      "z": -2,
      "name": "Rock_Shale_Brick_Smooth"
    },
    {
      "x": -4,
      "y": 1,
      "z": -2,
      "name": "Rock_Shale_Brick_Stairs",
      "rotation": 11
    },
    {
      "x": -4,
      "y": 2,
      "z": -2,
      "name": "Deco_Bone_Pile"
    },
    {
      "x": -4,
      "y": 3,
      "z": -2,
      "name": "Empty"
    },
    {
      "x": -4,
      "y": 4,
      "z": -2,
      "name": "Rock_Shale_Brick"
    },
    {
      "x": -4,
      "y": 5,
      "z": -2,
      "name": "Rock_Basalt"
    },
    {
      "x": -4,
      "y": 0,
      "z": -1,
      "name": "Rock_Shale_Brick_Smooth"
    },
    {
      "x": -4,
      "y": 1,
      "z": -1,
      "name": "Rock_Shale_Brick_Stairs",
      "rotation": 11
    },
    {
      "x": -4,
      "y": 2,
      "z": -1,
      "name": "Deco_Bone_Skulls"
    },
    {
      "x": -4,
      "y": 3,
      "z": -1,
      "name": "Empty"
    },
    {
      "x": -4,
      "y": 4,
      "z": -1,
      "name": "Rock_Shale_Brick"
    },
    {
      "x": -4,
      "y": 5,
      "z": -1,
      "name": "Rock_Basalt"
    },
    {
      "x": -4,
      "y": 0,
      "z": 0,
      "name": "Rock_Shale_Brick_Smooth"
    },
    {
      "x": -4,
      "y": 1,
      "z": 0,
      "name": "Rock_Shale_Brick_Pillar_Base"
    },
    {
      "x": -4,
      "y": 2,
      "z": 0,
      "name": "Rock_Shale_Brick_Pillar_Middle"
    },
    {
      "x": -4,
      "y": 3,
      "z": 0,
      "name": "Rock_Shale_Brick_Pillar_Base",
      "rotation": 8
    },
    {
      "x": -4,
      "y": 4,
      "z": 0,
      "name": "Rock_Shale_Brick"
    },
    {
      "x": -4,
      "y": 5,
      "z": 0,
      "name": "Rock_Basalt"
    },
    {
      "x": -3,
      "y": 0,
      "z": -15,
      "name": "Rock_Shale_Brick_Smooth"
    },
    {
      "x": -3,
      "y": 1,
      "z": -15,
      "name": "Rock_Shale_Brick"
    },
    {
      "x": -3,
      "y": 2,
      "z": -15,
      "name": "Rock_Shale_Brick"
    },
    {
      "x": -3,
      "y": 3,
      "z": -15,
      "name": "Rock_Shale_Brick"
    },
    {
      "x": -3,
      "y": 4,
      "z": -15,
      "name": "Rock_Shale_Brick"
    },
    {
      "x": -3,
      "y": 5,
      "z": -15,
      "name": "Rock_Basalt"
    },
    {
      "x": -3,
      "y": 0,
      "z": -14,
      "name": "Rock_Shale_Brick_Smooth"
    },
    {
      "x": -3,
      "y": 1,
      "z": -14,
      "name": "Furniture_Ancient_Barrel"
    },
    {
      "x": -3,
      "y": 2,
      "z": -14,
      "name": "Empty"
    },
    {
      "x": -3,
      "y": 3,
      "z": -14,
      "name": "Rock_Basalt_Brick"
    },
    {
      "x": -3,
      "y": 4,
      "z": -14,
      "name": "Rock_Basalt_Brick"
    },
    {
      "x": -3,
      "y": 5,
      "z": -14,
      "name": "Rock_Basalt"
    },
    {
      "x": -3,
      "y": 0,
      "z": -13,
      "name": "Rock_Shale"
    },
    {
      "x": -3,
      "y": 1,
      "z": -13,
      "name": "Plant_Crop_Mushroom_Glowing_Red"
    },
    {
      "x": -3,
      "y": 2,
      "z": -13,
      "name": "Empty"
    },
    {
      "x": -3,
      "y": 3,
      "z": -13,
      "name": "Empty"
    },
    {
      "x": -3,
      "y": 4,
      "z": -13,
      "name": "Empty"
    },
    {
      "x": -3,
      "y": 5,
      "z": -13,
      "name": "Rock_Basalt"
    },
    {
      "x": -3,
      "y": 0,
      "z": -12,
      "name": "Soil_Dirt_Cold"
    },
    {
      "x": -3,
      "y": 1,
      "z": -12,
      "name": "Empty"
    },
    {
      "x": -3,
      "y": 2,
      "z": -12,
      "name": "Empty"
    },
    {
      "x": -3,
      "y": 3,
      "z": -12,
      "name": "Empty"
    },
    {
      "x": -3,
      "y": 4,
      "z": -12,
      "name": "Empty"
    },
    {
      "x": -3,
      "y": 5,
      "z": -12,
      "name": "Rock_Basalt"
    },
    {
      "x": -3,
      "y": 0,
      "z": -11,
      "name": "Soil_Dirt_Cold"
    },
    {
      "x": -3,
      "y": 1,
      "z": -11,
      "name": "Empty"
    },
    {
      "x": -3,
      "y": 2,
      "z": -11,
      "name": "Empty"
    },
    {
      "x": -3,
      "y": 3,
      "z": -11,
      "name": "Empty"
    },
    {
      "x": -3,
      "y": 4,
      "z": -11,
      "name": "Empty"
    },
    {
      "x": -3,
      "y": 5,
      "z": -11,
      "name": "Rock_Basalt"
    },
    {
      "x": -3,
      "y": 0,
      "z": -10,
      "name": "Rock_Basalt"
    },
    {
      "x": -3,
      "y": 1,
      "z": -10,
      "name": "Empty"
    },
    {
      "x": -3,
      "y": 2,
      "z": -10,
      "name": "Empty"
    },
    {
      "x": -3,
      "y": 3,
      "z": -10,
      "name": "Empty"
    },
    {
      "x": -3,
      "y": 4,
      "z": -10,
      "name": "Empty"
    },
    {
      "x": -3,
      "y": 5,
      "z": -10,
      "name": "Rock_Basalt"
    },
    {
      "x": -3,
      "y": 0,
      "z": -9,
      "name": "Rock_Shale"
    },
    {
      "x": -3,
      "y": 1,
      "z": -9,
      "name": "Empty"
    },
    {
      "x": -3,
      "y": 2,
      "z": -9,
      "name": "Empty"
    },
    {
      "x": -3,
      "y": 3,
      "z": -9,
      "name": "Empty"
    },
    {
      "x": -3,
      "y": 4,
      "z": -9,
      "name": "Empty"
    },
    {
      "x": -3,
      "y": 5,
      "z": -9,
      "name": "Rock_Basalt"
    },
    {
      "x": -3,
      "y": 0,
      "z": -8,
      "name": "Rock_Shale"
    },
    {
      "x": -3,
      "y": 1,
      "z": -8,
      "name": "Empty"
    },
    {
      "x": -3,
      "y": 2,
      "z": -8,
      "name": "Empty"
    },
    {
      "x": -3,
      "y": 3,
      "z": -8,
      "name": "Empty"
    },
    {
      "x": -3,
      "y": 4,
      "z": -8,
      "name": "Empty"
    },
    {
      "x": -3,
      "y": 5,
      "z": -8,
      "name": "Rock_Basalt"
    },
    {
      "x": -3,
      "y": 0,
      "z": -7,
      "name": "Rock_Basalt"
    },
    {
      "x": -3,
      "y": 1,
      "z": -7,
      "name": "Rock_Basalt"
    },
    {
      "x": -3,
      "y": 2,
      "z": -7,
      "name": "Rock_Basalt"
    },
    {
      "x": -3,
      "y": 3,
      "z": -7,
      "name": "Empty"
    },
    {
      "x": -3,
      "y": 4,
      "z": -7,
      "name": "Empty"
    },
    {
      "x": -3,
      "y": 5,
      "z": -7,
      "name": "Rock_Basalt"
    },
    {
      "x": -3,
      "y": 0,
      "z": -6,
      "name": "Rock_Basalt"
    },
    {
      "x": -3,
      "y": 1,
      "z": -6,
      "name": "Rock_Basalt"
    },
    {
      "x": -3,
      "y": 2,
      "z": -6,
      "name": "Rock_Basalt"
    },
    {
      "x": -3,
      "y": 3,
      "z": -6,
      "name": "Rock_Basalt_Brick"
    },
    {
      "x": -3,
      "y": 4,
      "z": -6,
      "name": "Rock_Basalt_Brick"
    },
    {
      "x": -3,
      "y": 5,
      "z": -6,
      "name": "Rock_Basalt"
    },
    {
      "x": -3,
      "y": 0,
      "z": -5,
      "name": "Soil_Dirt_Cold"
    },
    {
      "x": -3,
      "y": 1,
      "z": -5,
      "name": "Empty"
    },
    {
      "x": -3,
      "y": 2,
      "z": -5,
      "name": "Empty"
    },
    {
      "x": -3,
      "y": 3,
      "z": -5,
      "name": "Rock_Basalt_Brick"
    },
    {
      "x": -3,
      "y": 4,
      "z": -5,
      "name": "Rock_Basalt_Brick"
    },
    {
      "x": -3,
      "y": 5,
      "z": -5,
      "name": "Rock_Basalt"
    },
    {
      "x": -3,
      "y": 0,
      "z": -4,
      "name": "Soil_Dirt_Cold"
    },
    {
      "x": -3,
      "y": 1,
      "z": -4,
      "name": "Empty"
    },
    {
      "x": -3,
      "y": 2,
      "z": -4,
      "name": "Empty"
    },
    {
      "x": -3,
      "y": 3,
      "z": -4,
      "name": "Empty"
    },
    {
      "x": -3,
      "y": 4,
      "z": -4,
      "name": "Rock_Shale_Brick_Stairs",
      "rotation": 11
    },
    {
      "x": -3,
      "y": 5,
      "z": -4,
      "name": "Rock_Basalt"
    },
    {
      "x": -3,
      "y": 0,
      "z": -3,
      "name": "Soil_Dirt_Cold"
    },
    {
      "x": -3,
      "y": 1,
      "z": -3,
      "name": "*Plant_Crop_Berry_Winter_Block_State_Definitions_StageFinal"
    },
    {
      "x": -3,
      "y": 2,
      "z": -3,
      "name": "Empty"
    },
    {
      "x": -3,
      "y": 3,
      "z": -3,
      "name": "Empty"
    },
    {
      "x": -3,
      "y": 4,
      "z": -3,
      "name": "Empty"
    },
    {
      "x": -3,
      "y": 5,
      "z": -3,
      "name": "Rock_Basalt"
    },
    {
      "x": -3,
      "y": 0,
      "z": -2,
      "name": "Soil_Dirt_Cold"
    },
    {
      "x": -3,
      "y": 1,
      "z": -2,
      "name": "Empty"
    },
    {
      "x": -3,
      "y": 2,
      "z": -2,
      "name": "Empty"
    },
    {
      "x": -3,
      "y": 3,
      "z": -2,
      "name": "Empty"
    },
    {
      "x": -3,
      "y": 4,
      "z": -2,
      "name": "Empty"
    },
    {
      "x": -3,
      "y": 5,
      "z": -2,
      "name": "Rock_Basalt"
    },
    {
      "x": -3,
      "y": 0,
      "z": -1,
      "name": "Rock_Basalt"
    },
    {
      "x": -3,
      "y": 1,
      "z": -1,
      "name": "Empty"
    },
    {
      "x": -3,
      "y": 2,
      "z": -1,
      "name": "Empty"
    },
    {
      "x": -3,
      "y": 3,
      "z": -1,
      "name": "Empty"
    },
    {
      "x": -3,
      "y": 4,
      "z": -1,
      "name": "Plant_Bush_Dead_Hanging"
    },
    {
      "x": -3,
      "y": 5,
      "z": -1,
      "name": "Rock_Basalt"
    },
    {
      "x": -3,
      "y": 0,
      "z": 0,
      "name": "Rock_Shale_Brick_Smooth"
    },
    {
      "x": -3,
      "y": 1,
      "z": 0,
      "name": "Empty"
    },
    {
      "x": -3,
      "y": 2,
      "z": 0,
      "name": "Empty"
    },
    {
      "x": -3,
      "y": 3,
      "z": 0,
      "name": "Empty"
    },
    {
      "x": -3,
      "y": 4,
      "z": 0,
      "name": "Rock_Shale_Brick_Stairs",
      "rotation": 11
    },
    {
      "x": -3,
      "y": 5,
      "z": 0,
      "name": "Rock_Basalt"
    },
    {
      "x": -2,
      "y": 0,
      "z": -15,
      "name": "Rock_Shale_Brick_Smooth"
    },
    {
      "x": -2,
      "y": 1,
      "z": -15,
      "name": "Rock_Shale_Brick"
    },
    {
      "x": -2,
      "y": 2,
      "z": -15,
      "name": "Rock_Shale_Brick"
    },
    {
      "x": -2,
      "y": 3,
      "z": -15,
      "name": "Rock_Shale_Brick"
    },
    {
      "x": -2,
      "y": 4,
      "z": -15,
      "name": "Rock_Shale_Brick"
    },
    {
      "x": -2,
      "y": 5,
      "z": -15,
      "name": "Rock_Basalt"
    },
    {
      "x": -2,
      "y": 0,
      "z": -14,
      "name": "Rock_Shale_Brick_Smooth"
    },
    {
      "x": -2,
      "y": 1,
      "z": -14,
      "name": "Furniture_Ancient_Barrel"
    },
    {
      "x": -2,
      "y": 2,
      "z": -14,
      "name": "Furniture_Ancient_Barrel"
    },
    {
      "x": -2,
      "y": 3,
      "z": -14,
      "name": "Rock_Basalt_Brick_Half",
      "rotation": 8
    },
    {
      "x": -2,
      "y": 4,
      "z": -14,
      "name": "Rock_Basalt_Brick"
    },
    {
      "x": -2,
      "y": 5,
      "z": -14,
      "name": "Rock_Basalt"
    },
    {
      "x": -2,
      "y": 0,
      "z": -13,
      "name": "Rock_Shale"
    },
    {
      "x": -2,
      "y": 1,
      "z": -13,
      "name": "Furniture_Ancient_Barrel"
    },
    {
      "x": -2,
      "y": 2,
      "z": -13,
      "name": "Empty"
    },
    {
      "x": -2,
      "y": 3,
      "z": -13,
      "name": "Empty"
    },
    {
      "x": -2,
      "y": 4,
      "z": -13,
      "name": "Empty"
    },
    {
      "x": -2,
      "y": 5,
      "z": -13,
      "name": "Rock_Basalt"
    },
    {
      "x": -2,
      "y": 0,
      "z": -12,
      "name": "Rock_Basalt_Brick_Stairs",
      "rotation": 1
    },
    {
      "x": -2,
      "y": 1,
      "z": -12,
      "name": "Empty"
    },
    {
      "x": -2,
      "y": 2,
      "z": -12,
      "name": "Empty"
    },
    {
      "x": -2,
      "y": 3,
      "z": -12,
      "name": "Empty"
    },
    {
      "x": -2,
      "y": 4,
      "z": -12,
      "name": "Empty"
    },
    {
      "x": -2,
      "y": 5,
      "z": -12,
      "name": "Rock_Basalt"
    },
    {
      "x": -2,
      "y": 0,
      "z": -11,
      "name": "Rock_Basalt_Brick_Stairs",
      "rotation": 1
    },
    {
      "x": -2,
      "y": 1,
      "z": -11,
      "name": "Empty"
    },
    {
      "x": -2,
      "y": 2,
      "z": -11,
      "name": "Empty"
    },
    {
      "x": -2,
      "y": 3,
      "z": -11,
      "name": "Empty"
    },
    {
      "x": -2,
      "y": 4,
      "z": -11,
      "name": "Empty"
    },
    {
      "x": -2,
      "y": 5,
      "z": -11,
      "name": "Rock_Basalt"
    },
    {
      "x": -2,
      "y": 0,
      "z": -10,
      "name": "Rock_Basalt"
    },
    {
      "x": -2,
      "y": 1,
      "z": -10,
      "name": "Empty"
    },
    {
      "x": -2,
      "y": 2,
      "z": -10,
      "name": "Empty"
    },
    {
      "x": -2,
      "y": 3,
      "z": -10,
      "name": "Empty"
    },
    {
      "x": -2,
      "y": 4,
      "z": -10,
      "name": "Empty"
    },
    {
      "x": -2,
      "y": 5,
      "z": -10,
      "name": "Rock_Basalt"
    },
    {
      "x": -2,
      "y": 0,
      "z": -9,
      "name": "Rock_Shale"
    },
    {
      "x": -2,
      "y": 1,
      "z": -9,
      "name": "Empty"
    },
    {
      "x": -2,
      "y": 2,
      "z": -9,
      "name": "Empty"
    },
    {
      "x": -2,
      "y": 3,
      "z": -9,
      "name": "Empty"
    },
    {
      "x": -2,
      "y": 4,
      "z": -9,
      "name": "Empty"
    },
    {
      "x": -2,
      "y": 5,
      "z": -9,
      "name": "Rock_Basalt"
    },
    {
      "x": -2,
      "y": 0,
      "z": -8,
      "name": "Rock_Shale"
    },
    {
      "x": -2,
      "y": 1,
      "z": -8,
      "name": "Rubble_Basalt"
    },
    {
      "x": -2,
      "y": 2,
      "z": -8,
      "name": "Empty"
    },
    {
      "x": -2,
      "y": 3,
      "z": -8,
      "name": "Empty"
    },
    {
      "x": -2,
      "y": 4,
      "z": -8,
      "name": "Empty"
    },
    {
      "x": -2,
      "y": 5,
      "z": -8,
      "name": "Rock_Basalt"
    },
    {
      "x": -2,
      "y": 0,
      "z": -7,
      "name": "Rock_Shale"
    },
    {
      "x": -2,
      "y": 1,
      "z": -7,
      "name": "Empty"
    },
    {
      "x": -2,
      "y": 2,
      "z": -7,
      "name": "Empty"
    },
    {
      "x": -2,
      "y": 3,
      "z": -7,
      "name": "Empty"
    },
    {
      "x": -2,
      "y": 4,
      "z": -7,
      "name": "Empty"
    },
    {
      "x": -2,
      "y": 5,
      "z": -7,
      "name": "Rock_Basalt"
    },
    {
      "x": -2,
      "y": 0,
      "z": -6,
      "name": "Rock_Basalt"
    },
    {
      "x": -2,
      "y": 1,
      "z": -6,
      "name": "Rock_Basalt"
    },
    {
      "x": -2,
      "y": 2,
      "z": -6,
      "name": "Empty"
    },
    {
      "x": -2,
      "y": 3,
      "z": -6,
      "name": "Rock_Basalt_Brick_Half",
      "rotation": 8
    },
    {
      "x": -2,
      "y": 4,
      "z": -6,
      "name": "Rock_Basalt_Brick"
    },
    {
      "x": -2,
      "y": 5,
      "z": -6,
      "name": "Rock_Basalt"
    },
    {
      "x": -2,
      "y": 0,
      "z": -5,
      "name": "Soil_Dirt_Cold"
    },
    {
      "x": -2,
      "y": 1,
      "z": -5,
      "name": "Plant_Bush_Dead_Twisted"
    },
    {
      "x": -2,
      "y": 2,
      "z": -5,
      "name": "Empty"
    },
    {
      "x": -2,
      "y": 3,
      "z": -5,
      "name": "Rock_Basalt_Brick_Half",
      "rotation": 8
    },
    {
      "x": -2,
      "y": 4,
      "z": -5,
      "name": "Rock_Basalt_Brick"
    },
    {
      "x": -2,
      "y": 5,
      "z": -5,
      "name": "Rock_Basalt"
    },
    {
      "x": -2,
      "y": 0,
      "z": -4,
      "name": "Soil_Dirt_Cold"
    },
    {
      "x": -2,
      "y": 1,
      "z": -4,
      "name": "Empty"
    },
    {
      "x": -2,
      "y": 2,
      "z": -4,
      "name": "Empty"
    },
    {
      "x": -2,
      "y": 3,
      "z": -4,
      "name": "Empty"
    },
    {
      "x": -2,
      "y": 4,
      "z": -4,
      "name": "Plant_Bush_Dead_Hanging"
    },
    {
      "x": -2,
      "y": 5,
      "z": -4,
      "name": "Rock_Basalt"
    },
    {
      "x": -2,
      "y": 0,
      "z": -3,
      "name": "Soil_Dirt_Cold"
    },
    {
      "x": -2,
      "y": 1,
      "z": -3,
      "name": "Empty"
    },
    {
      "x": -2,
      "y": 2,
      "z": -3,
      "name": "Empty"
    },
    {
      "x": -2,
      "y": 3,
      "z": -3,
      "name": "Empty"
    },
    {
      "x": -2,
      "y": 4,
      "z": -3,
      "name": "Empty"
    },
    {
      "x": -2,
      "y": 5,
      "z": -3,
      "name": "Rock_Basalt"
    },
    {
      "x": -2,
      "y": 0,
      "z": -2,
      "name": "Rock_Basalt"
    },
    {
      "x": -2,
      "y": 1,
      "z": -2,
      "name": "Empty"
    },
    {
      "x": -2,
      "y": 2,
      "z": -2,
      "name": "Empty"
    },
    {
      "x": -2,
      "y": 3,
      "z": -2,
      "name": "Empty"
    },
    {
      "x": -2,
      "y": 4,
      "z": -2,
      "name": "Empty"
    },
    {
      "x": -2,
      "y": 5,
      "z": -2,
      "name": "Rock_Basalt"
    },
    {
      "x": -2,
      "y": 0,
      "z": -1,
      "name": "Rock_Basalt"
    },
    {
      "x": -2,
      "y": 1,
      "z": -1,
      "name": "Empty"
    },
    {
      "x": -2,
      "y": 2,
      "z": -1,
      "name": "Empty"
    },
    {
      "x": -2,
      "y": 3,
      "z": -1,
      "name": "Empty"
    },
    {
      "x": -2,
      "y": 4,
      "z": -1,
      "name": "Empty"
    },
    {
      "x": -2,
      "y": 5,
      "z": -1,
      "name": "Rock_Basalt"
    },
    {
      "x": -2,
      "y": 0,
      "z": 0,
      "name": "Rock_Shale_Brick_Smooth"
    },
    {
      "x": -2,
      "y": 1,
      "z": 0,
      "name": "Empty"
    },
    {
      "x": -2,
      "y": 2,
      "z": 0,
      "name": "Empty"
    },
    {
      "x": -2,
      "y": 3,
      "z": 0,
      "name": "Empty"
    },
    {
      "x": -2,
      "y": 4,
      "z": 0,
      "name": "Empty"
    },
    {
      "x": -2,
      "y": 5,
      "z": 0,
      "name": "Rock_Basalt"
    },
    {
      "x": -1,
      "y": 0,
      "z": -15,
      "name": "Rock_Shale_Brick_Smooth"
    },
    {
      "x": -1,
      "y": 1,
      "z": -15,
      "name": "Rock_Shale"
    },
    {
      "x": -1,
      "y": 2,
      "z": -15,
      "name": "Rock_Shale"
    },
    {
      "x": -1,
      "y": 3,
      "z": -15,
      "name": "Rock_Shale"
    },
    {
      "x": -1,
      "y": 4,
      "z": -15,
      "name": "Rock_Shale"
    },
    {
      "x": -1,
      "y": 5,
      "z": -15,
      "name": "Rock_Basalt"
    },
    {
      "x": -1,
      "y": 0,
      "z": -14,
      "name": "Rock_Shale_Brick_Smooth"
    },
    {
      "x": -1,
      "y": 1,
      "z": -14,
      "name": "Empty"
    },
    {
      "x": -1,
      "y": 2,
      "z": -14,
      "name": "Empty"
    },
    {
      "x": -1,
      "y": 3,
      "z": -14,
      "name": "Empty"
    },
    {
      "x": -1,
      "y": 4,
      "z": -14,
      "name": "Rock_Basalt_Brick"
    },
    {
      "x": -1,
      "y": 5,
      "z": -14,
      "name": "Rock_Basalt"
    },
    {
      "x": -1,
      "y": 0,
      "z": -13,
      "name": "Rock_Shale"
    },
    {
      "x": -1,
      "y": 1,
      "z": -13,
      "name": "Empty"
    },
    {
      "x": -1,
      "y": 2,
      "z": -13,
      "name": "Empty"
    },
    {
      "x": -1,
      "y": 3,
      "z": -13,
      "name": "Empty"
    },
    {
      "x": -1,
      "y": 4,
      "z": -13,
      "name": "Plant_Bush_Dead_Hanging"
    },
    {
      "x": -1,
      "y": 5,
      "z": -13,
      "name": "Rock_Basalt"
    },
    {
      "x": -1,
      "y": 0,
      "z": -12,
      "name": "Rock_Basalt_Brick_Half"
    },
    {
      "x": -1,
      "y": 1,
      "z": -12,
      "name": "Empty"
    },
    {
      "x": -1,
      "y": 2,
      "z": -12,
      "name": "Empty"
    },
    {
      "x": -1,
      "y": 3,
      "z": -12,
      "name": "Empty"
    },
    {
      "x": -1,
      "y": 4,
      "z": -12,
      "name": "Empty"
    },
    {
      "x": -1,
      "y": 5,
      "z": -12,
      "name": "Rock_Basalt"
    },
    {
      "x": -1,
      "y": 0,
      "z": -11,
      "name": "Rock_Basalt_Brick_Half"
    },
    {
      "x": -1,
      "y": 1,
      "z": -11,
      "name": "Empty"
    },
    {
      "x": -1,
      "y": 2,
      "z": -11,
      "name": "Empty"
    },
    {
      "x": -1,
      "y": 3,
      "z": -11,
      "name": "Empty"
    },
    {
      "x": -1,
      "y": 4,
      "z": -11,
      "name": "Empty"
    },
    {
      "x": -1,
      "y": 5,
      "z": -11,
      "name": "Rock_Basalt"
    },
    {
      "x": -1,
      "y": 0,
      "z": -10,
      "name": "Rock_Basalt"
    },
    {
      "x": -1,
      "y": 1,
      "z": -10,
      "name": "Empty"
    },
    {
      "x": -1,
      "y": 2,
      "z": -10,
      "name": "Empty"
    },
    {
      "x": -1,
      "y": 3,
      "z": -10,
      "name": "Empty"
    },
    {
      "x": -1,
      "y": 4,
      "z": -10,
      "name": "Empty"
    },
    {
      "x": -1,
      "y": 5,
      "z": -10,
      "name": "Rock_Basalt"
    },
    {
      "x": -1,
      "y": 0,
      "z": -9,
      "name": "Rock_Shale"
    },
    {
      "x": -1,
      "y": 1,
      "z": -9,
      "name": "Empty"
    },
    {
      "x": -1,
      "y": 2,
      "z": -9,
      "name": "Empty"
    },
    {
      "x": -1,
      "y": 3,
      "z": -9,
      "name": "Empty"
    },
    {
      "x": -1,
      "y": 4,
      "z": -9,
      "name": "Empty"
    },
    {
      "x": -1,
      "y": 5,
      "z": -9,
      "name": "Rock_Basalt"
    },
    {
      "x": -1,
      "y": 0,
      "z": -8,
      "name": "Rock_Shale"
    },
    {
      "x": -1,
      "y": 1,
      "z": -8,
      "name": "Empty"
    },
    {
      "x": -1,
      "y": 2,
      "z": -8,
      "name": "Empty"
    },
    {
      "x": -1,
      "y": 3,
      "z": -8,
      "name": "Empty"
    },
    {
      "x": -1,
      "y": 4,
      "z": -8,
      "name": "Empty"
    },
    {
      "x": -1,
      "y": 5,
      "z": -8,
      "name": "Rock_Basalt"
    },
    {
      "x": -1,
      "y": 0,
      "z": -7,
      "name": "Rock_Shale"
    },
    {
      "x": -1,
      "y": 1,
      "z": -7,
      "name": "Empty"
    },
    {
      "x": -1,
      "y": 2,
      "z": -7,
      "name": "Empty"
    },
    {
      "x": -1,
      "y": 3,
      "z": -7,
      "name": "Empty"
    },
    {
      "x": -1,
      "y": 4,
      "z": -7,
      "name": "Empty"
    },
    {
      "x": -1,
      "y": 5,
      "z": -7,
      "name": "Rock_Basalt"
    },
    {
      "x": -1,
      "y": 0,
      "z": -6,
      "name": "Rock_Shale_Brick_Smooth"
    },
    {
      "x": -1,
      "y": 1,
      "z": -6,
      "name": "Wood_Redwood_Branch_Long"
    },
    {
      "x": -1,
      "y": 2,
      "z": -6,
      "name": "Wood_Redwood_Branch_Long"
    },
    {
      "x": -1,
      "y": 3,
      "z": -6,
      "name": "Wood_Redwood_Branch_Long"
    },
    {
      "x": -1,
      "y": 4,
      "z": -6,
      "name": "Rock_Basalt_Brick"
    },
    {
      "x": -1,
      "y": 5,
      "z": -6,
      "name": "Rock_Basalt"
    },
    {
      "x": -1,
      "y": 0,
      "z": -5,
      "name": "Rock_Shale"
    },
    {
      "x": -1,
      "y": 1,
      "z": -5,
      "name": "Empty"
    },
    {
      "x": -1,
      "y": 2,
      "z": -5,
      "name": "Empty"
    },
    {
      "x": -1,
      "y": 3,
      "z": -5,
      "name": "Empty"
    },
    {
      "x": -1,
      "y": 4,
      "z": -5,
      "name": "Rock_Basalt_Brick"
    },
    {
      "x": -1,
      "y": 5,
      "z": -5,
      "name": "Rock_Basalt"
    },
    {
      "x": -1,
      "y": 0,
      "z": -4,
      "name": "Rock_Shale"
    },
    {
      "x": -1,
      "y": 1,
      "z": -4,
      "name": "Empty"
    },
    {
      "x": -1,
      "y": 2,
      "z": -4,
      "name": "Empty"
    },
    {
      "x": -1,
      "y": 3,
      "z": -4,
      "name": "Empty"
    },
    {
      "x": -1,
      "y": 4,
      "z": -4,
      "name": "Empty"
    },
    {
      "x": -1,
      "y": 5,
      "z": -4,
      "name": "Rock_Basalt"
    },
    {
      "x": -1,
      "y": 0,
      "z": -3,
      "name": "Rock_Shale"
    },
    {
      "x": -1,
      "y": 1,
      "z": -3,
      "name": "Empty"
    },
    {
      "x": -1,
      "y": 2,
      "z": -3,
      "name": "Empty"
    },
    {
      "x": -1,
      "y": 3,
      "z": -3,
      "name": "Empty"
    },
    {
      "x": -1,
      "y": 4,
      "z": -3,
      "name": "Empty"
    },
    {
      "x": -1,
      "y": 5,
      "z": -3,
      "name": "Rock_Basalt"
    },
    {
      "x": -1,
      "y": 0,
      "z": -2,
      "name": "Rock_Shale"
    },
    {
      "x": -1,
      "y": 1,
      "z": -2,
      "name": "Empty"
    },
    {
      "x": -1,
      "y": 2,
      "z": -2,
      "name": "Empty"
    },
    {
      "x": -1,
      "y": 3,
      "z": -2,
      "name": "Empty"
    },
    {
      "x": -1,
      "y": 4,
      "z": -2,
      "name": "Empty"
    },
    {
      "x": -1,
      "y": 5,
      "z": -2,
      "name": "Rock_Basalt"
    },
    {
      "x": -1,
      "y": 0,
      "z": -1,
      "name": "Rock_Shale"
    },
    {
      "x": -1,
      "y": 1,
      "z": -1,
      "name": "Empty"
    },
    {
      "x": -1,
      "y": 2,
      "z": -1,
      "name": "Empty"
    },
    {
      "x": -1,
      "y": 3,
      "z": -1,
      "name": "Empty"
    },
    {
      "x": -1,
      "y": 4,
      "z": -1,
      "name": "Empty"
    },
    {
      "x": -1,
      "y": 5,
      "z": -1,
      "name": "Rock_Basalt"
    },
    {
      "x": -1,
      "y": 0,
      "z": 0,
      "name": "Rock_Shale_Brick_Smooth"
    },
    {
      "x": -1,
      "y": 1,
      "z": 0,
      "name": "Empty"
    },
    {
      "x": -1,
      "y": 2,
      "z": 0,
      "name": "Empty"
    },
    {
      "x": -1,
      "y": 3,
      "z": 0,
      "name": "Empty"
    },
    {
      "x": -1,
      "y": 4,
      "z": 0,
      "name": "Empty"
    },
    {
      "x": -1,
      "y": 5,
      "z": 0,
      "name": "Rock_Basalt"
    },
    {
      "x": 0,
      "y": 0,
      "z": -15,
      "name": "Rock_Shale_Brick_Smooth"
    },
    {
      "x": 0,
      "y": 1,
      "z": -15,
      "name": "Rock_Shale"
    },
    {
      "x": 0,
      "y": 2,
      "z": -15,
      "name": "Rock_Shale"
    },
    {
      "x": 0,
      "y": 3,
      "z": -15,
      "name": "Rock_Shale"
    },
    {
      "x": 0,
      "y": 4,
      "z": -15,
      "name": "Rock_Shale"
    },
    {
      "x": 0,
      "y": 5,
      "z": -15,
      "name": "Rock_Basalt"
    },
    {
      "x": 0,
      "y": 0,
      "z": -14,
      "name": "Rock_Shale_Brick_Smooth"
    },
    {
      "x": 0,
      "y": 1,
      "z": -14,
      "name": "Empty"
    },
    {
      "x": 0,
      "y": 2,
      "z": -14,
      "name": "Empty"
    },
    {
      "x": 0,
      "y": 3,
      "z": -14,
      "name": "Empty"
    },
    {
      "x": 0,
      "y": 4,
      "z": -14,
      "name": "Rock_Basalt_Brick"
    },
    {
      "x": 0,
      "y": 5,
      "z": -14,
      "name": "Rock_Basalt"
    },
    {
      "x": 0,
      "y": 0,
      "z": -13,
      "name": "Rock_Shale"
    },
    {
      "x": 0,
      "y": 1,
      "z": -13,
      "name": "Block_Spawner_Block",
      "components": {
        "Components": {
          "BlockSpawner": {
            "BlockSpawnerId": "Zone3_Encounters_Tier3"
          }
        }
      }
    },
    {
      "x": 0,
      "y": 2,
      "z": -13,
      "name": "Empty"
    },
    {
      "x": 0,
      "y": 3,
      "z": -13,
      "name": "Empty"
    },
    {
      "x": 0,
      "y": 4,
      "z": -13,
      "name": "Empty"
    },
    {
      "x": 0,
      "y": 5,
      "z": -13,
      "name": "Rock_Basalt"
    },
    {
      "x": 0,
      "y": 0,
      "z": -12,
      "name": "Rock_Basalt_Brick_Half"
    },
    {
      "x": 0,
      "y": 1,
      "z": -12,
      "name": "Empty"
    },
    {
      "x": 0,
      "y": 2,
      "z": -12,
      "name": "Empty"
    },
    {
      "x": 0,
      "y": 3,
      "z": -12,
      "name": "Empty"
    },
    {
      "x": 0,
      "y": 4,
      "z": -12,
      "name": "Empty"
    },
    {
      "x": 0,
      "y": 5,
      "z": -12,
      "name": "Rock_Basalt"
    },
    {
      "x": 0,
      "y": 0,
      "z": -11,
      "name": "Rock_Shale"
    },
    {
      "x": 0,
      "y": 1,
      "z": -11,
      "name": "Empty"
    },
    {
      "x": 0,
      "y": 2,
      "z": -11,
      "name": "Empty"
    },
    {
      "x": 0,
      "y": 3,
      "z": -11,
      "name": "Empty"
    },
    {
      "x": 0,
      "y": 4,
      "z": -11,
      "name": "Empty"
    },
    {
      "x": 0,
      "y": 5,
      "z": -11,
      "name": "Rock_Basalt"
    },
    {
      "x": 0,
      "y": 0,
      "z": -10,
      "name": "Rock_Shale"
    },
    {
      "x": 0,
      "y": 1,
      "z": -10,
      "name": "Empty"
    },
    {
      "x": 0,
      "y": 2,
      "z": -10,
      "name": "Empty"
    },
    {
      "x": 0,
      "y": 3,
      "z": -10,
      "name": "Empty"
    },
    {
      "x": 0,
      "y": 4,
      "z": -10,
      "name": "Empty"
    },
    {
      "x": 0,
      "y": 5,
      "z": -10,
      "name": "Rock_Basalt"
    },
    {
      "x": 0,
      "y": 0,
      "z": -9,
      "name": "Rock_Shale"
    },
    {
      "x": 0,
      "y": 1,
      "z": -9,
      "name": "Empty"
    },
    {
      "x": 0,
      "y": 2,
      "z": -9,
      "name": "Empty"
    },
    {
      "x": 0,
      "y": 3,
      "z": -9,
      "name": "Empty"
    },
    {
      "x": 0,
      "y": 4,
      "z": -9,
      "name": "Empty"
    },
    {
      "x": 0,
      "y": 5,
      "z": -9,
      "name": "Rock_Basalt"
    },
    {
      "x": 0,
      "y": 0,
      "z": -8,
      "name": "Rock_Shale"
    },
    {
      "x": 0,
      "y": 1,
      "z": -8,
      "name": "Empty"
    },
    {
      "x": 0,
      "y": 2,
      "z": -8,
      "name": "Empty"
    },
    {
      "x": 0,
      "y": 3,
      "z": -8,
      "name": "Empty"
    },
    {
      "x": 0,
      "y": 4,
      "z": -8,
      "name": "Empty"
    },
    {
      "x": 0,
      "y": 5,
      "z": -8,
      "name": "Rock_Basalt"
    },
    {
      "x": 0,
      "y": 0,
      "z": -7,
      "name": "Rock_Shale"
    },
    {
      "x": 0,
      "y": 1,
      "z": -7,
      "name": "Empty"
    },
    {
      "x": 0,
      "y": 2,
      "z": -7,
      "name": "Empty"
    },
    {
      "x": 0,
      "y": 3,
      "z": -7,
      "name": "Empty"
    },
    {
      "x": 0,
      "y": 4,
      "z": -7,
      "name": "Empty"
    },
    {
      "x": 0,
      "y": 5,
      "z": -7,
      "name": "Rock_Basalt"
    },
    {
      "x": 0,
      "y": 0,
      "z": -6,
      "name": "Rock_Shale_Brick_Smooth"
    },
    {
      "x": 0,
      "y": 1,
      "z": -6,
      "name": "Empty"
    },
    {
      "x": 0,
      "y": 2,
      "z": -6,
      "name": "Empty"
    },
    {
      "x": 0,
      "y": 3,
      "z": -6,
      "name": "Empty"
    },
    {
      "x": 0,
      "y": 4,
      "z": -6,
      "name": "Rock_Basalt_Brick"
    },
    {
      "x": 0,
      "y": 5,
      "z": -6,
      "name": "Rock_Basalt"
    },
    {
      "x": 0,
      "y": 0,
      "z": -5,
      "name": "Rock_Shale"
    },
    {
      "x": 0,
      "y": 1,
      "z": -5,
      "name": "Empty"
    },
    {
      "x": 0,
      "y": 2,
      "z": -5,
      "name": "Empty"
    },
    {
      "x": 0,
      "y": 3,
      "z": -5,
      "name": "Empty"
    },
    {
      "x": 0,
      "y": 4,
      "z": -5,
      "name": "Rock_Basalt_Brick"
    },
    {
      "x": 0,
      "y": 5,
      "z": -5,
      "name": "Rock_Basalt"
    },
    {
      "x": 0,
      "y": 0,
      "z": -4,
      "name": "Rock_Shale"
    },
    {
      "x": 0,
      "y": 1,
      "z": -4,
      "name": "Empty"
    },
    {
      "x": 0,
      "y": 2,
      "z": -4,
      "name": "Empty"
    },
    {
      "x": 0,
      "y": 3,
      "z": -4,
      "name": "Empty"
    },
    {
      "x": 0,
      "y": 4,
      "z": -4,
      "name": "Empty"
    },
    {
      "x": 0,
      "y": 5,
      "z": -4,
      "name": "Rock_Basalt"
    },
    {
      "x": 0,
      "y": 0,
      "z": -3,
      "name": "Rock_Shale"
    },
    {
      "x": 0,
      "y": 1,
      "z": -3,
      "name": "Empty"
    },
    {
      "x": 0,
      "y": 2,
      "z": -3,
      "name": "Empty"
    },
    {
      "x": 0,
      "y": 3,
      "z": -3,
      "name": "Empty"
    },
    {
      "x": 0,
      "y": 4,
      "z": -3,
      "name": "Empty"
    },
    {
      "x": 0,
      "y": 5,
      "z": -3,
      "name": "Rock_Basalt"
    },
    {
      "x": 0,
      "y": 0,
      "z": -2,
      "name": "Rock_Shale"
    },
    {
      "x": 0,
      "y": 1,
      "z": -2,
      "name": "Empty"
    },
    {
      "x": 0,
      "y": 2,
      "z": -2,
      "name": "Empty"
    },
    {
      "x": 0,
      "y": 3,
      "z": -2,
      "name": "Empty"
    },
    {
      "x": 0,
      "y": 4,
      "z": -2,
      "name": "Empty"
    },
    {
      "x": 0,
      "y": 5,
      "z": -2,
      "name": "Rock_Basalt"
    },
    {
      "x": 0,
      "y": 0,
      "z": -1,
      "name": "Rock_Shale"
    },
    {
      "x": 0,
      "y": 1,
      "z": -1,
      "name": "Empty"
    },
    {
      "x": 0,
      "y": 2,
      "z": -1,
      "name": "Empty"
    },
    {
      "x": 0,
      "y": 3,
      "z": -1,
      "name": "Empty"
    },
    {
      "x": 0,
      "y": 4,
      "z": -1,
      "name": "Empty"
    },
    {
      "x": 0,
      "y": 5,
      "z": -1,
      "name": "Rock_Basalt"
    },
    {
      "x": 0,
      "y": 0,
      "z": 0,
      "name": "Rock_Shale"
    },
    {
      "x": 0,
      "y": 1,
      "z": 0,
      "name": "Empty"
    },
    {
      "x": 0,
      "y": 2,
      "z": 0,
      "name": "Empty"
    },
    {
      "x": 0,
      "y": 3,
      "z": 0,
      "name": "Empty"
    },
    {
      "x": 0,
      "y": 4,
      "z": 0,
      "name": "Empty"
    },
    {
      "x": 0,
      "y": 5,
      "z": 0,
      "name": "Rock_Basalt"
    },
    {
      "x": 1,
      "y": 0,
      "z": -15,
      "name": "Rock_Shale_Brick_Smooth"
    },
    {
      "x": 1,
      "y": 1,
      "z": -15,
      "name": "Rock_Shale"
    },
    {
      "x": 1,
      "y": 2,
      "z": -15,
      "name": "Rock_Shale"
    },
    {
      "x": 1,
      "y": 3,
      "z": -15,
      "name": "Rock_Shale"
    },
    {
      "x": 1,
      "y": 4,
      "z": -15,
      "name": "Rock_Shale"
    },
    {
      "x": 1,
      "y": 5,
      "z": -15,
      "name": "Rock_Basalt"
    },
    {
      "x": 1,
      "y": 0,
      "z": -14,
      "name": "Rock_Shale_Brick_Smooth"
    },
    {
      "x": 1,
      "y": 1,
      "z": -14,
      "name": "Empty"
    },
    {
      "x": 1,
      "y": 2,
      "z": -14,
      "name": "Empty"
    },
    {
      "x": 1,
      "y": 3,
      "z": -14,
      "name": "Empty"
    },
    {
      "x": 1,
      "y": 4,
      "z": -14,
      "name": "Rock_Basalt_Brick"
    },
    {
      "x": 1,
      "y": 5,
      "z": -14,
      "name": "Rock_Basalt"
    },
    {
      "x": 1,
      "y": 0,
      "z": -13,
      "name": "Rock_Basalt"
    },
    {
      "x": 1,
      "y": 1,
      "z": -13,
      "name": "Empty"
    },
    {
      "x": 1,
      "y": 2,
      "z": -13,
      "name": "Empty"
    },
    {
      "x": 1,
      "y": 3,
      "z": -13,
      "name": "Empty"
    },
    {
      "x": 1,
      "y": 4,
      "z": -13,
      "name": "Empty"
    },
    {
      "x": 1,
      "y": 5,
      "z": -13,
      "name": "Rock_Basalt"
    },
    {
      "x": 1,
      "y": 0,
      "z": -12,
      "name": "Rock_Basalt_Brick_Stairs",
      "rotation": 3
    },
    {
      "x": 1,
      "y": 1,
      "z": -12,
      "name": "Empty"
    },
    {
      "x": 1,
      "y": 2,
      "z": -12,
      "name": "Empty"
    },
    {
      "x": 1,
      "y": 3,
      "z": -12,
      "name": "Empty"
    },
    {
      "x": 1,
      "y": 4,
      "z": -12,
      "name": "Empty"
    },
    {
      "x": 1,
      "y": 5,
      "z": -12,
      "name": "Rock_Basalt"
    },
    {
      "x": 1,
      "y": 0,
      "z": -11,
      "name": "Rock_Shale"
    },
    {
      "x": 1,
      "y": 1,
      "z": -11,
      "name": "Empty"
    },
    {
      "x": 1,
      "y": 2,
      "z": -11,
      "name": "Empty"
    },
    {
      "x": 1,
      "y": 3,
      "z": -11,
      "name": "Empty"
    },
    {
      "x": 1,
      "y": 4,
      "z": -11,
      "name": "Empty"
    },
    {
      "x": 1,
      "y": 5,
      "z": -11,
      "name": "Rock_Basalt"
    },
    {
      "x": 1,
      "y": 0,
      "z": -10,
      "name": "Rock_Shale"
    },
    {
      "x": 1,
      "y": 1,
      "z": -10,
      "name": "Empty"
    },
    {
      "x": 1,
      "y": 2,
      "z": -10,
      "name": "Empty"
    },
    {
      "x": 1,
      "y": 3,
      "z": -10,
      "name": "Empty"
    },
    {
      "x": 1,
      "y": 4,
      "z": -10,
      "name": "Empty"
    },
    {
      "x": 1,
      "y": 5,
      "z": -10,
      "name": "Rock_Basalt"
    },
    {
      "x": 1,
      "y": 0,
      "z": -9,
      "name": "Rock_Shale"
    },
    {
      "x": 1,
      "y": 1,
      "z": -9,
      "name": "Empty"
    },
    {
      "x": 1,
      "y": 2,
      "z": -9,
      "name": "Empty"
    },
    {
      "x": 1,
      "y": 3,
      "z": -9,
      "name": "Empty"
    },
    {
      "x": 1,
      "y": 4,
      "z": -9,
      "name": "Empty"
    },
    {
      "x": 1,
      "y": 5,
      "z": -9,
      "name": "Rock_Basalt"
    },
    {
      "x": 1,
      "y": 0,
      "z": -8,
      "name": "Rock_Shale"
    },
    {
      "x": 1,
      "y": 1,
      "z": -8,
      "name": "Empty"
    },
    {
      "x": 1,
      "y": 2,
      "z": -8,
      "name": "Empty"
    },
    {
      "x": 1,
      "y": 3,
      "z": -8,
      "name": "Empty"
    },
    {
      "x": 1,
      "y": 4,
      "z": -8,
      "name": "Empty"
    },
    {
      "x": 1,
      "y": 5,
      "z": -8,
      "name": "Rock_Basalt"
    },
    {
      "x": 1,
      "y": 0,
      "z": -7,
      "name": "Rock_Shale"
    },
    {
      "x": 1,
      "y": 1,
      "z": -7,
      "name": "Empty"
    },
    {
      "x": 1,
      "y": 2,
      "z": -7,
      "name": "Empty"
    },
    {
      "x": 1,
      "y": 3,
      "z": -7,
      "name": "Empty"
    },
    {
      "x": 1,
      "y": 4,
      "z": -7,
      "name": "Empty"
    },
    {
      "x": 1,
      "y": 5,
      "z": -7,
      "name": "Rock_Basalt"
    },
    {
      "x": 1,
      "y": 0,
      "z": -6,
      "name": "Rock_Shale_Brick_Smooth"
    },
    {
      "x": 1,
      "y": 1,
      "z": -6,
      "name": "Empty"
    },
    {
      "x": 1,
      "y": 2,
      "z": -6,
      "name": "Empty"
    },
    {
      "x": 1,
      "y": 3,
      "z": -6,
      "name": "Empty"
    },
    {
      "x": 1,
      "y": 4,
      "z": -6,
      "name": "Rock_Basalt_Brick"
    },
    {
      "x": 1,
      "y": 5,
      "z": -6,
      "name": "Rock_Basalt"
    },
    {
      "x": 1,
      "y": 0,
      "z": -5,
      "name": "Rock_Shale"
    },
    {
      "x": 1,
      "y": 1,
      "z": -5,
      "name": "Empty"
    },
    {
      "x": 1,
      "y": 2,
      "z": -5,
      "name": "Empty"
    },
    {
      "x": 1,
      "y": 3,
      "z": -5,
      "name": "Empty"
    },
    {
      "x": 1,
      "y": 4,
      "z": -5,
      "name": "Rock_Basalt_Brick"
    },
    {
      "x": 1,
      "y": 5,
      "z": -5,
      "name": "Rock_Basalt"
    },
    {
      "x": 1,
      "y": 0,
      "z": -4,
      "name": "Rock_Shale"
    },
    {
      "x": 1,
      "y": 1,
      "z": -4,
      "name": "Empty"
    },
    {
      "x": 1,
      "y": 2,
      "z": -4,
      "name": "Empty"
    },
    {
      "x": 1,
      "y": 3,
      "z": -4,
      "name": "Empty"
    },
    {
      "x": 1,
      "y": 4,
      "z": -4,
      "name": "Empty"
    },
    {
      "x": 1,
      "y": 5,
      "z": -4,
      "name": "Rock_Basalt"
    },
    {
      "x": 1,
      "y": 0,
      "z": -3,
      "name": "Rock_Shale"
    },
    {
      "x": 1,
      "y": 1,
      "z": -3,
      "name": "Empty"
    },
    {
      "x": 1,
      "y": 2,
      "z": -3,
      "name": "Empty"
    },
    {
      "x": 1,
      "y": 3,
      "z": -3,
      "name": "Empty"
    },
    {
      "x": 1,
      "y": 4,
      "z": -3,
      "name": "Empty"
    },
    {
      "x": 1,
      "y": 5,
      "z": -3,
      "name": "Rock_Basalt"
    },
    {
      "x": 1,
      "y": 0,
      "z": -2,
      "name": "Rock_Shale"
    },
    {
      "x": 1,
      "y": 1,
      "z": -2,
      "name": "Empty"
    },
    {
      "x": 1,
      "y": 2,
      "z": -2,
      "name": "Empty"
    },
    {
      "x": 1,
      "y": 3,
      "z": -2,
      "name": "Empty"
    },
    {
      "x": 1,
      "y": 4,
      "z": -2,
      "name": "Empty"
    },
    {
      "x": 1,
      "y": 5,
      "z": -2,
      "name": "Rock_Basalt"
    },
    {
      "x": 1,
      "y": 0,
      "z": -1,
      "name": "Rock_Shale"
    },
    {
      "x": 1,
      "y": 1,
      "z": -1,
      "name": "Empty"
    },
    {
      "x": 1,
      "y": 2,
      "z": -1,
      "name": "Empty"
    },
    {
      "x": 1,
      "y": 3,
      "z": -1,
      "name": "Empty"
    },
    {
      "x": 1,
      "y": 4,
      "z": -1,
      "name": "Empty"
    },
    {
      "x": 1,
      "y": 5,
      "z": -1,
      "name": "Rock_Basalt"
    },
    {
      "x": 1,
      "y": 0,
      "z": 0,
      "name": "Rock_Shale_Brick_Smooth"
    },
    {
      "x": 1,
      "y": 1,
      "z": 0,
      "name": "Empty"
    },
    {
      "x": 1,
      "y": 2,
      "z": 0,
      "name": "Empty"
    },
    {
      "x": 1,
      "y": 3,
      "z": 0,
      "name": "Empty"
    },
    {
      "x": 1,
      "y": 4,
      "z": 0,
      "name": "Empty"
    },
    {
      "x": 1,
      "y": 5,
      "z": 0,
      "name": "Rock_Basalt"
    },
    {
      "x": 2,
      "y": 0,
      "z": -15,
      "name": "Rock_Shale_Brick_Smooth"
    },
    {
      "x": 2,
      "y": 1,
      "z": -15,
      "name": "Rock_Shale_Brick"
    },
    {
      "x": 2,
      "y": 2,
      "z": -15,
      "name": "Rock_Shale_Brick"
    },
    {
      "x": 2,
      "y": 3,
      "z": -15,
      "name": "Rock_Shale_Brick"
    },
    {
      "x": 2,
      "y": 4,
      "z": -15,
      "name": "Rock_Shale_Brick"
    },
    {
      "x": 2,
      "y": 5,
      "z": -15,
      "name": "Rock_Basalt"
    },
    {
      "x": 2,
      "y": 0,
      "z": -14,
      "name": "Rock_Shale_Brick_Smooth"
    },
    {
      "x": 2,
      "y": 1,
      "z": -14,
      "name": "Empty"
    },
    {
      "x": 2,
      "y": 2,
      "z": -14,
      "name": "Empty"
    },
    {
      "x": 2,
      "y": 3,
      "z": -14,
      "name": "Rock_Basalt_Brick_Half",
      "rotation": 8
    },
    {
      "x": 2,
      "y": 4,
      "z": -14,
      "name": "Rock_Basalt_Brick"
    },
    {
      "x": 2,
      "y": 5,
      "z": -14,
      "name": "Rock_Basalt"
    },
    {
      "x": 2,
      "y": 0,
      "z": -13,
      "name": "Rock_Basalt"
    },
    {
      "x": 2,
      "y": 1,
      "z": -13,
      "name": "Empty"
    },
    {
      "x": 2,
      "y": 2,
      "z": -13,
      "name": "Empty"
    },
    {
      "x": 2,
      "y": 3,
      "z": -13,
      "name": "Empty"
    },
    {
      "x": 2,
      "y": 4,
      "z": -13,
      "name": "Empty"
    },
    {
      "x": 2,
      "y": 5,
      "z": -13,
      "name": "Rock_Basalt"
    },
    {
      "x": 2,
      "y": 0,
      "z": -12,
      "name": "Rock_Basalt"
    },
    {
      "x": 2,
      "y": 1,
      "z": -12,
      "name": "Empty"
    },
    {
      "x": 2,
      "y": 2,
      "z": -12,
      "name": "Empty"
    },
    {
      "x": 2,
      "y": 3,
      "z": -12,
      "name": "Empty"
    },
    {
      "x": 2,
      "y": 4,
      "z": -12,
      "name": "Empty"
    },
    {
      "x": 2,
      "y": 5,
      "z": -12,
      "name": "Rock_Basalt"
    },
    {
      "x": 2,
      "y": 0,
      "z": -11,
      "name": "Rock_Shale"
    },
    {
      "x": 2,
      "y": 1,
      "z": -11,
      "name": "Empty"
    },
    {
      "x": 2,
      "y": 2,
      "z": -11,
      "name": "Empty"
    },
    {
      "x": 2,
      "y": 3,
      "z": -11,
      "name": "Empty"
    },
    {
      "x": 2,
      "y": 4,
      "z": -11,
      "name": "Empty"
    },
    {
      "x": 2,
      "y": 5,
      "z": -11,
      "name": "Rock_Basalt"
    },
    {
      "x": 2,
      "y": 0,
      "z": -10,
      "name": "Rock_Shale"
    },
    {
      "x": 2,
      "y": 1,
      "z": -10,
      "name": "Empty"
    },
    {
      "x": 2,
      "y": 2,
      "z": -10,
      "name": "Empty"
    },
    {
      "x": 2,
      "y": 3,
      "z": -10,
      "name": "Empty"
    },
    {
      "x": 2,
      "y": 4,
      "z": -10,
      "name": "Empty"
    },
    {
      "x": 2,
      "y": 5,
      "z": -10,
      "name": "Rock_Basalt"
    },
    {
      "x": 2,
      "y": 0,
      "z": -9,
      "name": "Rock_Shale"
    },
    {
      "x": 2,
      "y": 1,
      "z": -9,
      "name": "Empty"
    },
    {
      "x": 2,
      "y": 2,
      "z": -9,
      "name": "Empty"
    },
    {
      "x": 2,
      "y": 3,
      "z": -9,
      "name": "Empty"
    },
    {
      "x": 2,
      "y": 4,
      "z": -9,
      "name": "Empty"
    },
    {
      "x": 2,
      "y": 5,
      "z": -9,
      "name": "Rock_Basalt"
    },
    {
      "x": 2,
      "y": 0,
      "z": -8,
      "name": "Rock_Shale"
    },
    {
      "x": 2,
      "y": 1,
      "z": -8,
      "name": "Empty"
    },
    {
      "x": 2,
      "y": 2,
      "z": -8,
      "name": "Empty"
    },
    {
      "x": 2,
      "y": 3,
      "z": -8,
      "name": "Empty"
    },
    {
      "x": 2,
      "y": 4,
      "z": -8,
      "name": "Empty"
    },
    {
      "x": 2,
      "y": 5,
      "z": -8,
      "name": "Rock_Basalt"
    },
    {
      "x": 2,
      "y": 0,
      "z": -7,
      "name": "Soil_Dirt_Cold"
    },
    {
      "x": 2,
      "y": 1,
      "z": -7,
      "name": "Empty"
    },
    {
      "x": 2,
      "y": 2,
      "z": -7,
      "name": "Empty"
    },
    {
      "x": 2,
      "y": 3,
      "z": -7,
      "name": "Empty"
    },
    {
      "x": 2,
      "y": 4,
      "z": -7,
      "name": "Empty"
    },
    {
      "x": 2,
      "y": 5,
      "z": -7,
      "name": "Rock_Basalt"
    },
    {
      "x": 2,
      "y": 0,
      "z": -6,
      "name": "Soil_Dirt_Cold"
    },
    {
      "x": 2,
      "y": 1,
      "z": -6,
      "name": "Empty"
    },
    {
      "x": 2,
      "y": 2,
      "z": -6,
      "name": "Empty"
    },
    {
      "x": 2,
      "y": 3,
      "z": -6,
      "name": "Rock_Basalt_Brick_Half",
      "rotation": 8
    },
    {
      "x": 2,
      "y": 4,
      "z": -6,
      "name": "Rock_Basalt_Brick"
    },
    {
      "x": 2,
      "y": 5,
      "z": -6,
      "name": "Rock_Basalt"
    },
    {
      "x": 2,
      "y": 0,
      "z": -5,
      "name": "Rock_Shale"
    },
    {
      "x": 2,
      "y": 1,
      "z": -5,
      "name": "Furniture_Ancient_Barrel"
    },
    {
      "x": 2,
      "y": 2,
      "z": -5,
      "name": "Empty"
    },
    {
      "x": 2,
      "y": 3,
      "z": -5,
      "name": "Rock_Basalt_Brick_Half",
      "rotation": 8
    },
    {
      "x": 2,
      "y": 4,
      "z": -5,
      "name": "Rock_Basalt_Brick"
    },
    {
      "x": 2,
      "y": 5,
      "z": -5,
      "name": "Rock_Basalt"
    },
    {
      "x": 2,
      "y": 0,
      "z": -4,
      "name": "Rock_Shale"
    },
    {
      "x": 2,
      "y": 1,
      "z": -4,
      "name": "Empty"
    },
    {
      "x": 2,
      "y": 2,
      "z": -4,
      "name": "Empty"
    },
    {
      "x": 2,
      "y": 3,
      "z": -4,
      "name": "Empty"
    },
    {
      "x": 2,
      "y": 4,
      "z": -4,
      "name": "Empty"
    },
    {
      "x": 2,
      "y": 5,
      "z": -4,
      "name": "Rock_Basalt"
    },
    {
      "x": 2,
      "y": 0,
      "z": -3,
      "name": "Rock_Shale"
    },
    {
      "x": 2,
      "y": 1,
      "z": -3,
      "name": "Empty"
    },
    {
      "x": 2,
      "y": 2,
      "z": -3,
      "name": "Empty"
    },
    {
      "x": 2,
      "y": 3,
      "z": -3,
      "name": "Empty"
    },
    {
      "x": 2,
      "y": 4,
      "z": -3,
      "name": "Empty"
    },
    {
      "x": 2,
      "y": 5,
      "z": -3,
      "name": "Rock_Basalt"
    },
    {
      "x": 2,
      "y": 0,
      "z": -2,
      "name": "Rock_Shale"
    },
    {
      "x": 2,
      "y": 1,
      "z": -2,
      "name": "Empty"
    },
    {
      "x": 2,
      "y": 2,
      "z": -2,
      "name": "Empty"
    },
    {
      "x": 2,
      "y": 3,
      "z": -2,
      "name": "Empty"
    },
    {
      "x": 2,
      "y": 4,
      "z": -2,
      "name": "Empty"
    },
    {
      "x": 2,
      "y": 5,
      "z": -2,
      "name": "Rock_Basalt"
    },
    {
      "x": 2,
      "y": 0,
      "z": -1,
      "name": "Rock_Basalt"
    },
    {
      "x": 2,
      "y": 1,
      "z": -1,
      "name": "Empty"
    },
    {
      "x": 2,
      "y": 2,
      "z": -1,
      "name": "Empty"
    },
    {
      "x": 2,
      "y": 3,
      "z": -1,
      "name": "Empty"
    },
    {
      "x": 2,
      "y": 4,
      "z": -1,
      "name": "Empty"
    },
    {
      "x": 2,
      "y": 5,
      "z": -1,
      "name": "Rock_Basalt"
    },
    {
      "x": 2,
      "y": 0,
      "z": 0,
      "name": "Rock_Shale_Brick_Smooth"
    },
    {
      "x": 2,
      "y": 1,
      "z": 0,
      "name": "Empty"
    },
    {
      "x": 2,
      "y": 2,
      "z": 0,
      "name": "Empty"
    },
    {
      "x": 2,
      "y": 3,
      "z": 0,
      "name": "Empty"
    },
    {
      "x": 2,
      "y": 4,
      "z": 0,
      "name": "Empty"
    },
    {
      "x": 2,
      "y": 5,
      "z": 0,
      "name": "Rock_Basalt"
    },
    {
      "x": 3,
      "y": 0,
      "z": -15,
      "name": "Rock_Shale_Brick_Smooth"
    },
    {
      "x": 3,
      "y": 1,
      "z": -15,
      "name": "Rock_Shale_Brick"
    },
    {
      "x": 3,
      "y": 2,
      "z": -15,
      "name": "Rock_Shale_Brick"
    },
    {
      "x": 3,
      "y": 3,
      "z": -15,
      "name": "Rock_Shale_Brick"
    },
    {
      "x": 3,
      "y": 4,
      "z": -15,
      "name": "Rock_Shale_Brick"
    },
    {
      "x": 3,
      "y": 5,
      "z": -15,
      "name": "Rock_Basalt"
    },
    {
      "x": 3,
      "y": 0,
      "z": -14,
      "name": "Rock_Shale_Brick_Smooth"
    },
    {
      "x": 3,
      "y": 1,
      "z": -14,
      "name": "Empty"
    },
    {
      "x": 3,
      "y": 2,
      "z": -14,
      "name": "Empty"
    },
    {
      "x": 3,
      "y": 3,
      "z": -14,
      "name": "Rock_Basalt_Brick"
    },
    {
      "x": 3,
      "y": 4,
      "z": -14,
      "name": "Rock_Basalt_Brick"
    },
    {
      "x": 3,
      "y": 5,
      "z": -14,
      "name": "Rock_Basalt"
    },
    {
      "x": 3,
      "y": 0,
      "z": -13,
      "name": "Rock_Shale"
    },
    {
      "x": 3,
      "y": 1,
      "z": -13,
      "name": "Empty"
    },
    {
      "x": 3,
      "y": 2,
      "z": -13,
      "name": "Empty"
    },
    {
      "x": 3,
      "y": 3,
      "z": -13,
      "name": "Empty"
    },
    {
      "x": 3,
      "y": 4,
      "z": -13,
      "name": "Empty"
    },
    {
      "x": 3,
      "y": 5,
      "z": -13,
      "name": "Rock_Basalt"
    },
    {
      "x": 3,
      "y": 0,
      "z": -12,
      "name": "Rock_Shale"
    },
    {
      "x": 3,
      "y": 1,
      "z": -12,
      "name": "Empty"
    },
    {
      "x": 3,
      "y": 2,
      "z": -12,
      "name": "Empty"
    },
    {
      "x": 3,
      "y": 3,
      "z": -12,
      "name": "Empty"
    },
    {
      "x": 3,
      "y": 4,
      "z": -12,
      "name": "Empty"
    },
    {
      "x": 3,
      "y": 5,
      "z": -12,
      "name": "Rock_Basalt"
    },
    {
      "x": 3,
      "y": 0,
      "z": -11,
      "name": "Rock_Shale"
    },
    {
      "x": 3,
      "y": 1,
      "z": -11,
      "name": "Empty"
    },
    {
      "x": 3,
      "y": 2,
      "z": -11,
      "name": "Empty"
    },
    {
      "x": 3,
      "y": 3,
      "z": -11,
      "name": "Empty"
    },
    {
      "x": 3,
      "y": 4,
      "z": -11,
      "name": "Empty"
    },
    {
      "x": 3,
      "y": 5,
      "z": -11,
      "name": "Rock_Basalt"
    },
    {
      "x": 3,
      "y": 0,
      "z": -10,
      "name": "Rock_Shale"
    },
    {
      "x": 3,
      "y": 1,
      "z": -10,
      "name": "Empty"
    },
    {
      "x": 3,
      "y": 2,
      "z": -10,
      "name": "Empty"
    },
    {
      "x": 3,
      "y": 3,
      "z": -10,
      "name": "Empty"
    },
    {
      "x": 3,
      "y": 4,
      "z": -10,
      "name": "Empty"
    },
    {
      "x": 3,
      "y": 5,
      "z": -10,
      "name": "Rock_Basalt"
    },
    {
      "x": 3,
      "y": 0,
      "z": -9,
      "name": "Rock_Shale"
    },
    {
      "x": 3,
      "y": 1,
      "z": -9,
      "name": "Empty"
    },
    {
      "x": 3,
      "y": 2,
      "z": -9,
      "name": "Empty"
    },
    {
      "x": 3,
      "y": 3,
      "z": -9,
      "name": "Empty"
    },
    {
      "x": 3,
      "y": 4,
      "z": -9,
      "name": "Empty"
    },
    {
      "x": 3,
      "y": 5,
      "z": -9,
      "name": "Rock_Basalt"
    },
    {
      "x": 3,
      "y": 0,
      "z": -8,
      "name": "Rock_Shale"
    },
    {
      "x": 3,
      "y": 1,
      "z": -8,
      "name": "Empty"
    },
    {
      "x": 3,
      "y": 2,
      "z": -8,
      "name": "Empty"
    },
    {
      "x": 3,
      "y": 3,
      "z": -8,
      "name": "Empty"
    },
    {
      "x": 3,
      "y": 4,
      "z": -8,
      "name": "Plant_Bush_Dead_Hanging"
    },
    {
      "x": 3,
      "y": 5,
      "z": -8,
      "name": "Rock_Basalt"
    },
    {
      "x": 3,
      "y": 0,
      "z": -7,
      "name": "Soil_Dirt_Cold"
    },
    {
      "x": 3,
      "y": 1,
      "z": -7,
      "name": "Rock_Shale_Brick_Beam"
    },
    {
      "x": 3,
      "y": 2,
      "z": -7,
      "name": "Furniture_Human_Ruins_Torch",
      "rotation": 3
    },
    {
      "x": 3,
      "y": 3,
      "z": -7,
      "name": "Empty"
    },
    {
      "x": 3,
      "y": 4,
      "z": -7,
      "name": "Empty"
    },
    {
      "x": 3,
      "y": 5,
      "z": -7,
      "name": "Rock_Basalt"
    },
    {
      "x": 3,
      "y": 0,
      "z": -6,
      "name": "Soil_Dirt_Cold"
    },
    {
      "x": 3,
      "y": 1,
      "z": -6,
      "name": "Empty"
    },
    {
      "x": 3,
      "y": 2,
      "z": -6,
      "name": "Empty"
    },
    {
      "x": 3,
      "y": 3,
      "z": -6,
      "name": "Rock_Basalt_Brick"
    },
    {
      "x": 3,
      "y": 4,
      "z": -6,
      "name": "Rock_Basalt_Brick"
    },
    {
      "x": 3,
      "y": 5,
      "z": -6,
      "name": "Rock_Basalt"
    },
    {
      "x": 3,
      "y": 0,
      "z": -5,
      "name": "Soil_Dirt_Cold"
    },
    {
      "x": 3,
      "y": 1,
      "z": -5,
      "name": "Furniture_Ancient_Barrel"
    },
    {
      "x": 3,
      "y": 2,
      "z": -5,
      "name": "Empty"
    },
    {
      "x": 3,
      "y": 3,
      "z": -5,
