{
  "version": 8,
  "blockIdVersion": 11,
  "anchorX": 0,
  "anchorY": 0,
  "anchorZ": 0,
  "blocks": [
    {
      "x": -10,
      "y": 0,
      "z": -9,
      "name": "Prefab_Spawner_Block",
      "components": {
        "Components": {
          "PrefabSpawner": {
            "FitHeightmap": false,
            "InheritSeed": true,
            "InheritHeightCondition": true
          },
          "PlacedByInteraction": {
            "WhoPlacedUuid": {
              "$binary": "QBnQLM5NQMa81/Qj3+UrJQ==",
              "$type": "04"
            }
          }
        }
      },
      "rotation": 3
    },
    {
      "x": -9,
      "y": 0,
      "z": -14,
      "name": "Rock_Shale_Brick_Smooth"
    },
    {
      "x": -9,
      "y": 1,
      "z": -14,
      "name": "Rock_Shale_Brick"
    },
    {
      "x": -9,
      "y": 2,
      "z": -14,
      "name": "Rock_Shale_Brick"
    },
    {
      "x": -9,
      "y": 3,
      "z": -14,
      "name": "Rock_Shale_Brick"
    },
    {
      "x": -9,
      "y": 4,
      "z": -14,
      "name": "Rock_Shale_Brick"
    },
    {
      "x": -9,
      "y": 0,
      "z": -13,
      "name": "Rock_Shale_Brick_Smooth"
    },
    {
      "x": -9,
      "y": 1,
      "z": -13,
      "name": "Rock_Shale_Brick_Pillar_Base"
    },
    {
      "x": -9,
      "y": 2,
      "z": -13,
      "name": "Rock_Shale_Brick_Pillar_Middle"
    },
    {
      "x": -9,
      "y": 3,
      "z": -13,
      "name": "Rock_Shale_Brick_Pillar_Base",
      "rotation": 8
    },
    {
      "x": -9,
      "y": 4,
      "z": -13,
      "name": "Rock_Shale_Brick"
    },
    {
      "x": -9,
      "y": 0,
      "z": -12,
      "name": "Rock_Shale_Brick_Smooth"
    },
    {
      "x": -9,
      "y": 1,
      "z": -12,
      "name": "Empty"
    },
    {
      "x": -9,
      "y": 2,
      "z": -12,
      "name": "Empty"
    },
    {
      "x": -9,
      "y": 3,
      "z": -12,
      "name": "Empty"
    },
    {
      "x": -9,
      "y": 4,
      "z": -12,
      "name": "Rock_Shale_Brick_Stairs",
      "rotation": 10
    },
    {
      "x": -9,
      "y": 0,
      "z": -11,
      "name": "Rock_Shale_Brick_Smooth"
    },
    {
      "x": -9,
      "y": 1,
      "z": -11,
      "name": "Empty"
    },
    {
      "x": -9,
      "y": 2,
      "z": -11,
      "name": "Empty"
    },
    {
      "x": -9,
      "y": 3,
      "z": -11,
      "name": "Empty"
    },
    {
      "x": -9,
      "y": 4,
      "z": -11,
      "name": "Empty"
    },
    {
      "x": -9,
      "y": 0,
      "z": -10,
      "name": "Rock_Shale_Brick_Smooth"
    },
    {
      "x": -9,
      "y": 1,
      "z": -10,
      "name": "Empty"
    },
    {
      "x": -9,
      "y": 2,
      "z": -10,
      "name": "Empty"
    },
    {
      "x": -9,
      "y": 3,
      "z": -10,
      "name": "Empty"
    },
    {
      "x": -9,
      "y": 4,
      "z": -10,
      "name": "Empty"
    },
    {
      "x": -9,
      "y": 0,
      "z": -9,
      "name": "Rock_Shale_Brick_Smooth"
    },
    {
      "x": -9,
      "y": 1,
      "z": -9,
      "name": "Empty"
    },
    {
      "x": -9,
      "y": 2,
      "z": -9,
      "name": "Empty"
    },
    {
      "x": -9,
      "y": 3,
      "z": -9,
      "name": "Empty"
    },
    {
      "x": -9,
      "y": 4,
      "z": -9,
      "name": "Empty"
    },
    {
      "x": -9,
      "y": 0,
      "z": -8,
      "name": "Rock_Shale_Brick_Smooth"
    },
    {
      "x": -9,
      "y": 1,
      "z": -8,
      "name": "Empty"
    },
    {
      "x": -9,
      "y": 2,
      "z": -8,
      "name": "Empty"
    },
    {
      "x": -9,
      "y": 3,
      "z": -8,
      "name": "Empty"
    },
    {
      "x": -9,
      "y": 4,
      "z": -8,
      "name": "Empty"
    },
    {
      "x": -9,
      "y": 0,
      "z": -7,
      "name": "Rock_Shale_Brick_Smooth"
    },
    {
      "x": -9,
      "y": 1,
      "z": -7,
      "name": "Empty"
    },
    {
      "x": -9,
      "y": 2,
      "z": -7,
      "name": "Empty"
    },
    {
      "x": -9,
      "y": 3,
      "z": -7,
      "name": "Empty"
    },
    {
      "x": -9,
      "y": 4,
      "z": -7,
      "name": "Empty"
    },
    {
      "x": -9,
      "y": 0,
      "z": -6,
      "name": "Rock_Shale_Brick_Smooth"
    },
    {
      "x": -9,
      "y": 1,
      "z": -6,
      "name": "Empty"
    },
    {
      "x": -9,
      "y": 2,
      "z": -6,
      "name": "Empty"
    },
    {
      "x": -9,
      "y": 3,
      "z": -6,
      "name": "Empty"
    },
    {
      "x": -9,
      "y": 4,
      "z": -6,
      "name": "Rock_Shale_Brick_Stairs",
      "rotation": 8
    },
    {
      "x": -9,
      "y": 0,
      "z": -5,
      "name": "Rock_Shale_Brick_Smooth"
    },
    {
      "x": -9,
      "y": 1,
      "z": -5,
      "name": "Rock_Shale_Brick_Pillar_Base"
    },
    {
      "x": -9,
      "y": 2,
      "z": -5,
      "name": "Rock_Shale_Brick_Pillar_Middle"
    },
    {
      "x": -9,
      "y": 3,
      "z": -5,
      "name": "Rock_Shale_Brick_Pillar_Base",
      "rotation": 8
    },
    {
      "x": -9,
      "y": 4,
      "z": -5,
      "name": "Rock_Shale_Brick"
    },
    {
      "x": -9,
      "y": 0,
      "z": -4,
      "name": "Rock_Shale_Brick_Smooth"
    },
    {
      "x": -9,
      "y": 1,
      "z": -4,
      "name": "Rock_Shale_Brick"
    },
    {
      "x": -9,
      "y": 2,
      "z": -4,
      "name": "Rock_Shale_Brick"
    },
    {
      "x": -9,
      "y": 3,
      "z": -4,
      "name": "Rock_Shale_Brick"
    },
    {
      "x": -9,
      "y": 4,
      "z": -4,
      "name": "Rock_Shale_Brick"
    },
    {
      "x": -8,
      "y": 0,
      "z": -14,
      "name": "Rock_Shale_Brick_Smooth"
    },
    {
      "x": -8,
      "y": 1,
      "z": -14,
      "name": "Rock_Shale_Brick"
    },
    {
      "x": -8,
      "y": 2,
      "z": -14,
      "name": "Rock_Shale_Brick"
    },
    {
      "x": -8,
      "y": 3,
      "z": -14,
      "name": "Rock_Basalt"
    },
    {
      "x": -8,
      "y": 4,
      "z": -14,
      "name": "Rock_Shale_Brick"
    },
    {
      "x": -8,
      "y": 0,
      "z": -13,
      "name": "Rock_Shale_Brick_Smooth"
    },
    {
      "x": -8,
      "y": 1,
      "z": -13,
      "name": "Rock_Shale_Brick_Stairs",
      "rotation": 10
    },
    {
      "x": -8,
      "y": 2,
      "z": -13,
      "name": "Deco_Bone_Skulls"
    },
    {
      "x": -8,
      "y": 3,
      "z": -13,
      "name": "Empty"
    },
    {
      "x": -8,
      "y": 4,
      "z": -13,
      "name": "Rock_Shale_Brick"
    },
    {
      "x": -8,
      "y": 0,
      "z": -12,
      "name": "Soil_Dirt_Cold"
    },
    {
      "x": -8,
      "y": 1,
      "z": -12,
      "name": "Plant_Bush_Dead_Twisted"
    },
    {
      "x": -8,
      "y": 2,
      "z": -12,
      "name": "Empty"
    },
    {
      "x": -8,
      "y": 3,
      "z": -12,
      "name": "Empty"
    },
    {
      "x": -8,
      "y": 4,
      "z": -12,
      "name": "Empty"
    },
    {
      "x": -8,
      "y": 0,
      "z": -11,
      "name": "Soil_Dirt_Cold"
    },
    {
      "x": -8,
      "y": 1,
      "z": -11,
      "name": "Empty"
    },
    {
      "x": -8,
      "y": 2,
      "z": -11,
      "name": "Empty"
    },
    {
      "x": -8,
      "y": 3,
      "z": -11,
      "name": "Empty"
    },
    {
      "x": -8,
      "y": 4,
      "z": -11,
      "name": "Empty"
    },
    {
      "x": -8,
      "y": 0,
      "z": -10,
      "name": "Soil_Dirt_Cold"
    },
    {
      "x": -8,
      "y": 1,
      "z": -10,
      "name": "Empty"
    },
    {
      "x": -8,
      "y": 2,
      "z": -10,
      "name": "Empty"
    },
    {
      "x": -8,
      "y": 3,
      "z": -10,
      "name": "Empty"
    },
    {
      "x": -8,
      "y": 4,
      "z": -10,
      "name": "Empty"
    },
    {
      "x": -8,
      "y": 0,
      "z": -9,
      "name": "Rock_Basalt"
    },
    {
      "x": -8,
      "y": 1,
      "z": -9,
      "name": "Empty"
    },
    {
      "x": -8,
      "y": 2,
      "z": -9,
      "name": "Empty"
    },
    {
      "x": -8,
      "y": 3,
      "z": -9,
      "name": "Empty"
    },
    {
      "x": -8,
      "y": 4,
      "z": -9,
      "name": "Empty"
    },
    {
      "x": -8,
      "y": 0,
      "z": -8,
      "name": "Rock_Basalt"
    },
    {
      "x": -8,
      "y": 1,
      "z": -8,
      "name": "Empty"
    },
    {
      "x": -8,
      "y": 2,
      "z": -8,
      "name": "Empty"
    },
    {
      "x": -8,
      "y": 3,
      "z": -8,
      "name": "Empty"
    },
    {
      "x": -8,
      "y": 4,
      "z": -8,
      "name": "Empty"
    },
    {
      "x": -8,
      "y": 0,
      "z": -7,
      "name": "Rock_Basalt"
    },
    {
      "x": -8,
      "y": 1,
      "z": -7,
      "name": "Empty"
    },
    {
      "x": -8,
      "y": 2,
      "z": -7,
      "name": "Empty"
    },
    {
      "x": -8,
      "y": 3,
      "z": -7,
      "name": "Empty"
    },
    {
      "x": -8,
      "y": 4,
      "z": -7,
      "name": "Plant_Bush_Dead_Hanging"
    },
    {
      "x": -8,
      "y": 0,
      "z": -6,
      "name": "Soil_Dirt_Cold"
    },
    {
      "x": -8,
      "y": 1,
      "z": -6,
      "name": "Furniture_Ancient_Barrel"
    },
    {
      "x": -8,
      "y": 2,
      "z": -6,
      "name": "Empty"
    },
    {
      "x": -8,
      "y": 3,
      "z": -6,
      "name": "Empty"
    },
    {
      "x": -8,
      "y": 4,
      "z": -6,
      "name": "Empty"
    },
    {
      "x": -8,
      "y": 0,
      "z": -5,
      "name": "Rock_Shale_Brick_Smooth"
    },
    {
      "x": -8,
      "y": 1,
      "z": -5,
      "name": "Rock_Shale_Brick_Stairs",
      "rotation": 8
    },
    {
      "x": -8,
      "y": 2,
      "z": -5,
      "name": "Deco_Bone_Pile"
    },
    {
      "x": -8,
      "y": 3,
      "z": -5,
      "name": "Empty"
    },
    {
      "x": -8,
      "y": 4,
      "z": -5,
      "name": "Rock_Shale_Brick"
    },
    {
      "x": -8,
      "y": 0,
      "z": -4,
      "name": "Rock_Shale_Brick_Smooth"
    },
    {
      "x": -8,
      "y": 1,
      "z": -4,
      "name": "Rock_Shale_Brick"
    },
    {
      "x": -8,
      "y": 2,
      "z": -4,
      "name": "Rock_Shale_Brick"
    },
    {
      "x": -8,
      "y": 3,
      "z": -4,
      "name": "Rock_Basalt"
    },
    {
      "x": -8,
      "y": 4,
      "z": -4,
      "name": "Rock_Shale_Brick"
    },
    {
      "x": -7,
      "y": 0,
      "z": -14,
      "name": "Rock_Shale_Brick_Smooth"
    },
    {
      "x": -7,
      "y": 1,
      "z": -14,
      "name": "Rock_Shale_Brick"
    },
    {
      "x": -7,
      "y": 2,
      "z": -14,
      "name": "Rock_Shale_Brick"
    },
    {
      "x": -7,
      "y": 3,
      "z": -14,
      "name": "Rock_Basalt"
    },
    {
      "x": -7,
      "y": 4,
      "z": -14,
      "name": "Rock_Shale_Brick"
    },
    {
      "x": -7,
      "y": 0,
      "z": -13,
      "name": "Rock_Shale_Brick_Smooth"
    },
    {
      "x": -7,
      "y": 1,
      "z": -13,
      "name": "Rock_Shale_Brick_Stairs",
      "rotation": 10
    },
    {
      "x": -7,
      "y": 2,
      "z": -13,
      "name": "Deco_Bone_Skulls"
    },
    {
      "x": -7,
      "y": 3,
      "z": -13,
      "name": "Empty"
    },
    {
      "x": -7,
      "y": 4,
      "z": -13,
      "name": "Rock_Shale_Brick"
    },
    {
      "x": -7,
      "y": 0,
      "z": -12,
      "name": "Soil_Dirt_Cold"
    },
    {
      "x": -7,
      "y": 1,
      "z": -12,
      "name": "Empty"
    },
    {
      "x": -7,
      "y": 2,
      "z": -12,
      "name": "Empty"
    },
    {
      "x": -7,
      "y": 3,
      "z": -12,
      "name": "Empty"
    },
    {
      "x": -7,
      "y": 4,
      "z": -12,
      "name": "Empty"
    },
    {
      "x": -7,
      "y": 0,
      "z": -11,
      "name": "Soil_Dirt_Cold"
    },
    {
      "x": -7,
      "y": 1,
      "z": -11,
      "name": "Empty"
    },
    {
      "x": -7,
      "y": 2,
      "z": -11,
      "name": "Empty"
    },
    {
      "x": -7,
      "y": 3,
      "z": -11,
      "name": "Empty"
    },
    {
      "x": -7,
      "y": 4,
      "z": -11,
      "name": "Plant_Bush_Dead_Hanging"
    },
    {
      "x": -7,
      "y": 0,
      "z": -10,
      "name": "Rock_Shale"
    },
    {
      "x": -7,
      "y": 1,
      "z": -10,
      "name": "Empty"
    },
    {
      "x": -7,
      "y": 2,
      "z": -10,
      "name": "Empty"
    },
    {
      "x": -7,
      "y": 3,
      "z": -10,
      "name": "Empty"
    },
    {
      "x": -7,
      "y": 4,
      "z": -10,
      "name": "Empty"
    },
    {
      "x": -7,
      "y": 0,
      "z": -9,
      "name": "Rock_Shale"
    },
    {
      "x": -7,
      "y": 1,
      "z": -9,
      "name": "Empty"
    },
    {
      "x": -7,
      "y": 2,
      "z": -9,
      "name": "Empty"
    },
    {
      "x": -7,
      "y": 3,
      "z": -9,
      "name": "Empty"
    },
    {
      "x": -7,
      "y": 4,
      "z": -9,
      "name": "Empty"
    },
    {
      "x": -7,
      "y": 0,
      "z": -8,
      "name": "Rock_Shale"
    },
    {
      "x": -7,
      "y": 1,
      "z": -8,
      "name": "Empty"
    },
    {
      "x": -7,
      "y": 2,
      "z": -8,
      "name": "Empty"
    },
    {
      "x": -7,
      "y": 3,
      "z": -8,
      "name": "Empty"
    },
    {
      "x": -7,
      "y": 4,
      "z": -8,
      "name": "Empty"
    },
    {
      "x": -7,
      "y": 0,
      "z": -7,
      "name": "Rock_Basalt"
    },
    {
      "x": -7,
      "y": 1,
      "z": -7,
      "name": "Empty"
    },
    {
      "x": -7,
      "y": 2,
      "z": -7,
      "name": "Empty"
    },
    {
      "x": -7,
      "y": 3,
      "z": -7,
      "name": "Empty"
    },
    {
      "x": -7,
      "y": 4,
      "z": -7,
      "name": "Empty"
    },
    {
      "x": -7,
      "y": 0,
      "z": -6,
      "name": "Soil_Dirt_Cold"
    },
    {
      "x": -7,
      "y": 1,
      "z": -6,
      "name": "Plant_Bush_Dead_Twisted"
    },
    {
      "x": -7,
      "y": 2,
      "z": -6,
      "name": "Empty"
    },
    {
      "x": -7,
      "y": 3,
      "z": -6,
      "name": "Empty"
    },
    {
      "x": -7,
      "y": 4,
      "z": -6,
      "name": "Empty"
    },
    {
      "x": -7,
      "y": 0,
      "z": -5,
      "name": "Rock_Shale_Brick_Smooth"
    },
    {
      "x": -7,
      "y": 1,
      "z": -5,
      "name": "Rock_Shale_Brick_Stairs",
      "rotation": 8
    },
    {
      "x": -7,
      "y": 2,
      "z": -5,
      "name": "Empty"
    },
    {
      "x": -7,
      "y": 3,
      "z": -5,
      "name": "Empty"
    },
    {
      "x": -7,
      "y": 4,
      "z": -5,
      "name": "Rock_Shale_Brick"
    },
    {
      "x": -7,
      "y": 0,
      "z": -4,
      "name": "Rock_Shale_Brick_Smooth"
    },
    {
      "x": -7,
      "y": 1,
      "z": -4,
      "name": "Rock_Shale_Brick"
    },
    {
      "x": -7,
      "y": 2,
      "z": -4,
      "name": "Rock_Shale_Brick"
    },
    {
      "x": -7,
      "y": 3,
      "z": -4,
      "name": "Rock_Basalt"
    },
    {
      "x": -7,
      "y": 4,
      "z": -4,
      "name": "Rock_Shale_Brick"
    },
    {
      "x": -6,
      "y": 0,
      "z": -14,
      "name": "Rock_Shale_Brick_Smooth"
    },
    {
      "x": -6,
      "y": 1,
      "z": -14,
      "name": "Rock_Shale_Brick"
    },
    {
      "x": -6,
      "y": 2,
      "z": -14,
      "name": "Rock_Shale_Brick"
    },
    {
      "x": -6,
      "y": 3,
      "z": -14,
      "name": "Rock_Shale_Brick"
    },
    {
      "x": -6,
      "y": 4,
      "z": -14,
      "name": "Rock_Shale_Brick"
    },
    {
      "x": -6,
      "y": 0,
      "z": -13,
      "name": "Rock_Shale_Brick_Smooth"
    },
    {
      "x": -6,
      "y": 1,
      "z": -13,
      "name": "Rock_Shale_Brick_Pillar_Base"
    },
    {
      "x": -6,
      "y": 2,
      "z": -13,
      "name": "Rock_Shale_Brick_Pillar_Middle"
    },
    {
      "x": -6,
      "y": 3,
      "z": -13,
      "name": "Rock_Shale_Brick_Pillar_Base",
      "rotation": 8
    },
    {
      "x": -6,
      "y": 4,
      "z": -13,
      "name": "Rock_Shale_Brick"
    },
    {
      "x": -6,
      "y": 0,
      "z": -12,
      "name": "Rock_Basalt"
    },
    {
      "x": -6,
      "y": 1,
      "z": -12,
      "name": "Rock_Basalt"
    },
    {
      "x": -6,
      "y": 2,
      "z": -12,
      "name": "Rubble_Basalt"
    },
    {
      "x": -6,
      "y": 3,
      "z": -12,
      "name": "Empty"
    },
    {
      "x": -6,
      "y": 4,
      "z": -12,
      "name": "Rock_Shale_Brick_Stairs",
      "rotation": 10
    },
    {
      "x": -6,
      "y": 0,
      "z": -11,
      "name": "Rock_Basalt"
    },
    {
      "x": -6,
      "y": 1,
      "z": -11,
      "name": "Rock_Basalt"
    },
    {
      "x": -6,
      "y": 2,
      "z": -11,
      "name": "Empty"
    },
    {
      "x": -6,
      "y": 3,
      "z": -11,
      "name": "Empty"
    },
    {
      "x": -6,
      "y": 4,
      "z": -11,
      "name": "Empty"
    },
    {
      "x": -6,
      "y": 0,
      "z": -10,
      "name": "Rock_Shale"
    },
    {
      "x": -6,
      "y": 1,
      "z": -10,
      "name": "Empty"
    },
    {
      "x": -6,
      "y": 2,
      "z": -10,
      "name": "Empty"
    },
    {
      "x": -6,
      "y": 3,
      "z": -10,
      "name": "Empty"
    },
    {
      "x": -6,
      "y": 4,
      "z": -10,
      "name": "Empty"
    },
    {
      "x": -6,
      "y": 0,
      "z": -9,
      "name": "Rock_Shale"
    },
    {
      "x": -6,
      "y": 1,
      "z": -9,
      "name": "Empty"
    },
    {
      "x": -6,
      "y": 2,
      "z": -9,
      "name": "Empty"
    },
    {
      "x": -6,
      "y": 3,
      "z": -9,
      "name": "Empty"
    },
    {
      "x": -6,
      "y": 4,
      "z": -9,
      "name": "Empty"
    },
    {
      "x": -6,
      "y": 0,
      "z": -8,
      "name": "Rock_Shale"
    },
    {
      "x": -6,
      "y": 1,
      "z": -8,
      "name": "Empty"
    },
    {
      "x": -6,
      "y": 2,
      "z": -8,
      "name": "Empty"
    },
    {
      "x": -6,
      "y": 3,
      "z": -8,
      "name": "Empty"
    },
    {
      "x": -6,
      "y": 4,
      "z": -8,
      "name": "Empty"
    },
    {
      "x": -6,
      "y": 0,
      "z": -7,
      "name": "Rock_Shale"
    },
    {
      "x": -6,
      "y": 1,
      "z": -7,
      "name": "Empty"
    },
    {
      "x": -6,
      "y": 2,
      "z": -7,
      "name": "Empty"
    },
    {
      "x": -6,
      "y": 3,
      "z": -7,
      "name": "Empty"
    },
    {
      "x": -6,
      "y": 4,
      "z": -7,
      "name": "Empty"
    },
    {
      "x": -6,
      "y": 0,
      "z": -6,
      "name": "Soil_Dirt_Cold"
    },
    {
      "x": -6,
      "y": 1,
      "z": -6,
      "name": "Furniture_Ancient_Crate",
      "rotation": 2
    },
    {
      "x": -6,
      "y": 2,
      "z": -6,
      "name": "Empty"
    },
    {
      "x": -6,
      "y": 3,
      "z": -6,
      "name": "Empty"
    },
    {
      "x": -6,
      "y": 4,
      "z": -6,
      "name": "Rock_Shale_Brick_Stairs",
      "rotation": 8
    },
    {
      "x": -6,
      "y": 0,
      "z": -5,
      "name": "Rock_Shale_Brick_Smooth"
    },
    {
      "x": -6,
      "y": 1,
      "z": -5,
      "name": "Rock_Shale_Brick_Pillar_Base"
    },
    {
      "x": -6,
      "y": 2,
      "z": -5,
      "name": "Rock_Shale_Brick_Pillar_Middle"
    },
    {
      "x": -6,
      "y": 3,
      "z": -5,
      "name": "Rock_Shale_Brick_Pillar_Base",
      "rotation": 8
    },
    {
      "x": -6,
      "y": 4,
      "z": -5,
      "name": "Rock_Shale_Brick"
    },
    {
      "x": -6,
      "y": 0,
      "z": -4,
      "name": "Rock_Shale_Brick_Smooth"
    },
    {
      "x": -6,
      "y": 1,
      "z": -4,
      "name": "Rock_Shale_Brick"
    },
    {
      "x": -6,
      "y": 2,
      "z": -4,
      "name": "Rock_Shale_Brick"
    },
    {
      "x": -6,
      "y": 3,
      "z": -4,
      "name": "Rock_Shale_Brick"
    },
    {
      "x": -6,
      "y": 4,
      "z": -4,
      "name": "Rock_Shale_Brick"
    },
    {
      "x": -5,
      "y": 0,
      "z": -14,
      "name": "Rock_Shale_Brick_Smooth"
    },
    {
      "x": -5,
      "y": 1,
      "z": -14,
      "name": "Rock_Shale"
    },
    {
      "x": -5,
      "y": 2,
      "z": -14,
      "name": "Rock_Shale"
    },
    {
      "x": -5,
      "y": 3,
      "z": -14,
      "name": "Rock_Shale"
    },
    {
      "x": -5,
      "y": 4,
      "z": -14,
      "name": "Rock_Shale"
    },
    {
      "x": -5,
      "y": 0,
      "z": -13,
      "name": "Rock_Shale_Brick_Smooth"
    },
    {
      "x": -5,
      "y": 1,
      "z": -13,
      "name": "Rock_Basalt_Brick"
    },
    {
      "x": -5,
      "y": 2,
      "z": -13,
      "name": "Rock_Basalt_Brick"
    },
    {
      "x": -5,
      "y": 3,
      "z": -13,
      "name": "Rock_Basalt_Brick"
    },
    {
      "x": -5,
      "y": 4,
      "z": -13,
      "name": "Rock_Basalt_Brick"
    },
    {
      "x": -5,
      "y": 0,
      "z": -12,
      "name": "Rock_Basalt"
    },
    {
      "x": -5,
      "y": 1,
      "z": -12,
      "name": "Rock_Basalt"
    },
    {
      "x": -5,
      "y": 2,
      "z": -12,
      "name": "Rock_Basalt"
    },
    {
      "x": -5,
      "y": 3,
      "z": -12,
      "name": "Rock_Basalt_Brick"
    },
    {
      "x": -5,
      "y": 4,
      "z": -12,
      "name": "Rock_Basalt_Brick"
    },
    {
      "x": -5,
      "y": 0,
      "z": -11,
      "name": "Rock_Basalt"
    },
    {
      "x": -5,
      "y": 1,
      "z": -11,
      "name": "Furniture_Ancient_Barrel"
    },
    {
      "x": -5,
      "y": 2,
      "z": -11,
      "name": "Empty"
    },
    {
      "x": -5,
      "y": 3,
      "z": -11,
      "name": "Rock_Basalt_Brick_Half",
      "rotation": 8
    },
    {
      "x": -5,
      "y": 4,
      "z": -11,
      "name": "Rock_Basalt_Brick"
    },
    {
      "x": -5,
      "y": 0,
      "z": -10,
      "name": "Rock_Shale"
    },
    {
      "x": -5,
      "y": 1,
      "z": -10,
      "name": "Empty"
    },
    {
      "x": -5,
      "y": 2,
      "z": -10,
      "name": "Empty"
    },
    {
      "x": -5,
      "y": 3,
      "z": -10,
      "name": "Empty"
    },
    {
      "x": -5,
      "y": 4,
      "z": -10,
      "name": "Rock_Basalt_Brick"
    },
    {
      "x": -5,
      "y": 0,
      "z": -9,
      "name": "Rock_Shale"
    },
    {
      "x": -5,
      "y": 1,
      "z": -9,
      "name": "Empty"
    },
    {
      "x": -5,
      "y": 2,
      "z": -9,
      "name": "Empty"
    },
    {
      "x": -5,
      "y": 3,
      "z": -9,
      "name": "Empty"
    },
    {
      "x": -5,
      "y": 4,
      "z": -9,
      "name": "Rock_Basalt_Brick"
    },
    {
      "x": -5,
      "y": 0,
      "z": -8,
      "name": "Rock_Shale"
    },
    {
      "x": -5,
      "y": 1,
      "z": -8,
      "name": "Empty"
    },
    {
      "x": -5,
      "y": 2,
      "z": -8,
      "name": "Empty"
    },
    {
      "x": -5,
      "y": 3,
      "z": -8,
      "name": "Empty"
    },
    {
      "x": -5,
      "y": 4,
      "z": -8,
      "name": "Rock_Basalt_Brick"
    },
    {
      "x": -5,
      "y": 0,
      "z": -7,
      "name": "Soil_Dirt_Cold"
    },
    {
      "x": -5,
      "y": 1,
      "z": -7,
      "name": "Empty"
    },
    {
      "x": -5,
      "y": 2,
      "z": -7,
      "name": "Empty"
    },
    {
      "x": -5,
      "y": 3,
      "z": -7,
      "name": "Rock_Basalt_Brick_Half",
      "rotation": 8
    },
    {
      "x": -5,
      "y": 4,
      "z": -7,
      "name": "Rock_Basalt_Brick"
    },
    {
      "x": -5,
      "y": 0,
      "z": -6,
      "name": "Soil_Dirt_Cold"
    },
    {
      "x": -5,
      "y": 1,
      "z": -6,
      "name": "Plant_Bush_Dead_Twisted"
    },
    {
      "x": -5,
      "y": 2,
      "z": -6,
      "name": "Empty"
    },
    {
      "x": -5,
      "y": 3,
      "z": -6,
      "name": "Rock_Basalt_Brick"
    },
    {
      "x": -5,
      "y": 4,
      "z": -6,
      "name": "Rock_Basalt_Brick"
    },
    {
      "x": -5,
      "y": 0,
      "z": -5,
      "name": "Rock_Shale_Brick_Smooth"
    },
    {
      "x": -5,
      "y": 1,
      "z": -5,
      "name": "Rock_Basalt_Brick"
    },
    {
      "x": -5,
      "y": 2,
      "z": -5,
      "name": "Rock_Basalt_Brick"
    },
    {
      "x": -5,
      "y": 3,
      "z": -5,
      "name": "Rock_Basalt_Brick"
    },
    {
      "x": -5,
      "y": 4,
      "z": -5,
      "name": "Rock_Basalt_Brick"
    },
    {
      "x": -5,
      "y": 0,
      "z": -4,
      "name": "Rock_Shale_Brick_Smooth"
    },
    {
      "x": -5,
      "y": 1,
      "z": -4,
      "name": "Rock_Shale"
    },
    {
      "x": -5,
      "y": 2,
      "z": -4,
      "name": "Rock_Shale"
    },
    {
      "x": -5,
      "y": 3,
      "z": -4,
      "name": "Rock_Shale"
    },
    {
      "x": -5,
      "y": 4,
      "z": -4,
      "name": "Rock_Shale"
    },
    {
      "x": -5,
      "y": 0,
      "z": -3,
      "name": "Rock_Shale_Brick_Smooth"
    },
    {
      "x": -5,
      "y": 1,
      "z": -3,
      "name": "Rock_Shale_Brick"
    },
    {
      "x": -5,
      "y": 2,
      "z": -3,
      "name": "Rock_Shale_Brick"
    },
    {
      "x": -5,
      "y": 3,
      "z": -3,
      "name": "Rock_Shale_Brick"
    },
    {
      "x": -5,
      "y": 4,
      "z": -3,
      "name": "Rock_Shale_Brick"
    },
    {
      "x": -5,
      "y": 0,
      "z": -2,
      "name": "Rock_Shale_Brick_Smooth"
    },
    {
      "x": -5,
      "y": 1,
      "z": -2,
      "name": "Rock_Shale_Brick"
    },
    {
      "x": -5,
      "y": 2,
      "z": -2,
      "name": "Rock_Shale_Brick"
    },
    {
      "x": -5,
      "y": 3,
      "z": -2,
      "name": "Rock_Basalt"
    },
    {
      "x": -5,
      "y": 4,
      "z": -2,
      "name": "Rock_Shale_Brick"
    },
    {
      "x": -5,
      "y": 0,
      "z": -1,
      "name": "Rock_Shale_Brick_Smooth"
    },
    {
      "x": -5,
      "y": 1,
      "z": -1,
      "name": "Rock_Shale_Brick"
    },
    {
      "x": -5,
      "y": 2,
      "z": -1,
      "name": "Rock_Shale_Brick"
    },
    {
      "x": -5,
      "y": 3,
      "z": -1,
      "name": "Rock_Basalt"
    },
    {
      "x": -5,
      "y": 4,
      "z": -1,
      "name": "Rock_Shale_Brick"
    },
    {
      "x": -5,
      "y": 0,
      "z": 0,
      "name": "Rock_Shale_Brick_Smooth"
    },
    {
      "x": -5,
      "y": 1,
      "z": 0,
      "name": "Rock_Shale_Brick"
    },
    {
      "x": -5,
      "y": 2,
      "z": 0,
      "name": "Rock_Shale_Brick"
    },
    {
      "x": -5,
      "y": 3,
      "z": 0,
      "name": "Rock_Shale_Brick"
    },
    {
      "x": -5,
      "y": 4,
      "z": 0,
      "name": "Rock_Shale_Brick"
    },
    {
      "x": -4,
      "y": 0,
      "z": -14,
      "name": "Rock_Shale_Brick_Smooth"
    },
    {
      "x": -4,
      "y": 1,
      "z": -14,
      "name": "Rock_Shale"
    },
    {
      "x": -4,
      "y": 2,
      "z": -14,
      "name": "Rock_Shale"
    },
    {
      "x": -4,
      "y": 3,
      "z": -14,
      "name": "Rock_Shale"
    },
    {
      "x": -4,
      "y": 4,
      "z": -14,
      "name": "Rock_Shale"
    },
    {
      "x": -4,
      "y": 0,
      "z": -13,
      "name": "Rock_Shale_Brick_Smooth"
    },
    {
      "x": -4,
      "y": 1,
      "z": -13,
      "name": "Rock_Basalt_Brick"
    },
    {
      "x": -4,
      "y": 2,
      "z": -13,
      "name": "Rock_Basalt_Brick"
    },
    {
      "x": -4,
      "y": 3,
      "z": -13,
      "name": "Rock_Basalt_Brick"
    },
    {
      "x": -4,
      "y": 4,
      "z": -13,
      "name": "Rock_Basalt_Brick"
    },
    {
      "x": -4,
      "y": 0,
      "z": -12,
      "name": "Rock_Basalt"
    },
    {
      "x": -4,
      "y": 1,
      "z": -12,
      "name": "Empty"
    },
    {
      "x": -4,
      "y": 2,
      "z": -12,
      "name": "Empty"
    },
    {
      "x": -4,
      "y": 3,
      "z": -12,
      "name": "Rock_Basalt_Brick"
    },
    {
      "x": -4,
      "y": 4,
      "z": -12,
      "name": "Rock_Basalt_Brick"
    },
    {
      "x": -4,
      "y": 0,
      "z": -11,
      "name": "Rock_Basalt"
    },
    {
      "x": -4,
      "y": 1,
      "z": -11,
      "name": "Empty"
    },
    {
      "x": -4,
      "y": 2,
      "z": -11,
      "name": "Empty"
    },
    {
      "x": -4,
      "y": 3,
      "z": -11,
      "name": "Rock_Basalt_Brick_Half",
      "rotation": 8
    },
    {
      "x": -4,
      "y": 4,
      "z": -11,
      "name": "Rock_Basalt_Brick"
    },
    {
      "x": -4,
      "y": 0,
      "z": -10,
      "name": "Rock_Shale_Brick_Smooth"
    },
    {
      "x": -4,
      "y": 1,
      "z": -10,
      "name": "Empty"
    },
    {
      "x": -4,
      "y": 2,
      "z": -10,
      "name": "Empty"
    },
    {
      "x": -4,
      "y": 3,
      "z": -10,
      "name": "Empty"
    },
    {
      "x": -4,
      "y": 4,
      "z": -10,
      "name": "Rock_Basalt_Brick"
    },
    {
      "x": -4,
      "y": 0,
      "z": -9,
      "name": "Rock_Shale_Brick_Smooth"
    },
    {
      "x": -4,
      "y": 1,
      "z": -9,
      "name": "Empty"
    },
    {
      "x": -4,
      "y": 2,
      "z": -9,
      "name": "Empty"
    },
    {
      "x": -4,
      "y": 3,
      "z": -9,
      "name": "Empty"
    },
    {
      "x": -4,
      "y": 4,
      "z": -9,
      "name": "Rock_Basalt_Brick"
    },
    {
      "x": -4,
      "y": 0,
      "z": -8,
      "name": "Rock_Shale_Brick_Smooth"
    },
    {
      "x": -4,
      "y": 1,
      "z": -8,
      "name": "Empty"
    },
    {
      "x": -4,
      "y": 2,
      "z": -8,
      "name": "Empty"
    },
    {
      "x": -4,
      "y": 3,
      "z": -8,
      "name": "Empty"
    },
    {
      "x": -4,
      "y": 4,
      "z": -8,
      "name": "Rock_Basalt_Brick"
    },
    {
      "x": -4,
      "y": 0,
      "z": -7,
      "name": "Soil_Dirt_Cold"
    },
    {
      "x": -4,
      "y": 1,
      "z": -7,
      "name": "Empty"
    },
    {
      "x": -4,
      "y": 2,
      "z": -7,
      "name": "Empty"
    },
    {
      "x": -4,
      "y": 3,
      "z": -7,
      "name": "Rock_Basalt_Brick_Half",
      "rotation": 8
    },
    {
      "x": -4,
      "y": 4,
      "z": -7,
      "name": "Rock_Basalt_Brick"
    },
    {
      "x": -4,
      "y": 0,
      "z": -6,
      "name": "Soil_Dirt_Cold"
    },
    {
      "x": -4,
      "y": 1,
      "z": -6,
      "name": "Empty"
    },
    {
      "x": -4,
      "y": 2,
      "z": -6,
      "name": "Empty"
    },
    {
      "x": -4,
      "y": 3,
      "z": -6,
      "name": "Rock_Basalt_Brick"
    },
    {
      "x": -4,
      "y": 4,
      "z": -6,
      "name": "Rock_Basalt_Brick"
    },
    {
      "x": -4,
      "y": 0,
      "z": -5,
      "name": "Rock_Shale_Brick_Smooth"
    },
    {
      "x": -4,
      "y": 1,
      "z": -5,
      "name": "Rock_Basalt_Brick"
    },
    {
      "x": -4,
      "y": 2,
      "z": -5,
      "name": "Rock_Basalt_Brick"
    },
    {
      "x": -4,
      "y": 3,
      "z": -5,
      "name": "Rock_Basalt_Brick"
    },
    {
      "x": -4,
      "y": 4,
      "z": -5,
      "name": "Rock_Basalt_Brick"
    },
    {
      "x": -4,
      "y": 0,
      "z": -4,
      "name": "Rock_Shale_Brick_Smooth"
    },
    {
      "x": -4,
      "y": 1,
      "z": -4,
      "name": "Rock_Basalt_Brick"
    },
    {
      "x": -4,
      "y": 2,
      "z": -4,
      "name": "Rock_Basalt_Brick"
    },
    {
      "x": -4,
      "y": 3,
      "z": -4,
      "name": "Rock_Basalt_Brick"
    },
    {
      "x": -4,
      "y": 4,
      "z": -4,
      "name": "Rock_Basalt_Brick"
    },
    {
      "x": -4,
      "y": 0,
      "z": -3,
      "name": "Rock_Shale_Brick_Smooth"
    },
    {
      "x": -4,
      "y": 1,
      "z": -3,
      "name": "Rock_Shale_Brick_Pillar_Base"
    },
    {
      "x": -4,
      "y": 2,
      "z": -3,
      "name": "Rock_Shale_Brick_Pillar_Middle"
    },
    {
      "x": -4,
      "y": 3,
      "z": -3,
      "name": "Rock_Shale_Brick_Pillar_Base",
      "rotation": 8
    },
    {
      "x": -4,
      "y": 4,
      "z": -3,
      "name": "Rock_Shale_Brick"
    },
    {
      "x": -4,
      "y": 0,
      "z": -2,
      "name": "Rock_Shale_Brick_Smooth"
    },
    {
      "x": -4,
      "y": 1,
      "z": -2,
      "name": "Rock_Shale_Brick_Stairs",
      "rotation": 11
    },
    {
      "x": -4,
      "y": 2,
      "z": -2,
      "name": "Deco_Bone_Skulls"
    },
    {
      "x": -4,
      "y": 3,
      "z": -2,
      "name": "Empty"
    },
    {
      "x": -4,
      "y": 4,
      "z": -2,
      "name": "Rock_Shale_Brick"
    },
    {
      "x": -4,
      "y": 0,
      "z": -1,
      "name": "Rock_Shale_Brick_Smooth"
    },
    {
      "x": -4,
      "y": 1,
      "z": -1,
      "name": "Rock_Shale_Brick_Stairs",
      "rotation": 11
    },
    {
      "x": -4,
      "y": 2,
      "z": -1,
      "name": "Deco_Bone_Pile"
    },
    {
      "x": -4,
      "y": 3,
      "z": -1,
      "name": "Empty"
    },
    {
      "x": -4,
      "y": 4,
      "z": -1,
      "name": "Rock_Shale_Brick"
    },
    {
      "x": -4,
      "y": 0,
      "z": 0,
      "name": "Rock_Shale_Brick_Smooth"
    },
    {
      "x": -4,
      "y": 1,
      "z": 0,
      "name": "Rock_Shale_Brick_Pillar_Base"
    },
    {
      "x": -4,
      "y": 2,
      "z": 0,
      "name": "Rock_Shale_Brick_Pillar_Middle"
    },
    {
      "x": -4,
      "y": 3,
      "z": 0,
      "name": "Rock_Shale_Brick_Pillar_Base",
      "rotation": 8
    },
    {
      "x": -4,
      "y": 4,
      "z": 0,
      "name": "Rock_Shale_Brick"
    },
    {
      "x": -3,
      "y": 0,
      "z": -14,
      "name": "Rock_Shale_Brick_Smooth"
    },
    {
      "x": -3,
      "y": 1,
      "z": -14,
      "name": "Rock_Shale_Brick"
    },
    {
      "x": -3,
      "y": 2,
      "z": -14,
      "name": "Rock_Shale_Brick"
    },
    {
      "x": -3,
      "y": 3,
      "z": -14,
      "name": "Rock_Shale_Brick"
    },
    {
      "x": -3,
      "y": 4,
      "z": -14,
      "name": "Rock_Shale_Brick"
    },
    {
      "x": -3,
      "y": 0,
      "z": -13,
      "name": "Rock_Shale_Brick_Smooth"
    },
    {
      "x": -3,
      "y": 1,
      "z": -13,
      "name": "Rock_Shale_Brick_Pillar_Base"
    },
    {
      "x": -3,
      "y": 2,
      "z": -13,
      "name": "Rock_Shale_Brick_Pillar_Middle"
    },
    {
      "x": -3,
      "y": 3,
      "z": -13,
      "name": "Rock_Shale_Brick_Pillar_Base",
      "rotation": 8
    },
    {
      "x": -3,
      "y": 4,
      "z": -13,
      "name": "Rock_Shale_Brick"
    },
    {
      "x": -3,
      "y": 0,
      "z": -12,
      "name": "Soil_Dirt_Cold"
    },
    {
      "x": -3,
      "y": 1,
      "z": -12,
      "name": "Rock_Shale_Brick_Beam"
    },
    {
      "x": -3,
      "y": 2,
      "z": -12,
      "name": "Furniture_Human_Ruins_Torch"
    },
    {
      "x": -3,
      "y": 3,
      "z": -12,
      "name": "Empty"
    },
    {
      "x": -3,
      "y": 4,
      "z": -12,
      "name": "Rock_Shale_Brick_Stairs",
      "rotation": 10
    },
    {
      "x": -3,
      "y": 0,
      "z": -11,
      "name": "Soil_Dirt_Cold"
    },
    {
      "x": -3,
      "y": 1,
      "z": -11,
      "name": "*Plant_Crop_Berry_Winter_Block_State_Definitions_StageFinal"
    },
    {
      "x": -3,
      "y": 2,
      "z": -11,
      "name": "Empty"
    },
    {
      "x": -3,
      "y": 3,
      "z": -11,
      "name": "Empty"
    },
    {
      "x": -3,
      "y": 4,
      "z": -11,
      "name": "Plant_Bush_Dead_Hanging"
    },
    {
      "x": -3,
      "y": 0,
      "z": -10,
      "name": "Rock_Shale"
    },
    {
      "x": -3,
      "y": 1,
      "z": -10,
      "name": "Empty"
    },
    {
      "x": -3,
      "y": 2,
      "z": -10,
      "name": "Empty"
    },
    {
      "x": -3,
      "y": 3,
      "z": -10,
      "name": "Empty"
    },
    {
      "x": -3,
      "y": 4,
      "z": -10,
      "name": "Empty"
    },
    {
      "x": -3,
      "y": 0,
      "z": -9,
      "name": "Rock_Shale"
    },
    {
      "x": -3,
      "y": 1,
      "z": -9,
      "name": "Empty"
    },
    {
      "x": -3,
      "y": 2,
      "z": -9,
      "name": "Empty"
    },
    {
      "x": -3,
      "y": 3,
      "z": -9,
      "name": "Empty"
    },
    {
      "x": -3,
      "y": 4,
      "z": -9,
      "name": "Empty"
    },
    {
      "x": -3,
      "y": 0,
      "z": -8,
      "name": "Rock_Shale"
    },
    {
      "x": -3,
      "y": 1,
      "z": -8,
      "name": "Empty"
    },
    {
      "x": -3,
      "y": 2,
      "z": -8,
      "name": "Empty"
    },
    {
      "x": -3,
      "y": 3,
      "z": -8,
      "name": "Empty"
    },
    {
      "x": -3,
      "y": 4,
      "z": -8,
      "name": "Empty"
    },
    {
      "x": -3,
      "y": 0,
      "z": -7,
      "name": "Rock_Shale"
    },
    {
      "x": -3,
      "y": 1,
      "z": -7,
      "name": "Empty"
    },
    {
      "x": -3,
      "y": 2,
      "z": -7,
      "name": "Empty"
    },
    {
      "x": -3,
      "y": 3,
      "z": -7,
      "name": "Empty"
    },
    {
      "x": -3,
      "y": 4,
      "z": -7,
      "name": "Empty"
    },
    {
      "x": -3,
      "y": 0,
      "z": -6,
      "name": "Rock_Shale"
    },
    {
      "x": -3,
      "y": 1,
      "z": -6,
      "name": "Empty"
    },
    {
      "x": -3,
      "y": 2,
      "z": -6,
      "name": "Empty"
    },
    {
      "x": -3,
      "y": 3,
      "z": -6,
      "name": "Empty"
    },
    {
      "x": -3,
      "y": 4,
      "z": -6,
      "name": "Empty"
    },
    {
      "x": -3,
      "y": 0,
      "z": -5,
      "name": "Rock_Shale_Brick_Smooth"
    },
    {
      "x": -3,
      "y": 1,
      "z": -5,
      "name": "Empty"
    },
    {
      "x": -3,
      "y": 2,
      "z": -5,
      "name": "Empty"
    },
    {
      "x": -3,
      "y": 3,
      "z": -5,
      "name": "Rock_Basalt_Brick"
    },
    {
      "x": -3,
      "y": 4,
      "z": -5,
      "name": "Rock_Basalt_Brick"
    },
    {
      "x": -3,
      "y": 0,
      "z": -4,
      "name": "Soil_Dirt_Cold"
    },
    {
      "x": -3,
      "y": 1,
      "z": -4,
      "name": "*Plant_Crop_Berry_Winter_Block_State_Definitions_StageFinal"
    },
    {
      "x": -3,
      "y": 2,
      "z": -4,
      "name": "Empty"
    },
    {
      "x": -3,
      "y": 3,
      "z": -4,
      "name": "Rock_Basalt_Brick"
    },
    {
      "x": -3,
      "y": 4,
      "z": -4,
      "name": "Rock_Basalt_Brick"
    },
    {
      "x": -3,
      "y": 0,
      "z": -3,
      "name": "Soil_Dirt_Cold"
    },
    {
      "x": -3,
      "y": 1,
      "z": -3,
      "name": "Furniture_Ancient_Barrel"
    },
    {
      "x": -3,
      "y": 2,
      "z": -3,
      "name": "Empty"
    },
    {
      "x": -3,
      "y": 3,
      "z": -3,
      "name": "Empty"
    },
    {
      "x": -3,
      "y": 4,
      "z": -3,
      "name": "Rock_Shale_Brick_Stairs",
      "rotation": 11
    },
    {
      "x": -3,
      "y": 0,
      "z": -2,
      "name": "Soil_Dirt_Cold"
    },
    {
      "x": -3,
      "y": 1,
      "z": -2,
      "name": "Deco_Bone_Skulls"
    },
    {
      "x": -3,
      "y": 2,
      "z": -2,
      "name": "Empty"
    },
    {
      "x": -3,
      "y": 3,
      "z": -2,
      "name": "Empty"
    },
    {
      "x": -3,
      "y": 4,
      "z": -2,
      "name": "Empty"
    },
    {
      "x": -3,
      "y": 0,
      "z": -1,
      "name": "Soil_Dirt_Cold"
    },
    {
      "x": -3,
      "y": 1,
      "z": -1,
      "name": "Empty"
    },
    {
      "x": -3,
      "y": 2,
      "z": -1,
      "name": "Empty"
    },
    {
      "x": -3,
      "y": 3,
      "z": -1,
      "name": "Empty"
    },
    {
      "x": -3,
      "y": 4,
      "z": -1,
      "name": "Empty"
    },
    {
      "x": -3,
      "y": 0,
      "z": 0,
      "name": "Rock_Shale_Brick_Smooth"
    },
    {
      "x": -3,
      "y": 1,
      "z": 0,
      "name": "Empty"
    },
    {
      "x": -3,
      "y": 2,
      "z": 0,
      "name": "Empty"
    },
    {
      "x": -3,
      "y": 3,
      "z": 0,
      "name": "Empty"
    },
    {
      "x": -3,
      "y": 4,
      "z": 0,
      "name": "Rock_Shale_Brick_Stairs",
      "rotation": 11
    },
    {
      "x": -2,
      "y": 0,
      "z": -14,
      "name": "Rock_Shale_Brick_Smooth"
    },
    {
      "x": -2,
      "y": 1,
      "z": -14,
      "name": "Rock_Shale_Brick"
    },
    {
      "x": -2,
      "y": 2,
      "z": -14,
      "name": "Rock_Shale_Brick"
    },
    {
      "x": -2,
      "y": 3,
      "z": -14,
      "name": "Rock_Shale_Brick"
    },
    {
      "x": -2,
      "y": 4,
      "z": -14,
      "name": "Rock_Shale_Brick"
    },
    {
      "x": -2,
      "y": 0,
      "z": -13,
      "name": "Rock_Shale_Brick_Smooth"
    },
    {
      "x": -2,
      "y": 1,
      "z": -13,
      "name": "Rock_Shale_Brick_Stairs",
      "rotation": 10
    },
    {
      "x": -2,
      "y": 2,
      "z": -13,
      "name": "Deco_Bone_Skulls"
    },
    {
      "x": -2,
      "y": 3,
      "z": -13,
      "name": "Empty"
    },
    {
      "x": -2,
      "y": 4,
      "z": -13,
      "name": "Rock_Shale_Brick"
    },
    {
      "x": -2,
      "y": 0,
      "z": -12,
      "name": "Soil_Dirt_Cold"
    },
    {
      "x": -2,
      "y": 1,
      "z": -12,
      "name": "Deco_Bone_Pile"
    },
    {
      "x": -2,
      "y": 2,
      "z": -12,
      "name": "Empty"
    },
    {
      "x": -2,
      "y": 3,
      "z": -12,
      "name": "Empty"
    },
    {
      "x": -2,
      "y": 4,
      "z": -12,
      "name": "Empty"
    },
    {
      "x": -2,
      "y": 0,
      "z": -11,
      "name": "Soil_Dirt_Cold"
    },
    {
      "x": -2,
      "y": 1,
      "z": -11,
      "name": "Empty"
    },
    {
      "x": -2,
      "y": 2,
      "z": -11,
      "name": "Empty"
    },
    {
      "x": -2,
      "y": 3,
      "z": -11,
      "name": "Empty"
    },
    {
      "x": -2,
      "y": 4,
      "z": -11,
      "name": "Empty"
    },
    {
      "x": -2,
      "y": 0,
      "z": -10,
      "name": "Soil_Dirt_Cold"
    },
    {
      "x": -2,
      "y": 1,
      "z": -10,
      "name": "Empty"
    },
    {
      "x": -2,
      "y": 2,
      "z": -10,
      "name": "Empty"
    },
    {
      "x": -2,
      "y": 3,
      "z": -10,
      "name": "Empty"
    },
    {
      "x": -2,
      "y": 4,
      "z": -10,
      "name": "Empty"
    },
    {
      "x": -2,
      "y": 0,
      "z": -9,
      "name": "Rock_Shale"
    },
    {
      "x": -2,
      "y": 1,
      "z": -9,
      "name": "Empty"
    },
    {
      "x": -2,
      "y": 2,
      "z": -9,
      "name": "Empty"
    },
    {
      "x": -2,
      "y": 3,
      "z": -9,
      "name": "Empty"
    },
    {
      "x": -2,
      "y": 4,
      "z": -9,
      "name": "Empty"
    },
    {
      "x": -2,
      "y": 0,
      "z": -8,
      "name": "Rock_Shale"
    },
    {
      "x": -2,
      "y": 1,
      "z": -8,
      "name": "Empty"
    },
    {
      "x": -2,
      "y": 2,
      "z": -8,
      "name": "Empty"
    },
    {
      "x": -2,
      "y": 3,
      "z": -8,
      "name": "Empty"
    },
    {
      "x": -2,
      "y": 4,
      "z": -8,
      "name": "Empty"
    },
    {
      "x": -2,
      "y": 0,
      "z": -7,
      "name": "Rock_Shale"
    },
    {
      "x": -2,
      "y": 1,
      "z": -7,
      "name": "Empty"
    },
    {
      "x": -2,
      "y": 2,
      "z": -7,
      "name": "Empty"
    },
    {
      "x": -2,
      "y": 3,
      "z": -7,
      "name": "Empty"
    },
    {
      "x": -2,
      "y": 4,
      "z": -7,
      "name": "Empty"
    },
    {
      "x": -2,
      "y": 0,
      "z": -6,
      "name": "Rock_Shale"
    },
    {
      "x": -2,
      "y": 1,
      "z": -6,
      "name": "Empty"
    },
    {
      "x": -2,
      "y": 2,
      "z": -6,
      "name": "Empty"
    },
    {
      "x": -2,
      "y": 3,
      "z": -6,
      "name": "Empty"
    },
    {
      "x": -2,
      "y": 4,
      "z": -6,
      "name": "Empty"
    },
    {
      "x": -2,
      "y": 0,
      "z": -5,
      "name": "Rock_Shale_Brick_Smooth"
    },
    {
      "x": -2,
      "y": 1,
      "z": -5,
      "name": "Empty"
    },
    {
      "x": -2,
      "y": 2,
      "z": -5,
      "name": "Empty"
    },
    {
      "x": -2,
      "y": 3,
      "z": -5,
      "name": "Rock_Basalt_Brick_Half",
      "rotation": 8
    },
    {
      "x": -2,
      "y": 4,
      "z": -5,
      "name": "Rock_Basalt_Brick"
    },
    {
      "x": -2,
      "y": 0,
      "z": -4,
      "name": "Rock_Basalt"
    },
    {
      "x": -2,
      "y": 1,
      "z": -4,
      "name": "Empty"
    },
    {
      "x": -2,
      "y": 2,
      "z": -4,
      "name": "Empty"
    },
    {
      "x": -2,
      "y": 3,
      "z": -4,
      "name": "Rock_Basalt_Brick_Half",
      "rotation": 8
    },
    {
      "x": -2,
      "y": 4,
      "z": -4,
      "name": "Rock_Basalt_Brick"
    },
    {
      "x": -2,
      "y": 0,
      "z": -3,
      "name": "Rock_Basalt"
    },
    {
      "x": -2,
      "y": 1,
      "z": -3,
      "name": "Rubble_Basalt"
    },
    {
      "x": -2,
      "y": 2,
      "z": -3,
      "name": "Empty"
    },
    {
      "x": -2,
      "y": 3,
      "z": -3,
      "name": "Empty"
    },
    {
      "x": -2,
      "y": 4,
      "z": -3,
      "name": "Plant_Bush_Dead_Hanging"
    },
    {
      "x": -2,
      "y": 0,
      "z": -2,
      "name": "Soil_Dirt_Cold"
    },
    {
      "x": -2,
      "y": 1,
      "z": -2,
      "name": "Empty"
    },
    {
      "x": -2,
      "y": 2,
      "z": -2,
      "name": "Empty"
    },
    {
      "x": -2,
      "y": 3,
      "z": -2,
      "name": "Empty"
    },
    {
      "x": -2,
      "y": 4,
      "z": -2,
      "name": "Empty"
    },
    {
      "x": -2,
      "y": 0,
      "z": -1,
      "name": "Soil_Dirt_Cold"
    },
    {
      "x": -2,
      "y": 1,
      "z": -1,
      "name": "Empty"
    },
    {
      "x": -2,
      "y": 2,
      "z": -1,
      "name": "Empty"
    },
    {
      "x": -2,
      "y": 3,
      "z": -1,
      "name": "Empty"
    },
    {
      "x": -2,
      "y": 4,
      "z": -1,
      "name": "Empty"
    },
    {
      "x": -2,
      "y": 0,
      "z": 0,
      "name": "Rock_Shale_Brick_Smooth"
    },
    {
      "x": -2,
      "y": 1,
      "z": 0,
      "name": "Empty"
    },
    {
      "x": -2,
      "y": 2,
      "z": 0,
      "name": "Empty"
    },
    {
      "x": -2,
      "y": 3,
      "z": 0,
      "name": "Empty"
    },
    {
      "x": -2,
      "y": 4,
      "z": 0,
      "name": "Empty"
    },
    {
      "x": -1,
      "y": 0,
      "z": -14,
      "name": "Rock_Shale_Brick_Smooth"
    },
    {
      "x": -1,
      "y": 1,
      "z": -14,
      "name": "Rock_Shale"
    },
    {
      "x": -1,
      "y": 2,
      "z": -14,
      "name": "Rock_Shale"
    },
    {
      "x": -1,
      "y": 3,
      "z": -14,
      "name": "Rock_Shale"
    },
    {
      "x": -1,
      "y": 4,
      "z": -14,
      "name": "Rock_Shale"
    },
    {
      "x": -1,
      "y": 0,
      "z": -13,
      "name": "Rock_Shale_Brick_Smooth"
    },
    {
      "x": -1,
      "y": 1,
      "z": -13,
      "name": "Rock_Shale_Brick_Stairs",
      "rotation": 10
    },
    {
      "x": -1,
      "y": 2,
      "z": -13,
      "name": "Deco_Bone_Pile"
    },
    {
      "x": -1,
      "y": 3,
      "z": -13,
      "name": "Empty"
    },
    {
      "x": -1,
      "y": 4,
      "z": -13,
      "name": "Rock_Shale_Brick"
    },
    {
      "x": -1,
      "y": 0,
      "z": -12,
      "name": "Soil_Dirt_Cold"
    },
    {
      "x": -1,
      "y": 1,
      "z": -12,
      "name": "Plant_Bush_Dead_Twisted"
    },
    {
      "x": -1,
      "y": 2,
      "z": -12,
      "name": "Empty"
    },
    {
      "x": -1,
      "y": 3,
      "z": -12,
      "name": "Empty"
    },
    {
      "x": -1,
      "y": 4,
      "z": -12,
      "name": "Empty"
    },
    {
      "x": -1,
      "y": 0,
      "z": -11,
      "name": "Soil_Dirt_Cold"
    },
    {
      "x": -1,
      "y": 1,
      "z": -11,
      "name": "Empty"
    },
    {
      "x": -1,
      "y": 2,
      "z": -11,
      "name": "Empty"
    },
    {
      "x": -1,
      "y": 3,
      "z": -11,
      "name": "Empty"
    },
    {
      "x": -1,
      "y": 4,
      "z": -11,
      "name": "Empty"
    },
    {
      "x": -1,
      "y": 0,
      "z": -10,
      "name": "Soil_Dirt_Cold"
    },
    {
      "x": -1,
      "y": 1,
      "z": -10,
      "name": "Empty"
    },
    {
      "x": -1,
      "y": 2,
      "z": -10,
      "name": "Empty"
    },
    {
      "x": -1,
      "y": 3,
      "z": -10,
      "name": "Empty"
    },
    {
      "x": -1,
      "y": 4,
      "z": -10,
      "name": "Empty"
    },
    {
      "x": -1,
      "y": 0,
      "z": -9,
      "name": "Rock_Shale"
    },
    {
      "x": -1,
      "y": 1,
      "z": -9,
      "name": "Empty"
    },
    {
      "x": -1,
      "y": 2,
      "z": -9,
      "name": "Empty"
    },
    {
      "x": -1,
      "y": 3,
      "z": -9,
      "name": "Empty"
    },
    {
      "x": -1,
      "y": 4,
      "z": -9,
      "name": "Empty"
    },
    {
      "x": -1,
      "y": 0,
      "z": -8,
      "name": "Rock_Shale"
    },
    {
      "x": -1,
      "y": 1,
      "z": -8,
      "name": "Empty"
    },
    {
      "x": -1,
      "y": 2,
      "z": -8,
      "name": "Empty"
    },
    {
      "x": -1,
      "y": 3,
      "z": -8,
      "name": "Empty"
    },
    {
      "x": -1,
      "y": 4,
      "z": -8,
      "name": "Empty"
    },
    {
      "x": -1,
      "y": 0,
      "z": -7,
      "name": "Rock_Shale"
    },
    {
      "x": -1,
      "y": 1,
      "z": -7,
      "name": "Empty"
    },
    {
      "x": -1,
      "y": 2,
      "z": -7,
      "name": "Empty"
    },
    {
      "x": -1,
      "y": 3,
      "z": -7,
      "name": "Empty"
    },
    {
      "x": -1,
      "y": 4,
      "z": -7,
      "name": "Empty"
    },
    {
      "x": -1,
      "y": 0,
      "z": -6,
      "name": "Rock_Shale"
    },
    {
      "x": -1,
      "y": 1,
      "z": -6,
      "name": "Empty"
    },
    {
      "x": -1,
      "y": 2,
      "z": -6,
      "name": "Empty"
    },
    {
      "x": -1,
      "y": 3,
      "z": -6,
      "name": "Empty"
    },
    {
      "x": -1,
      "y": 4,
      "z": -6,
      "name": "Empty"
    },
    {
      "x": -1,
      "y": 0,
      "z": -5,
      "name": "Rock_Shale_Brick_Smooth"
    },
    {
      "x": -1,
      "y": 1,
      "z": -5,
      "name": "Empty"
    },
    {
      "x": -1,
      "y": 2,
      "z": -5,
      "name": "Empty"
    },
    {
      "x": -1,
      "y": 3,
      "z": -5,
      "name": "Empty"
    },
    {
      "x": -1,
      "y": 4,
      "z": -5,
      "name": "Rock_Basalt_Brick"
    },
    {
      "x": -1,
      "y": 0,
      "z": -4,
      "name": "Rock_Shale"
    },
    {
      "x": -1,
      "y": 1,
      "z": -4,
      "name": "Empty"
    },
    {
      "x": -1,
      "y": 2,
      "z": -4,
      "name": "Empty"
    },
    {
      "x": -1,
      "y": 3,
      "z": -4,
      "name": "Empty"
    },
    {
      "x": -1,
      "y": 4,
      "z": -4,
      "name": "Rock_Basalt_Brick"
    },
    {
      "x": -1,
      "y": 0,
      "z": -3,
      "name": "Rock_Shale"
    },
    {
      "x": -1,
      "y": 1,
      "z": -3,
      "name": "Empty"
    },
    {
      "x": -1,
      "y": 2,
      "z": -3,
      "name": "Empty"
    },
    {
      "x": -1,
      "y": 3,
      "z": -3,
      "name": "Empty"
    },
    {
      "x": -1,
      "y": 4,
      "z": -3,
      "name": "Empty"
    },
    {
      "x": -1,
      "y": 0,
      "z": -2,
      "name": "Rock_Shale"
    },
    {
      "x": -1,
      "y": 1,
      "z": -2,
      "name": "Empty"
    },
    {
      "x": -1,
      "y": 2,
      "z": -2,
      "name": "Empty"
    },
    {
      "x": -1,
      "y": 3,
      "z": -2,
      "name": "Empty"
    },
    {
      "x": -1,
      "y": 4,
      "z": -2,
      "name": "Empty"
    },
    {
      "x": -1,
      "y": 0,
      "z": -1,
      "name": "Rock_Shale"
    },
    {
      "x": -1,
      "y": 1,
      "z": -1,
      "name": "Empty"
    },
    {
      "x": -1,
      "y": 2,
      "z": -1,
      "name": "Empty"
    },
    {
      "x": -1,
      "y": 3,
      "z": -1,
      "name": "Empty"
    },
    {
      "x": -1,
      "y": 4,
      "z": -1,
      "name": "Empty"
    },
    {
      "x": -1,
      "y": 0,
      "z": 0,
      "name": "Rock_Shale_Brick_Smooth"
    },
    {
      "x": -1,
      "y": 1,
      "z": 0,
      "name": "Empty"
    },
    {
      "x": -1,
      "y": 2,
      "z": 0,
      "name": "Empty"
    },
    {
      "x": -1,
      "y": 3,
      "z": 0,
      "name": "Empty"
    },
    {
      "x": -1,
      "y": 4,
      "z": 0,
      "name": "Empty"
    },
    {
      "x": 0,
      "y": 0,
      "z": -14,
      "name": "Rock_Shale_Brick_Smooth"
    },
    {
      "x": 0,
      "y": 1,
      "z": -14,
      "name": "Rock_Shale"
    },
    {
      "x": 0,
      "y": 2,
      "z": -14,
      "name": "Rock_Shale"
    },
    {
      "x": 0,
      "y": 3,
      "z": -14,
      "name": "Rock_Shale"
    },
    {
      "x": 0,
      "y": 4,
      "z": -14,
      "name": "Rock_Shale"
    },
    {
      "x": 0,
      "y": 0,
      "z": -13,
      "name": "Rock_Shale_Brick_Smooth"
    },
    {
      "x": 0,
      "y": 1,
      "z": -13,
      "name": "Rock_Shale_Brick_Stairs",
      "rotation": 10
    },
    {
      "x": 0,
      "y": 2,
      "z": -13,
      "name": "Deco_Bone_Skulls"
    },
    {
      "x": 0,
      "y": 3,
      "z": -13,
      "name": "Empty"
    },
    {
      "x": 0,
      "y": 4,
      "z": -13,
      "name": "Rock_Shale_Brick"
    },
    {
      "x": 0,
      "y": 0,
      "z": -12,
      "name": "Soil_Dirt_Cold"
    },
    {
      "x": 0,
      "y": 1,
      "z": -12,
      "name": "Empty"
    },
    {
      "x": 0,
      "y": 2,
      "z": -12,
      "name": "Empty"
    },
    {
      "x": 0,
      "y": 3,
      "z": -12,
      "name": "Empty"
    },
    {
      "x": 0,
      "y": 4,
      "z": -12,
      "name": "Empty"
    },
    {
      "x": 0,
      "y": 0,
      "z": -11,
      "name": "Soil_Dirt_Cold"
    },
    {
      "x": 0,
      "y": 1,
      "z": -11,
      "name": "Empty"
    },
    {
      "x": 0,
      "y": 2,
      "z": -11,
      "name": "Empty"
    },
    {
      "x": 0,
      "y": 3,
      "z": -11,
      "name": "Empty"
    },
    {
      "x": 0,
      "y": 4,
      "z": -11,
      "name": "Empty"
    },
    {
      "x": 0,
      "y": 0,
      "z": -10,
      "name": "Rock_Basalt"
    },
    {
      "x": 0,
      "y": 1,
      "z": -10,
      "name": "Furniture_Ancient_Barrel"
    },
    {
      "x": 0,
      "y": 2,
      "z": -10,
      "name": "Empty"
    },
    {
      "x": 0,
      "y": 3,
      "z": -10,
      "name": "Empty"
    },
    {
      "x": 0,
      "y": 4,
      "z": -10,
      "name": "Empty"
    },
    {
      "x": 0,
      "y": 0,
      "z": -9,
      "name": "Rock_Shale"
    },
    {
      "x": 0,
      "y": 1,
      "z": -9,
      "name": "Empty"
    },
    {
      "x": 0,
      "y": 2,
      "z": -9,
      "name": "Empty"
    },
    {
      "x": 0,
      "y": 3,
      "z": -9,
      "name": "Empty"
    },
    {
      "x": 0,
      "y": 4,
      "z": -9,
      "name": "Empty"
    },
    {
      "x": 0,
      "y": 0,
      "z": -8,
      "name": "Rock_Shale"
    },
    {
      "x": 0,
      "y": 1,
      "z": -8,
      "name": "Empty"
    },
    {
      "x": 0,
      "y": 2,
      "z": -8,
      "name": "Empty"
    },
    {
      "x": 0,
      "y": 3,
      "z": -8,
      "name": "Empty"
    },
    {
      "x": 0,
      "y": 4,
      "z": -8,
      "name": "Empty"
    },
    {
      "x": 0,
      "y": 0,
      "z": -7,
      "name": "Rock_Shale"
    },
    {
      "x": 0,
      "y": 1,
      "z": -7,
      "name": "Empty"
    },
    {
      "x": 0,
      "y": 2,
      "z": -7,
      "name": "Empty"
    },
    {
      "x": 0,
      "y": 3,
      "z": -7,
      "name": "Empty"
    },
    {
      "x": 0,
      "y": 4,
      "z": -7,
      "name": "Empty"
    },
    {
      "x": 0,
      "y": 0,
      "z": -6,
      "name": "Rock_Shale"
    },
    {
      "x": 0,
      "y": 1,
      "z": -6,
      "name": "Empty"
    },
    {
      "x": 0,
      "y": 2,
      "z": -6,
      "name": "Empty"
    },
    {
      "x": 0,
      "y": 3,
      "z": -6,
      "name": "Empty"
    },
    {
      "x": 0,
      "y": 4,
      "z": -6,
      "name": "Empty"
    },
    {
      "x": 0,
      "y": 0,
      "z": -5,
      "name": "Rock_Shale_Brick_Smooth"
    },
    {
      "x": 0,
      "y": 1,
      "z": -5,
      "name": "Empty"
    },
    {
      "x": 0,
      "y": 2,
      "z": -5,
      "name": "Empty"
    },
    {
      "x": 0,
      "y": 3,
      "z": -5,
      "name": "Empty"
    },
    {
      "x": 0,
      "y": 4,
      "z": -5,
      "name": "Rock_Basalt_Brick"
    },
    {
      "x": 0,
      "y": 0,
      "z": -4,
      "name": "Rock_Shale"
    },
    {
      "x": 0,
      "y": 1,
      "z": -4,
      "name": "Empty"
    },
    {
      "x": 0,
      "y": 2,
      "z": -4,
      "name": "Empty"
    },
    {
      "x": 0,
      "y": 3,
      "z": -4,
      "name": "Empty"
    },
    {
      "x": 0,
      "y": 4,
      "z": -4,
      "name": "Rock_Basalt_Brick"
    },
    {
      "x": 0,
      "y": 0,
      "z": -3,
      "name": "Rock_Shale"
    },
    {
      "x": 0,
      "y": 1,
      "z": -3,
      "name": "Empty"
    },
    {
      "x": 0,
      "y": 2,
      "z": -3,
      "name": "Empty"
    },
    {
      "x": 0,
      "y": 3,
      "z": -3,
      "name": "Empty"
    },
    {
      "x": 0,
      "y": 4,
      "z": -3,
      "name": "Empty"
    },
    {
      "x": 0,
      "y": 0,
      "z": -2,
      "name": "Rock_Shale"
    },
    {
      "x": 0,
      "y": 1,
      "z": -2,
      "name": "Empty"
    },
    {
      "x": 0,
      "y": 2,
      "z": -2,
      "name": "Empty"
    },
    {
      "x": 0,
      "y": 3,
      "z": -2,
      "name": "Empty"
    },
    {
      "x": 0,
      "y": 4,
      "z": -2,
      "name": "Empty"
    },
    {
      "x": 0,
      "y": 0,
      "z": -1,
      "name": "Rock_Shale"
    },
    {
      "x": 0,
      "y": 1,
      "z": -1,
      "name": "Empty"
    },
    {
      "x": 0,
      "y": 2,
      "z": -1,
      "name": "Empty"
    },
    {
      "x": 0,
      "y": 3,
      "z": -1,
      "name": "Empty"
    },
    {
      "x": 0,
      "y": 4,
      "z": -1,
      "name": "Empty"
    },
    {
      "x": 0,
      "y": 0,
      "z": 0,
      "name": "Rock_Shale"
    },
    {
      "x": 0,
      "y": 1,
      "z": 0,
      "name": "Empty"
    },
    {
      "x": 0,
      "y": 2,
      "z": 0,
      "name": "Empty"
    },
    {
      "x": 0,
      "y": 3,
      "z": 0,
      "name": "Empty"
    },
    {
      "x": 0,
      "y": 4,
      "z": 0,
      "name": "Empty"
    },
    {
      "x": 1,
      "y": 0,
      "z": -14,
      "name": "Rock_Shale_Brick_Smooth"
    },
    {
      "x": 1,
      "y": 1,
      "z": -14,
      "name": "Rock_Shale_Brick"
    },
    {
      "x": 1,
      "y": 2,
      "z": -14,
      "name": "Rock_Shale_Brick"
    },
    {
      "x": 1,
      "y": 3,
      "z": -14,
      "name": "Rock_Shale_Brick"
    },
    {
      "x": 1,
      "y": 4,
      "z": -14,
      "name": "Rock_Shale_Brick"
    },
    {
      "x": 1,
      "y": 0,
      "z": -13,
      "name": "Rock_Shale_Brick_Smooth"
    },
    {
      "x": 1,
      "y": 1,
      "z": -13,
      "name": "Rock_Shale_Brick_Stairs",
      "rotation": 10
    },
    {
      "x": 1,
      "y": 2,
      "z": -13,
      "name": "Deco_Bone_Skulls"
    },
    {
      "x": 1,
      "y": 3,
      "z": -13,
      "name": "Empty"
    },
    {
      "x": 1,
      "y": 4,
      "z": -13,
      "name": "Rock_Shale_Brick"
    },
    {
      "x": 1,
      "y": 0,
      "z": -12,
      "name": "Soil_Dirt_Cold"
    },
    {
      "x": 1,
      "y": 1,
      "z": -12,
      "name": "Empty"
    },
    {
      "x": 1,
      "y": 2,
      "z": -12,
      "name": "Empty"
    },
    {
      "x": 1,
      "y": 3,
      "z": -12,
      "name": "Empty"
    },
    {
      "x": 1,
      "y": 4,
      "z": -12,
      "name": "Empty"
    },
    {
      "x": 1,
      "y": 0,
      "z": -11,
      "name": "Rock_Basalt"
    },
    {
      "x": 1,
      "y": 1,
      "z": -11,
      "name": "Rock_Basalt"
    },
    {
      "x": 1,
      "y": 2,
      "z": -11,
      "name": "Furniture_Ancient_Crate"
    },
    {
      "x": 1,
      "y": 3,
      "z": -11,
      "name": "Empty"
    },
    {
      "x": 1,
      "y": 4,
      "z": -11,
      "name": "Empty"
    },
    {
      "x": 1,
      "y": 0,
      "z": -10,
      "name": "Rock_Basalt"
    },
    {
      "x": 1,
      "y": 1,
      "z": -10,
      "name": "Furniture_Ancient_Barrel"
    },
    {
      "x": 1,
      "y": 2,
      "z": -10,
      "name": "Empty"
    },
    {
      "x": 1,
      "y": 3,
      "z": -10,
      "name": "Empty"
    },
    {
      "x": 1,
      "y": 4,
      "z": -10,
      "name": "Empty"
    },
    {
      "x": 1,
      "y": 0,
      "z": -9,
      "name": "Rock_Shale"
    },
    {
      "x": 1,
      "y": 1,
      "z": -9,
      "name": "Furniture_Ancient_Barrel"
    },
    {
      "x": 1,
      "y": 2,
      "z": -9,
      "name": "Empty"
    },
    {
      "x": 1,
      "y": 3,
      "z": -9,
      "name": "Empty"
    },
    {
      "x": 1,
      "y": 4,
      "z": -9,
      "name": "Empty"
    },
    {
      "x": 1,
      "y": 0,
      "z": -8,
      "name": "Rock_Shale"
    },
    {
      "x": 1,
      "y": 1,
      "z": -8,
      "name": "Empty"
    },
    {
      "x": 1,
      "y": 2,
      "z": -8,
      "name": "Empty"
    },
    {
      "x": 1,
      "y": 3,
      "z": -8,
      "name": "Empty"
    },
    {
      "x": 1,
      "y": 4,
      "z": -8,
      "name": "Empty"
    },
    {
      "x": 1,
      "y": 0,
      "z": -7,
      "name": "Soil_Dirt_Cold"
    },
    {
      "x": 1,
      "y": 1,
      "z": -7,
      "name": "Empty"
    },
    {
      "x": 1,
      "y": 2,
      "z": -7,
      "name": "Empty"
    },
    {
      "x": 1,
      "y": 3,
      "z": -7,
      "name": "Empty"
    },
    {
      "x": 1,
      "y": 4,
      "z": -7,
      "name": "Empty"
    },
    {
      "x": 1,
      "y": 0,
      "z": -6,
      "name": "Soil_Dirt_Cold"
    },
    {
      "x": 1,
      "y": 1,
      "z": -6,
      "name": "Empty"
    },
    {
      "x": 1,
      "y": 2,
      "z": -6,
      "name": "Empty"
    },
    {
      "x": 1,
      "y": 3,
      "z": -6,
      "name": "Empty"
    },
    {
      "x": 1,
      "y": 4,
      "z": -6,
      "name": "Empty"
    },
    {
      "x": 1,
      "y": 0,
      "z": -5,
      "name": "Rock_Shale_Brick_Smooth"
    },
    {
      "x": 1,
      "y": 1,
      "z": -5,
      "name": "Empty"
    },
    {
      "x": 1,
      "y": 2,
      "z": -5,
      "name": "Empty"
    },
    {
      "x": 1,
      "y": 3,
      "z": -5,
      "name": "Empty"
    },
    {
      "x": 1,
      "y": 4,
      "z": -5,
      "name": "Rock_Basalt_Brick"
    },
    {
      "x": 1,
      "y": 0,
      "z": -4,
      "name": "Rock_Shale"
    },
    {
      "x": 1,
      "y": 1,
      "z": -4,
      "name": "Empty"
    },
    {
      "x": 1,
      "y": 2,
      "z": -4,
      "name": "Empty"
    },
    {
      "x": 1,
      "y": 3,
      "z": -4,
      "name": "Empty"
    },
    {
      "x": 1,
      "y": 4,
      "z": -4,
      "name": "Rock_Basalt_Brick"
    },
    {
      "x": 1,
      "y": 0,
      "z": -3,
      "name": "Rock_Shale"
    },
    {
      "x": 1,
      "y": 1,
      "z": -3,
      "name": "Empty"
    },
    {
      "x": 1,
      "y": 2,
      "z": -3,
      "name": "Empty"
    },
    {
      "x": 1,
      "y": 3,
      "z": -3,
      "name": "Empty"
    },
    {
      "x": 1,
      "y": 4,
      "z": -3,
      "name": "Empty"
    },
    {
      "x": 1,
      "y": 0,
      "z": -2,
      "name": "Rock_Shale"
    },
    {
      "x": 1,
      "y": 1,
      "z": -2,
      "name": "Empty"
    },
    {
      "x": 1,
      "y": 2,
      "z": -2,
      "name": "Empty"
    },
    {
      "x": 1,
      "y": 3,
      "z": -2,
      "name": "Empty"
    },
    {
      "x": 1,
      "y": 4,
      "z": -2,
      "name": "Empty"
    },
    {
      "x": 1,
      "y": 0,
      "z": -1,
      "name": "Rock_Shale"
    },
    {
      "x": 1,
      "y": 1,
      "z": -1,
      "name": "Empty"
    },
    {
      "x": 1,
      "y": 2,
      "z": -1,
      "name": "Empty"
    },
    {
      "x": 1,
      "y": 3,
      "z": -1,
      "name": "Empty"
    },
    {
      "x": 1,
      "y": 4,
      "z": -1,
      "name": "Empty"
    },
    {
      "x": 1,
      "y": 0,
      "z": 0,
      "name": "Rock_Shale_Brick_Smooth"
    },
    {
      "x": 1,
      "y": 1,
      "z": 0,
      "name": "Empty"
    },
    {
      "x": 1,
      "y": 2,
      "z": 0,
      "name": "Empty"
    },
    {
      "x": 1,
      "y": 3,
      "z": 0,
      "name": "Empty"
    },
    {
      "x": 1,
      "y": 4,
      "z": 0,
      "name": "Empty"
    },
    {
      "x": 2,
      "y": 0,
      "z": -14,
      "name": "Rock_Shale_Brick_Smooth"
    },
    {
      "x": 2,
      "y": 1,
      "z": -14,
      "name": "Rock_Shale_Brick"
    },
    {
      "x": 2,
      "y": 2,
      "z": -14,
      "name": "Rock_Shale_Brick"
    },
    {
      "x": 2,
      "y": 3,
      "z": -14,
      "name": "Rock_Shale_Brick"
    },
    {
      "x": 2,
      "y": 4,
      "z": -14,
      "name": "Rock_Shale_Brick"
    },
    {
      "x": 2,
      "y": 0,
      "z": -13,
      "name": "Rock_Shale_Brick_Smooth"
    },
    {
      "x": 2,
      "y": 1,
      "z": -13,
      "name": "Rock_Shale_Brick_Pillar_Base"
    },
    {
      "x": 2,
      "y": 2,
      "z": -13,
      "name": "Rock_Shale_Brick_Pillar_Middle"
    },
    {
      "x": 2,
      "y": 3,
      "z": -13,
      "name": "Rock_Shale_Brick_Pillar_Base",
      "rotation": 8
    },
    {
      "x": 2,
      "y": 4,
      "z": -13,
      "name": "Rock_Shale_Brick"
    },
    {
      "x": 2,
      "y": 0,
      "z": -12,
      "name": "Rock_Basalt"
    },
    {
      "x": 2,
      "y": 1,
      "z": -12,
      "name": "Rock_Basalt"
    },
    {
      "x": 2,
      "y": 2,
      "z": -12,
      "name": "Rock_Basalt"
    },
    {
      "x": 2,
      "y": 3,
      "z": -12,
      "name": "Empty"
    },
    {
      "x": 2,
      "y": 4,
      "z": -12,
      "name": "Rock_Shale_Brick_Stairs",
      "rotation": 10
    },
    {
      "x": 2,
      "y": 0,
      "z": -11,
      "name": "Rock_Basalt"
    },
    {
      "x": 2,
      "y": 1,
      "z": -11,
      "name": "Rock_Basalt"
    },
    {
      "x": 2,
      "y": 2,
      "z": -11,
      "name": "Empty"
    },
    {
      "x": 2,
      "y": 3,
      "z": -11,
      "name": "Empty"
    },
    {
      "x": 2,
      "y": 4,
      "z": -11,
      "name": "Empty"
    },
    {
      "x": 2,
      "y": 0,
      "z": -10,
      "name": "Rock_Basalt"
    },
    {
      "x": 2,
      "y": 1,
      "z": -10,
      "name": "Rubble_Basalt_Medium"
    },
    {
      "x": 2,
      "y": 2,
      "z": -10,
      "name": "Empty"
    },
    {
      "x": 2,
      "y": 3,
      "z": -10,
      "name": "Empty"
    },
    {
      "x": 2,
      "y": 4,
      "z": -10,
      "name": "Empty"
    },
    {
      "x": 2,
      "y": 0,
      "z": -9,
      "name": "Rock_Shale"
    },
    {
      "x": 2,
      "y": 1,
      "z": -9,
      "name": "Empty"
    },
    {
      "x": 2,
      "y": 2,
      "z": -9,
      "name": "Empty"
    },
    {
      "x": 2,
      "y": 3,
      "z": -9,
      "name": "Empty"
    },
    {
      "x": 2,
      "y": 4,
      "z": -9,
      "name": "Plant_Bush_Dead_Hanging"
    },
    {
      "x": 2,
      "y": 0,
      "z": -8,
      "name": "Rock_Shale"
    },
    {
      "x": 2,
      "y": 1,
      "z": -8,
      "name": "Empty"
    },
    {
      "x": 2,
      "y": 2,
      "z": -8,
      "name": "Empty"
    },
    {
      "x": 2,
      "y": 3,
      "z": -8,
      "name": "Empty"
    },
    {
      "x": 2,
      "y": 4,
      "z": -8,
      "name": "Empty"
    },
    {
      "x": 2,
      "y": 0,
      "z": -7,
      "name": "Soil_Dirt_Cold"
    },
    {
      "x": 2,
      "y": 1,
      "z": -7,
      "name": "Empty"
    },
    {
      "x": 2,
      "y": 2,
      "z": -7,
      "name": "Empty"
    },
    {
      "x": 2,
      "y": 3,
      "z": -7,
      "name": "Empty"
    },
    {
      "x": 2,
      "y": 4,
      "z": -7,
      "name": "Empty"
    },
    {
      "x": 2,
      "y": 0,
      "z": -6,
      "name": "Soil_Dirt_Cold"
    },
    {
      "x": 2,
      "y": 1,
      "z": -6,
      "name": "Empty"
    },
    {
      "x": 2,
      "y": 2,
      "z": -6,
      "name": "Empty"
    },
    {
      "x": 2,
      "y": 3,
      "z": -6,
      "name": "Empty"
    },
    {
      "x": 2,
      "y": 4,
      "z": -6,
      "name": "Empty"
    },
    {
      "x": 2,
      "y": 0,
      "z": -5,
      "name": "Soil_Dirt_Cold"
    },
    {
      "x": 2,
      "y": 1,
      "z": -5,
      "name": "Empty"
    },
    {
      "x": 2,
      "y": 2,
      "z": -5,
      "name": "Empty"
    },
    {
      "x": 2,
      "y": 3,
      "z": -5,
      "name": "Rock_Basalt_Brick_Half",
      "rotation": 8
    },
    {
      "x": 2,
      "y": 4,
      "z": -5,
      "name": "Rock_Basalt_Brick"
    },
    {
      "x": 2,
      "y": 0,
      "z": -4,
      "name": "Soil_Dirt_Cold"
    },
    {
      "x": 2,
      "y": 1,
      "z": -4,
      "name": "Empty"
    },
    {
      "x": 2,
      "y": 2,
      "z": -4,
      "name": "Empty"
    },
    {
      "x": 2,
      "y": 3,
      "z": -4,
      "name": "Rock_Basalt_Brick_Half",
      "rotation": 8
    },
    {
      "x": 2,
      "y": 4,
      "z": -4,
      "name": "Rock_Basalt_Brick"
    },
    {
      "x": 2,
      "y": 0,
      "z": -3,
      "name": "Rock_Basalt"
    },
    {
      "x": 2,
      "y": 1,
      "z": -3,
      "name": "Wood_Redwood_Branch_Long"
    },
    {
      "x": 2,
      "y": 2,
      "z": -3,
      "name": "Wood_Redwood_Branch_Long"
    },
    {
      "x": 2,
      "y": 3,
      "z": -3,
      "name": "Wood_Redwood_Branch_Long"
    },
    {
      "x": 2,
      "y": 4,
      "z": -3,
      "name": "Wood_Redwood_Branch_Long"
    },
    {
      "x": 2,
      "y": 0,
      "z": -2,
      "name": "Rock_Basalt"
    },
    {
      "x": 2,
      "y": 1,
      "z": -2,
      "name": "Empty"
    },
    {
      "x": 2,
      "y": 2,
      "z": -2,
      "name": "Empty"
    },
    {
      "x": 2,
      "y": 3,
      "z": -2,
      "name": "Empty"
    },
    {
      "x": 2,
      "y": 4,
      "z": -2,
      "name": "Plant_Bush_Dead_Hanging"
    },
    {
      "x": 2,
      "y": 0,
      "z": -1,
      "name": "Rock_Basalt"
    },
    {
      "x": 2,
      "y": 1,
      "z": -1,
      "name": "Empty"
    },
    {
      "x": 2,
      "y": 2,
      "z": -1,
      "name": "Empty"
    },
    {
      "x": 2,
      "y": 3,
      "z": -1,
      "name": "Empty"
    },
    {
      "x": 2,
      "y": 4,
      "z": -1,
      "name": "Empty"
    },
    {
      "x": 2,
      "y": 0,
      "z": 0,
      "name": "Rock_Shale_Brick_Smooth"
    },
    {
      "x": 2,
      "y": 1,
      "z": 0,
      "name": "Empty"
    },
    {
      "x": 2,
      "y": 2,
      "z": 0,
      "name": "Empty"
    },
    {
      "x": 2,
      "y": 3,
      "z": 0,
      "name": "Empty"
    },
    {
      "x": 2,
      "y": 4,
      "z": 0,
      "name": "Empty"
    },
    {
      "x": 3,
      "y": 0,
      "z": -14,
      "name": "Rock_Shale_Brick_Smooth"
    },
    {
      "x": 3,
      "y": 1,
      "z": -14,
      "name": "Rock_Shale"
    },
    {
      "x": 3,
      "y": 2,
      "z": -14,
      "name": "Rock_Shale"
    },
    {
      "x": 3,
      "y": 3,
      "z": -14,
      "name": "Rock_Shale"
    },
    {
      "x": 3,
      "y": 4,
      "z": -14,
      "name": "Rock_Shale"
    },
    {
      "x": 3,
      "y": 0,
      "z": -13,
      "name": "Rock_Shale_Brick_Smooth"
    },
    {
      "x": 3,
      "y": 1,
      "z": -13,
      "name": "Rock_Basalt_Brick"
    },
    {
      "x": 3,
      "y": 2,
      "z": -13,
      "name": "Rock_Basalt_Brick"
    },
    {
      "x": 3,
      "y": 3,
      "z": -13,
      "name": "Rock_Basalt_Brick"
    },
    {
      "x": 3,
      "y": 4,
      "z": -13,
      "name": "Rock_Basalt_Brick"
    },
    {
      "x": 3,
      "y": 0,
      "z": -12,
      "name": "Rock_Shale"
    },
    {
      "x": 3,
      "y": 1,
      "z": -12,
      "name": "Rock_Basalt_Brick"
    },
    {
      "x": 3,
      "y": 2,
      "z": -12,
      "name": "Rock_Basalt_Brick"
    },
    {
      "x": 3,
      "y": 3,
      "z": -12,
      "name": "Rock_Basalt_Brick"
    },
    {
      "x": 3,
      "y": 4,
      "z": -12,
      "name": "Rock_Basalt_Brick"
    },
    {
      "x": 3,
      "y": 0,
      "z": -11,
      "name": "Rock_Basalt"
    },
    {
      "x": 3,
      "y": 1,
      "z": -11,
      "name": "Rock_Basalt"
    },
    {
      "x": 3,
      "y": 2,
      "z": -11,
      "name": "Rock_Basalt"
    },
    {
      "x": 3,
      "y": 3,
      "z": -11,
      "name": "Empty"
    },
    {
      "x": 3,
      "y": 4,
      "z": -11,
      "name": "Rock_Shale_Brick_Stairs",
      "rotation": 9
    },
    {
      "x": 3,
      "y": 0,
      "z": -10,
      "name": "Rock_Shale"
    },
    {
      "x": 3,
      "y": 1,
      "z": -10,
      "name": "Empty"
    },
    {
      "x": 3,
      "y": 2,
      "z": -10,
      "name": "Empty"
    },
    {
      "x": 3,
      "y": 3,
      "z": -10,
      "name": "Empty"
    },
    {
      "x": 3,
      "y": 4,
      "z": -10,
      "name": "Empty"
    },
    {
      "x": 3,
      "y": 0,
      "z": -9,
      "name": "Rock_Shale"
    },
    {
      "x": 3,
      "y": 1,
      "z": -9,
      "name": "Empty"
    },
    {
      "x": 3,
      "y": 2,
      "z": -9,
      "name": "Empty"
    },
    {
      "x": 3,
      "y": 3,
      "z": -9,
      "name": "Empty"
    },
    {
      "x": 3,
      "y": 4,
      "z": -9,
      "name": "Empty"
    },
    {
      "x": 3,
      "y": 0,
      "z": -8,
      "name": "Soil_Dirt_Cold"
    },
    {
      "x": 3,
      "y": 1,
      "z": -8,
      "name": "*Plant_Crop_Berry_Winter_Block_State_Definitions_StageFinal"
    },
    {
      "x": 3,
      "y": 2,
      "z": -8,
      "name": "Empty"
    },
    {
      "x": 3,
      "y": 3,
      "z": -8,
      "name": "Empty"
    },
    {
      "x": 3,
      "y": 4,
      "z": -8,
      "name": "Empty"
    },
    {
      "x": 3,
      "y": 0,
      "z": -7,
      "name": "Soil_Dirt_Cold"
    },
    {
      "x": 3,
      "y": 1,
      "z": -7,
      "name": "Empty"
    },
    {
      "x": 3,
      "y": 2,
      "z": -7,
      "name": "Empty"
    },
    {
      "x": 3,
      "y": 3,
      "z": -7,
      "name": "Empty"
    },
    {
      "x": 3,
      "y": 4,
      "z": -7,
      "name": "Empty"
    },
    {
      "x": 3,
      "y": 0,
      "z": -6,
      "name": "Soil_Dirt_Cold"
    },
    {
      "x": 3,
      "y": 1,
      "z": -6,
      "name": "Rock_Shale_Brick_Beam"
    },
    {
      "x": 3,
      "y": 2,
      "z": -6,
      "name": "Furniture_Human_Ruins_Torch",
      "rotation": 3
    },
    {
      "x": 3,
      "y": 3,
      "z": -6,
      "name": "Empty"
    },
    {
      "x": 3,
      "y": 4,
      "z": -6,
      "name": "Rock_Shale_Brick_Stairs",
      "rotation": 9
    },
    {
      "x": 3,
      "y": 0,
      "z": -5,
      "name": "Soil_Dirt_Cold"
    },
    {
      "x": 3,
      "y": 1,
      "z": -5,
      "name": "Furniture_Ancient_Barrel"
    },
    {
      "x": 3,
      "y": 2,
      "z": -5,
      "name": "Furniture_Ancient_Barrel"
    },
    {
      "x": 3,
      "y": 3,
      "z": -5,
      "name": "Rock_Basalt_Brick"
    },
    {
      "x": 3,
      "y": 4,
      "z": -5,
      "name": "Rock_Basalt_Brick"
    },
    {
      "x": 3,
      "y": 0,
      "z": -4,
      "name": "Soil_Dirt_Cold"
    },
    {
      "x": 3,
      "y": 1,
      "z": -4,
      "name": "Furniture_Ancient_Barrel"
    },
    {
      "x": 3,
      "y": 2,
      "z": -4,
      "name": "Empty"
    },
    {
      "x": 3,
      "y": 3,
      "z": -4,
      "name": "Rock_Basalt_Brick"
    },
    {
      "x": 3,
      "y": 4,
      "z": -4,
      "name": "Rock_Basalt_Brick"
    },
    {
      "x": 3,
      "y": 0,
      "z": -3,
      "name": "Soil_Dirt_Cold"
    },
    {
      "x": 3,
      "y": 1,
      "z": -3,
      "name": "Empty"
    },
    {
      "x": 3,
      "y": 2,
      "z": -3,
      "name": "Empty"
    },
    {
      "x": 3,
      "y": 3,
      "z": -3,
      "name": "Empty"
    },
    {
      "x": 3,
      "y": 4,
      "z": -3,
      "name": "Rock_Shale_Brick_Stairs",
      "rotation": 9
    },
    {
      "x": 3,
      "y": 0,
      "z": -2,
      "name": "Soil_Dirt_Cold"
    },
    {
      "x": 3,
      "y": 1,
      "z": -2,
      "name": "Empty"
    },
    {
      "x": 3,
      "y": 2,
      "z": -2,
      "name": "Empty"
    },
    {
      "x": 3,
      "y": 3,
      "z": -2,
      "name": "Empty"
    },
    {
      "x": 3,
      "y": 4,
      "z": -2,
      "name": "Empty"
    },
    {
      "x": 3,
      "y": 0,
      "z": -1,
      "name": "Soil_Dirt_Cold"
    },
    {
      "x": 3,
      "y": 1,
      "z": -1,
      "name": "Plant_Bush_Dead_Twisted"
    },
    {
      "x": 3,
      "y": 2,
      "z": -1,
      "name": "Empty"
    },
    {
      "x": 3,
      "y": 3,
      "z": -1,
      "name": "Empty"
    },
    {
      "x": 3,
      "y": 4,
      "z": -1,
      "name": "Empty"
    },
    {
      "x": 3,
      "y": 0,
      "z": 0,
      "name": "Rock_Shale_Brick_Smooth"
    },
    {
      "x": 3,
      "y": 1,
      "z": 0,
      "name": "Empty"
    },
    {
      "x": 3,
      "y": 2,
      "z": 0,
      "name": "Empty"
    },
    {
      "x": 3,
      "y": 3,
      "z": 0,
      "name": "Empty"
    },
    {
      "x": 3,
      "y": 4,
      "z": 0,
      "name": "Rock_Shale_Brick_Stairs",
      "rotation": 9
    },
    {
      "x": 4,
      "y": 0,
      "z": -14,
      "name": "Rock_Shale_Brick_Smooth"
    },
    {
      "x": 4,
      "y": 1,
      "z": -14,
      "name": "Rock_Shale"
    },
    {
      "x": 4,
      "y": 2,
      "z": -14,
      "name": "Rock_Shale"
    },
    {
      "x": 4,
      "y": 3,
      "z": -14,
      "name": "Rock_Shale"
    },
    {
      "x": 4,
      "y": 4,
      "z": -14,
      "name": "Rock_Shale"
    },
    {
      "x": 4,
      "y": 0,
      "z": -13,
      "name": "Rock_Shale_Brick_Smooth"
    },
    {
      "x": 4,
      "y": 1,
      "z": -13,
      "name": "Rock_Basalt_Brick"
    },
    {
      "x": 4,
      "y": 2,
      "z": -13,
      "name": "Rock_Basalt_Brick"
    },
    {
      "x": 4,
      "y": 3,
      "z": -13,
      "name": "Rock_Basalt_Brick"
    },
    {
      "x": 4,
      "y": 4,
      "z": -13,
      "name": "Rock_Basalt_Brick"
    },
    {
      "x": 4,
      "y": 0,
      "z": -12,
      "name": "Rock_Shale_Brick_Smooth"
    },
    {
      "x": 4,
      "y": 1,
      "z": -12,
      "name": "Rock_Basalt_Brick"
    },
    {
      "x": 4,
      "y": 2,
      "z": -12,
      "name": "Rock_Basalt_Brick"
    },
    {
      "x": 4,
      "y": 3,
      "z": -12,
      "name": "Rock_Basalt_Brick"
    },
    {
      "x": 4,
      "y": 4,
      "z": -12,
      "name": "Rock_Basalt_Brick"
    },
    {
      "x": 4,
      "y": 0,
      "z": -11,
      "name": "Rock_Shale_Brick_Smooth"
    },
    {
      "x": 4,
      "y": 1,
      "z": -11,
      "name": "Rock_Shale_Brick_Pillar_Base"
    },
    {
      "x": 4,
      "y": 2,
      "z": -11,
      "name": "Rock_Shale_Brick_Pillar_Middle"
    },
    {
      "x": 4,
      "y": 3,
      "z": -11,
      "name": "Rock_Shale_Brick_Pillar_Base",
      "rotation": 8
    },
    {
      "x": 4,
      "y": 4,
      "z": -11,
      "name": "Rock_Shale_Brick"
    },
    {
      "x": 4,
      "y": 0,
      "z": -10,
      "name": "Rock_Shale_Brick_Smooth"
    },
    {
      "x": 4,
      "y": 1,
      "z": -10,
      "name": "Rock_Shale_Brick_Stairs",
      "rotation": 9
    },
    {
      "x": 4,
      "y": 2,
      "z": -10,
      "name": "Deco_Bone_Pile"
    },
    {
      "x": 4,
      "y": 3,
      "z": -10,
      "name": "Empty"
    },
    {
      "x": 4,
      "y": 4,
      "z": -10,
      "name": "Rock_Shale_Brick"
    },
    {
      "x": 4,
      "y": 0,
      "z": -9,
      "name": "Rock_Shale_Brick_Smooth"
    },
    {
      "x": 4,
      "y": 1,
      "z": -9,
      "name": "Rock_Shale_Brick_Stairs",
      "rotation": 9
    },
    {
      "x": 4,
      "y": 2,
      "z": -9,
      "name": "Deco_Bone_Pile"
    },
    {
      "x": 4,
      "y": 3,
      "z": -9,
      "name": "Empty"
    },
    {
      "x": 4,
      "y": 4,
      "z": -9,
      "name": "Rock_Shale_Brick"
    },
    {
      "x": 4,
      "y": 0,
      "z": -8,
      "name": "Rock_Shale_Brick_Smooth"
    },
    {
      "x": 4,
      "y": 1,
      "z": -8,
      "name": "Rock_Shale_Brick_Stairs",
      "rotation": 9
    },
    {
      "x": 4,
      "y": 2,
      "z": -8,
      "name": "Deco_Bone_Skulls"
    },
    {
      "x": 4,
      "y": 3,
      "z": -8,
      "name": "Empty"
    },
    {
      "x": 4,
      "y": 4,
      "z": -8,
      "name": "Rock_Shale_Brick"
    },
    {
      "x": 4,
      "y": 0,
      "z": -7,
      "name": "Rock_Shale_Brick_Smooth"
    },
    {
      "x": 4,
      "y": 1,
      "z": -7,
      "name": "Rock_Shale_Brick_Stairs",
      "rotation": 9
    },
    {
      "x": 4,
      "y": 2,
      "z": -7,
      "name": "Deco_Bone_Skulls"
    },
    {
      "x": 4,
      "y": 3,
      "z": -7,
      "name": "Empty"
    },
    {
      "x": 4,
      "y": 4,
      "z": -7,
      "name": "Rock_Shale_Brick"
    },
    {
      "x": 4,
      "y": 0,
      "z": -6,
      "name": "Rock_Shale_Brick_Smooth"
    },
    {
      "x": 4,
      "y": 1,
      "z": -6,
      "name": "Rock_Shale_Brick_Pillar_Base"
    },
    {
      "x": 4,
      "y": 2,
      "z": -6,
      "name": "Rock_Shale_Brick_Pillar_Middle"
    },
    {
      "x": 4,
      "y": 3,
      "z": -6,
      "name": "Rock_Shale_Brick_Pillar_Base",
      "rotation": 8
    },
    {
      "x": 4,
      "y": 4,
      "z": -6,
      "name": "Rock_Shale_Brick"
    },
    {
      "x": 4,
      "y": 0,
      "z": -5,
      "name": "Rock_Shale_Brick_Smooth"
    },
    {
      "x": 4,
      "y": 1,
      "z": -5,
      "name": "Rock_Basalt_Brick"
    },
    {
      "x": 4,
      "y": 2,
      "z": -5,
      "name": "Rock_Basalt_Brick"
    },
    {
      "x": 4,
      "y": 3,
      "z": -5,
      "name": "Rock_Basalt_Brick"
    },
    {
      "x": 4,
      "y": 4,
      "z": -5,
      "name": "Rock_Basalt_Brick"
    },
    {
      "x": 4,
      "y": 0,
      "z": -4,
      "name": "Rock_Shale_Brick_Smooth"
    },
    {
      "x": 4,
      "y": 1,
      "z": -4,
      "name": "Rock_Basalt_Brick"
    },
    {
      "x": 4,
      "y": 2,
      "z": -4,
      "name": "Rock_Basalt_Brick"
    },
    {
      "x": 4,
      "y": 3,
      "z": -4,
      "name": "Rock_Basalt_Brick"
    },
    {
      "x": 4,
      "y": 4,
      "z": -4,
      "name": "Rock_Basalt_Brick"
    },
    {
      "x": 4,
      "y": 0,
      "z": -3,
      "name": "Rock_Shale_Brick_Smooth"
    },
    {
      "x": 4,
      "y": 1,
      "z": -3,
      "name": "Rock_Shale_Brick_Pillar_Base"
    },
    {
      "x": 4,
      "y": 2,
      "z": -3,
      "name": "Rock_Shale_Brick_Pillar_Middle"
    },
    {
      "x": 4,
      "y": 3,
      "z": -3,
      "name": "Rock_Shale_Brick_Pillar_Base",
      "rotation": 8
    },
    {
      "x": 4,
      "y": 4,
      "z": -3,
      "name": "Rock_Shale_Brick"
    },
    {
      "x": 4,
      "y": 0,
      "z": -2,
      "name": "Rock_Shale_Brick_Smooth"
    },
    {
      "x": 4,
      "y": 1,
      "z": -2,
      "name": "Rock_Shale_Brick_Stairs",
      "rotation": 9
    },
    {
      "x": 4,
      "y": 2,
      "z": -2,
      "name": "Deco_Bone_Pile"
    },
    {
      "x": 4,
      "y": 3,
      "z": -2,
      "name": "Empty"
    },
    {
      "x": 4,
      "y": 4,
      "z": -2,
      "name": "Rock_Shale_Brick"
    },
    {
      "x": 4,
      "y": 0,
      "z": -1,
      "name": "Rock_Shale_Brick_Smooth"
    },
    {
      "x": 4,
      "y": 1,
      "z": -1,
      "name": "Rock_Shale_Brick_Stairs",
      "rotation": 9
    },
    {
      "x": 4,
      "y": 2,
      "z": -1,
      "name": "Deco_Bone_Pile"
    },
    {
      "x": 4,
      "y": 3,
      "z": -1,
      "name": "Empty"
    },
    {
      "x": 4,
      "y": 4,
      "z": -1,
      "name": "Rock_Shale_Brick"
    },
    {
      "x": 4,
      "y": 0,
      "z": 0,
      "name": "Rock_Shale_Brick_Smooth"
    },
    {
      "x": 4,
      "y": 1,
      "z": 0,
      "name": "Rock_Shale_Brick_Pillar_Base"
    },
    {
      "x": 4,
      "y": 2,
      "z": 0,
      "name": "Rock_Shale_Brick_Pillar_Middle"
    },
    {
      "x": 4,
      "y": 3,
      "z": 0,
      "name": "Rock_Shale_Brick_Pillar_Base",
      "rotation": 8
    },
    {
      "x": 4,
      "y": 4,
      "z": 0,
      "name": "Rock_Shale_Brick"
    },
    {
      "x": 5,
      "y": 0,
      "z": -14,
      "name": "Rock_Shale_Brick_Smooth"
    },
    {
      "x": 5,
      "y": 1,
      "z": -14,
      "name": "Rock_Shale"
    },
    {
      "x": 5,
      "y": 2,
      "z": -14,
      "name": "Rock_Shale"
    },
    {
      "x": 5,
      "y": 3,
      "z": -14,
      "name": "Rock_Shale"
    },
    {
      "x": 5,
      "y": 4,
      "z": -14,
      "name": "Rock_Shale"
    },
    {
      "x": 5,
      "y": 0,
      "z": -13,
      "name": "Rock_Shale_Brick_Smooth"
    },
    {
      "x": 5,
      "y": 1,
      "z": -13,
      "name": "Rock_Shale"
    },
    {
      "x": 5,
      "y": 2,
      "z": -13,
      "name": "Rock_Shale"
    },
    {
      "x": 5,
      "y": 3,
      "z": -13,
      "name": "Rock_Shale"
    },
    {
      "x": 5,
      "y": 4,
      "z": -13,
      "name": "Rock_Shale"
    },
    {
      "x": 5,
      "y": 0,
      "z": -12,
      "name": "Rock_Shale_Brick_Smooth"
    },
    {
      "x": 5,
      "y": 1,
      "z": -12,
      "name": "Rock_Shale"
    },
    {
      "x": 5,
      "y": 2,
      "z": -12,
      "name": "Rock_Shale"
    },
    {
      "x": 5,
      "y": 3,
      "z": -12,
      "name": "Rock_Shale"
    },
    {
      "x": 5,
      "y": 4,
      "z": -12,
      "name": "Rock_Shale"
    },
    {
      "x": 5,
      "y": 0,
      "z": -11,
      "name": "Rock_Shale_Brick_Smooth"
    },
    {
      "x": 5,
      "y": 1,
      "z": -11,
      "name": "Rock_Shale_Brick"
    },
    {
      "x": 5,
      "y": 2,
      "z": -11,
      "name": "Rock_Shale_Brick"
    },
    {
      "x": 5,
      "y": 3,
      "z": -11,
      "name": "Rock_Shale_Brick"
    },
    {
      "x": 5,
      "y": 4,
      "z": -11,
      "name": "Rock_Shale_Brick"
    },
    {
      "x": 5,
      "y": 0,
      "z": -10,
      "name": "Rock_Shale_Brick_Smooth"
    },
    {
      "x": 5,
      "y": 1,
      "z": -10,
      "name": "Rock_Shale_Brick"
    },
    {
      "x": 5,
      "y": 2,
      "z": -10,
      "name": "Rock_Shale_Brick"
    },
    {
      "x": 5,
      "y": 3,
      "z": -10,
      "name": "Rock_Shale_Brick"
    },
    {
      "x": 5,
      "y": 4,
      "z": -10,
      "name": "Rock_Shale_Brick"
    },
    {
      "x": 5,
      "y": 0,
      "z": -9,
      "name": "Rock_Shale_Brick_Smooth"
    },
    {
      "x": 5,
      "y": 1,
      "z": -9,
      "name": "Rock_Shale"
    },
    {
      "x": 5,
      "y": 2,
      "z": -9,
      "name": "Rock_Shale"
    },
    {
      "x": 5,
      "y": 3,
      "z": -9,
      "name": "Rock_Shale"
    },
    {
      "x": 5,
      "y": 4,
      "z": -9,
      "name": "Rock_Shale"
    },
    {
      "x": 5,
      "y": 0,
      "z": -8,
      "name": "Rock_Shale_Brick_Smooth"
    },
    {
      "x": 5,
      "y": 1,
      "z": -8,
      "name": "Rock_Shale"
    },
    {
      "x": 5,
      "y": 2,
      "z": -8,
      "name": "Rock_Shale"
    },
    {
      "x": 5,
      "y": 3,
      "z": -8,
      "name": "Rock_Shale"
    },
    {
      "x": 5,
      "y": 4,
      "z": -8,
      "name": "Rock_Shale"
    },
    {
      "x": 5,
      "y": 0,
      "z": -7,
      "name": "Rock_Shale_Brick_Smooth"
    },
    {
      "x": 5,
      "y": 1,
      "z": -7,
      "name": "Rock_Shale_Brick"
    },
    {
      "x": 5,
      "y": 2,
      "z": -7,
      "name": "Rock_Shale_Brick"
    },
    {
      "x": 5,
      "y": 3,
      "z": -7,
      "name": "Rock_Shale_Brick"
    },
    {
      "x": 5,
      "y": 4,
      "z": -7,
      "name": "Rock_Shale_Brick"
    },
    {
      "x": 5,
      "y": 0,
      "z": -6,
      "name": "Rock_Shale_Brick_Smooth"
    },
    {
      "x": 5,
      "y": 1,
      "z": -6,
      "name": "Rock_Shale_Brick"
    },
    {
      "x": 5,
      "y": 2,
      "z": -6,
      "name": "Rock_Shale_Brick"
    },
    {
      "x": 5,
      "y": 3,
      "z": -6,
      "name": "Rock_Shale_Brick"
    },
    {
      "x": 5,
      "y": 4,
      "z": -6,
      "name": "Rock_Shale_Brick"
    },
    {
      "x": 5,
      "y": 0,
      "z": -5,
      "name": "Rock_Shale_Brick_Smooth"
    },
    {
      "x": 5,
      "y": 1,
      "z": -5,
      "name": "Rock_Shale"
    },
    {
      "x": 5,
      "y": 2,
      "z": -5,
      "name": "Rock_Shale"
    },
    {
      "x": 5,
      "y": 3,
      "z": -5,
      "name": "Rock_Shale"
    },
    {
      "x": 5,
      "y": 4,
      "z": -5,
      "name": "Rock_Shale"
    },
    {
      "x": 5,
      "y": 0,
      "z": -4,
      "name": "Rock_Shale_Brick_Smooth"
    },
    {
      "x": 5,
      "y": 1,
      "z": -4,
      "name": "Rock_Shale"
    },
    {
      "x": 5,
      "y": 2,
      "z": -4,
      "name": "Rock_Shale"
    },
    {
      "x": 5,
      "y": 3,
      "z": -4,
      "name": "Rock_Shale"
    },
    {
      "x": 5,
      "y": 4,
      "z": -4,
      "name": "Rock_Shale"
    },
    {
      "x": 5,
      "y": 0,
      "z": -3,
      "name": "Rock_Shale_Brick_Smooth"
    },
    {
      "x": 5,
      "y": 1,
      "z": -3,
      "name": "Rock_Shale_Brick"
    },
    {
      "x": 5,
      "y": 2,
      "z": -3,
      "name": "Rock_Shale_Brick"
    },
    {
      "x": 5,
      "y": 3,
      "z": -3,
      "name": "Rock_Shale_Brick"
    },
    {
      "x": 5,
      "y": 4,
      "z": -3,
      "name": "Rock_Shale_Brick"
    },
    {
      "x": 5,
      "y": 0,
      "z": -2,
      "name": "Rock_Shale_Brick_Smooth"
    },
    {
      "x": 5,
      "y": 1,
      "z": -2,
      "name": "Rock_Shale_Brick"
    },
    {
      "x": 5,
      "y": 2,
      "z": -2,
      "name": "Rock_Shale_Brick"
    },
    {
      "x": 5,
      "y": 3,
      "z": -2,
      "name": "Rock_Basalt"
    },
    {
      "x": 5,
      "y": 4,
      "z": -2,
      "name": "Rock_Shale_Brick"
    },
    {
      "x": 5,
      "y": 0,
      "z": -1,
      "name": "Rock_Shale_Brick_Smooth"
    },
    {
      "x": 5,
      "y": 1,
      "z": -1,
      "name": "Rock_Shale_Brick"
    },
    {
      "x": 5,
      "y": 2,
      "z": -1,
      "name": "Rock_Shale_Brick"
    },
    {
      "x": 5,
      "y": 3,
      "z": -1,
      "name": "Rock_Basalt"
    },
    {
      "x": 5,
      "y": 4,
      "z": -1,
      "name": "Rock_Shale_Brick"
    },
    {
      "x": 5,
      "y": 0,
      "z": 0,
      "name": "Rock_Shale_Brick_Smooth"
    },
    {
      "x": 5,
      "y": 1,
      "z": 0,
      "name": "Rock_Shale_Brick"
    },
    {
      "x": 5,
      "y": 2,
      "z": 0,
      "name": "Rock_Shale_Brick"
    },
    {
      "x": 5,
      "y": 3,
      "z": 0,
      "name": "Rock_Shale_Brick"
    },
    {
      "x": 5,
      "y": 4,
      "z": 0,
      "name": "Rock_Shale_Brick"
    }
  ]
}